5:return {{["x"] = 2, ["y"] = 1, ["z"] = 6, ["name"] = "wool:blue"}, {["x"] = 2, ["y"] = 1, ["z"] = 7, ["name"] = "wool:blue"}, {["x"] = 2, ["y"] = 1, ["z"] = 8, ["name"] = "wool:blue"}, {["x"] = 2, ["y"] = 1, ["z"] = 9, ["name"] = "wool:blue"}, {["x"] = 2, ["y"] = 2, ["z"] = 6, ["name"] = "wool:blue"}, {["x"] = 2, ["y"] = 2, ["z"] = 7, ["name"] = "wool:blue"}, {["x"] = 2, ["y"] = 2, ["z"] = 8, ["name"] = "wool:blue"}, {["x"] = 2, ["y"] = 2, ["z"] = 9, ["name"] = "wool:blue"}, {["x"] = 2, ["y"] = 3, ["z"] = 6, ["name"] = "wool:blue"}, {["x"] = 2, ["y"] = 3, ["z"] = 7, ["name"] = "wool:blue"}, {["x"] = 2, ["y"] = 3, ["z"] = 8, ["name"] = "wool:blue"}, {["x"] = 2, ["y"] = 3, ["z"] = 9, ["name"] = "wool:blue"}, {["x"] = 2, ["y"] = 4, ["z"] = 6, ["name"] = "wool:blue"}, {["x"] = 2, ["y"] = 4, ["z"] = 7, ["name"] = "wool:blue"}, {["x"] = 2, ["y"] = 4, ["z"] = 8, ["name"] = "wool:blue"}, {["x"] = 2, ["y"] = 4, ["z"] = 9, ["name"] = "wool:blue"}, {["x"] = 2, ["y"] = 5, ["z"] = 6, ["name"] = "wool:blue"}, {["x"] = 2, ["y"] = 5, ["z"] = 7, ["name"] = "wool:blue"}, {["x"] = 2, ["y"] = 5, ["z"] = 8, ["name"] = "wool:blue"}, {["x"] = 2, ["y"] = 5, ["z"] = 9, ["name"] = "wool:blue"}, {["x"] = 2, ["y"] = 6, ["z"] = 6, ["name"] = "wool:blue"}, {["x"] = 2, ["y"] = 6, ["z"] = 7, ["name"] = "wool:blue"}, {["x"] = 2, ["y"] = 6, ["z"] = 8, ["name"] = "wool:blue"}, {["x"] = 2, ["y"] = 6, ["z"] = 9, ["name"] = "wool:blue"}, {["x"] = 2, ["y"] = 7, ["z"] = 6, ["name"] = "wool:blue"}, {["x"] = 2, ["y"] = 7, ["z"] = 7, ["name"] = "wool:blue"}, {["x"] = 2, ["y"] = 7, ["z"] = 8, ["name"] = "wool:blue"}, {["x"] = 2, ["y"] = 7, ["z"] = 9, ["name"] = "wool:blue"}, {["x"] = 2, ["y"] = 8, ["z"] = 6, ["name"] = "wool:blue"}, {["x"] = 2, ["y"] = 8, ["z"] = 7, ["name"] = "wool:blue"}, {["x"] = 2, ["y"] = 8, ["z"] = 8, ["name"] = "wool:blue"}, {["x"] = 2, ["y"] = 8, ["z"] = 9, ["name"] = "wool:blue"}, {["x"] = 3, ["y"] = 1, ["z"] = 4, ["name"] = "wool:blue"}, {["x"] = 3, ["y"] = 1, ["z"] = 5, ["name"] = "wool:blue"}, {["x"] = 3, ["y"] = 1, ["z"] = 6, ["name"] = "wool:blue"}, {["x"] = 3, ["y"] = 1, ["z"] = 7, ["name"] = "wool:blue"}, {["x"] = 3, ["y"] = 1, ["z"] = 8, ["name"] = "wool:blue"}, {["x"] = 3, ["y"] = 1, ["z"] = 9, ["name"] = "wool:blue"}, {["x"] = 3, ["y"] = 1, ["z"] = 10, ["name"] = "wool:blue"}, {["x"] = 3, ["y"] = 1, ["z"] = 11, ["name"] = "wool:blue"}, {["x"] = 3, ["y"] = 2, ["z"] = 4, ["name"] = "wool:blue"}, {["x"] = 3, ["y"] = 2, ["z"] = 5, ["name"] = "wool:blue"}, {["x"] = 3, ["y"] = 2, ["z"] = 6, ["name"] = "wool:blue"}, {["x"] = 3, ["y"] = 2, ["z"] = 7, ["name"] = "wool:blue"}, {["x"] = 3, ["y"] = 2, ["z"] = 8, ["name"] = "wool:blue"}, {["x"] = 3, ["y"] = 2, ["z"] = 9, ["name"] = "wool:blue"}, {["x"] = 3, ["y"] = 2, ["z"] = 10, ["name"] = "wool:blue"}, {["x"] = 3, ["y"] = 2, ["z"] = 11, ["name"] = "wool:blue"}, {["x"] = 3, ["y"] = 3, ["z"] = 4, ["name"] = "wool:blue"}, {["x"] = 3, ["y"] = 3, ["z"] = 5, ["name"] = "wool:blue"}, {["x"] = 3, ["y"] = 3, ["z"] = 6, ["name"] = "wool:blue"}, {["x"] = 3, ["y"] = 3, ["z"] = 7, ["name"] = "wool:blue"}, {["x"] = 3, ["y"] = 3, ["z"] = 8, ["name"] = "wool:blue"}, {["x"] = 3, ["y"] = 3, ["z"] = 9, ["name"] = "wool:blue"}, {["x"] = 3, ["y"] = 3, ["z"] = 10, ["name"] = "wool:blue"}, {["x"] = 3, ["y"] = 3, ["z"] = 11, ["name"] = "wool:blue"}, {["x"] = 3, ["y"] = 4, ["z"] = 4, ["name"] = "wool:blue"}, {["x"] = 3, ["y"] = 4, ["z"] = 5, ["name"] = "wool:blue"}, {["x"] = 3, ["y"] = 4, ["z"] = 6, ["name"] = "wool:blue"}, {["x"] = 3, ["y"] = 4, ["z"] = 7, ["name"] = "wool:blue"}, {["x"] = 3, ["y"] = 4, ["z"] = 8, ["name"] = "wool:blue"}, {["x"] = 3, ["y"] = 4, ["z"] = 9, ["name"] = "wool:blue"}, {["x"] = 3, ["y"] = 4, ["z"] = 10, ["name"] = "wool:blue"}, {["x"] = 3, ["y"] = 4, ["z"] = 11, ["name"] = "wool:blue"}, {["x"] = 3, ["y"] = 5, ["z"] = 4, ["name"] = "wool:blue"}, {["x"] = 3, ["y"] = 5, ["z"] = 5, ["name"] = "wool:blue"}, {["x"] = 3, ["y"] = 5, ["z"] = 6, ["name"] = "wool:blue"}, {["x"] = 3, ["y"] = 5, ["z"] = 7, ["name"] = "wool:blue"}, {["x"] = 3, ["y"] = 5, ["z"] = 8, ["name"] = "wool:blue"}, {["x"] = 3, ["y"] = 5, ["z"] = 9, ["name"] = "wool:blue"}, {["x"] = 3, ["y"] = 5, ["z"] = 10, ["name"] = "wool:blue"}, {["x"] = 3, ["y"] = 5, ["z"] = 11, ["name"] = "wool:blue"}, {["x"] = 3, ["y"] = 6, ["z"] = 4, ["name"] = "wool:blue"}, {["x"] = 3, ["y"] = 6, ["z"] = 5, ["name"] = "wool:blue"}, {["x"] = 3, ["y"] = 6, ["z"] = 6, ["name"] = "wool:blue"}, {["x"] = 3, ["y"] = 6, ["z"] = 7, ["name"] = "wool:blue"}, {["x"] = 3, ["y"] = 6, ["z"] = 8, ["name"] = "wool:blue"}, {["x"] = 3, ["y"] = 6, ["z"] = 9, ["name"] = "wool:blue"}, {["x"] = 3, ["y"] = 6, ["z"] = 10, ["name"] = "wool:blue"}, {["x"] = 3, ["y"] = 6, ["z"] = 11, ["name"] = "wool:blue"}, {["x"] = 3, ["y"] = 7, ["z"] = 4, ["name"] = "wool:blue"}, {["x"] = 3, ["y"] = 7, ["z"] = 5, ["name"] = "wool:blue"}, {["x"] = 3, ["y"] = 7, ["z"] = 6, ["name"] = "wool:blue"}, {["x"] = 3, ["y"] = 7, ["z"] = 7, ["name"] = "wool:blue"}, {["x"] = 3, ["y"] = 7, ["z"] = 8, ["name"] = "wool:blue"}, {["x"] = 3, ["y"] = 7, ["z"] = 9, ["name"] = "wool:blue"}, {["x"] = 3, ["y"] = 7, ["z"] = 10, ["name"] = "wool:blue"}, {["x"] = 3, ["y"] = 7, ["z"] = 11, ["name"] = "wool:blue"}, {["x"] = 3, ["y"] = 8, ["z"] = 4, ["name"] = "wool:blue"}, {["x"] = 3, ["y"] = 8, ["z"] = 5, ["name"] = "wool:blue"}, {["x"] = 3, ["y"] = 8, ["z"] = 6, ["name"] = "wool:blue"}, {["x"] = 3, ["y"] = 8, ["z"] = 7, ["name"] = "wool:blue"}, {["x"] = 3, ["y"] = 8, ["z"] = 8, ["name"] = "wool:blue"}, {["x"] = 3, ["y"] = 8, ["z"] = 9, ["name"] = "wool:blue"}, {["x"] = 3, ["y"] = 8, ["z"] = 10, ["name"] = "wool:blue"}, {["x"] = 3, ["y"] = 8, ["z"] = 11, ["name"] = "wool:blue"}, {["x"] = 4, ["y"] = 1, ["z"] = 3, ["name"] = "wool:blue"}, {["x"] = 4, ["y"] = 1, ["z"] = 4, ["name"] = "wool:blue"}, {["x"] = 4, ["y"] = 1, ["z"] = 5, ["name"] = "wool:blue"}, {["x"] = 4, ["y"] = 1, ["z"] = 6, ["name"] = "wool:blue"}, {["x"] = 4, ["y"] = 1, ["z"] = 7, ["name"] = "wool:blue"}, {["x"] = 4, ["y"] = 1, ["z"] = 8, ["name"] = "wool:blue"}, {["x"] = 4, ["y"] = 1, ["z"] = 9, ["name"] = "wool:blue"}, {["x"] = 4, ["y"] = 1, ["z"] = 10, ["name"] = "wool:blue"}, {["x"] = 4, ["y"] = 1, ["z"] = 11, ["name"] = "wool:blue"}, {["x"] = 4, ["y"] = 1, ["z"] = 12, ["name"] = "wool:blue"}, {["x"] = 4, ["y"] = 2, ["z"] = 3, ["name"] = "wool:blue"}, {["x"] = 4, ["y"] = 2, ["z"] = 4, ["name"] = "wool:blue"}, {["x"] = 4, ["y"] = 2, ["z"] = 5, ["name"] = "wool:blue"}, {["x"] = 4, ["y"] = 2, ["z"] = 6, ["name"] = "wool:blue"}, {["x"] = 4, ["y"] = 2, ["z"] = 7, ["name"] = "wool:blue"}, {["x"] = 4, ["y"] = 2, ["z"] = 8, ["name"] = "wool:blue"}, {["x"] = 4, ["y"] = 2, ["z"] = 9, ["name"] = "wool:blue"}, {["x"] = 4, ["y"] = 2, ["z"] = 10, ["name"] = "wool:blue"}, {["x"] = 4, ["y"] = 2, ["z"] = 11, ["name"] = "wool:blue"}, {["x"] = 4, ["y"] = 2, ["z"] = 12, ["name"] = "wool:blue"}, {["x"] = 4, ["y"] = 3, ["z"] = 3, ["name"] = "wool:blue"}, {["x"] = 4, ["y"] = 3, ["z"] = 4, ["name"] = "wool:blue"}, {["x"] = 4, ["y"] = 3, ["z"] = 5, ["name"] = "wool:blue"}, {["x"] = 4, ["y"] = 3, ["z"] = 6, ["name"] = "wool:blue"}, {["x"] = 4, ["y"] = 3, ["z"] = 7, ["name"] = "wool:blue"}, {["x"] = 4, ["y"] = 3, ["z"] = 8, ["name"] = "wool:blue"}, {["x"] = 4, ["y"] = 3, ["z"] = 9, ["name"] = "wool:blue"}, {["x"] = 4, ["y"] = 3, ["z"] = 10, ["name"] = "wool:blue"}, {["x"] = 4, ["y"] = 3, ["z"] = 11, ["name"] = "wool:blue"}, {["x"] = 4, ["y"] = 3, ["z"] = 12, ["name"] = "wool:blue"}, {["x"] = 4, ["y"] = 4, ["z"] = 3, ["name"] = "wool:blue"}, {["x"] = 4, ["y"] = 4, ["z"] = 4, ["name"] = "wool:blue"}, {["x"] = 4, ["y"] = 4, ["z"] = 5, ["name"] = "wool:blue"}, {["x"] = 4, ["y"] = 4, ["z"] = 6, ["name"] = "wool:blue"}, {["x"] = 4, ["y"] = 4, ["z"] = 7, ["name"] = "wool:blue"}, {["x"] = 4, ["y"] = 4, ["z"] = 8, ["name"] = "wool:blue"}, {["x"] = 4, ["y"] = 4, ["z"] = 9, ["name"] = "wool:blue"}, {["x"] = 4, ["y"] = 4, ["z"] = 10, ["name"] = "wool:blue"}, {["x"] = 4, ["y"] = 4, ["z"] = 11, ["name"] = "wool:blue"}, {["x"] = 4, ["y"] = 4, ["z"] = 12, ["name"] = "wool:blue"}, {["x"] = 4, ["y"] = 5, ["z"] = 3, ["name"] = "wool:blue"}, {["x"] = 4, ["y"] = 5, ["z"] = 4, ["name"] = "wool:blue"}, {["x"] = 4, ["y"] = 5, ["z"] = 5, ["name"] = "wool:blue"}, {["x"] = 4, ["y"] = 5, ["z"] = 6, ["name"] = "wool:blue"}, {["x"] = 4, ["y"] = 5, ["z"] = 7, ["name"] = "wool:blue"}, {["x"] = 4, ["y"] = 5, ["z"] = 8, ["name"] = "wool:blue"}, {["x"] = 4, ["y"] = 5, ["z"] = 9, ["name"] = "wool:blue"}, {["x"] = 4, ["y"] = 5, ["z"] = 10, ["name"] = "wool:blue"}, {["x"] = 4, ["y"] = 5, ["z"] = 11, ["name"] = "wool:blue"}, {["x"] = 4, ["y"] = 5, ["z"] = 12, ["name"] = "wool:blue"}, {["x"] = 4, ["y"] = 6, ["z"] = 3, ["name"] = "wool:blue"}, {["x"] = 4, ["y"] = 6, ["z"] = 4, ["name"] = "wool:blue"}, {["x"] = 4, ["y"] = 6, ["z"] = 5, ["name"] = "wool:blue"}, {["x"] = 4, ["y"] = 6, ["z"] = 6, ["name"] = "wool:blue"}, {["x"] = 4, ["y"] = 6, ["z"] = 7, ["name"] = "wool:blue"}, {["x"] = 4, ["y"] = 6, ["z"] = 8, ["name"] = "wool:blue"}, {["x"] = 4, ["y"] = 6, ["z"] = 9, ["name"] = "wool:blue"}, {["x"] = 4, ["y"] = 6, ["z"] = 10, ["name"] = "wool:blue"}, {["x"] = 4, ["y"] = 6, ["z"] = 11, ["name"] = "wool:blue"}, {["x"] = 4, ["y"] = 6, ["z"] = 12, ["name"] = "wool:blue"}, {["x"] = 4, ["y"] = 7, ["z"] = 3, ["name"] = "wool:blue"}, {["x"] = 4, ["y"] = 7, ["z"] = 4, ["name"] = "wool:blue"}, {["x"] = 4, ["y"] = 7, ["z"] = 5, ["name"] = "wool:blue"}, {["x"] = 4, ["y"] = 7, ["z"] = 6, ["name"] = "wool:blue"}, {["x"] = 4, ["y"] = 7, ["z"] = 7, ["name"] = "wool:blue"}, {["x"] = 4, ["y"] = 7, ["z"] = 8, ["name"] = "wool:blue"}, {["x"] = 4, ["y"] = 7, ["z"] = 9, ["name"] = "wool:blue"}, {["x"] = 4, ["y"] = 7, ["z"] = 10, ["name"] = "wool:blue"}, {["x"] = 4, ["y"] = 7, ["z"] = 11, ["name"] = "wool:blue"}, {["x"] = 4, ["y"] = 7, ["z"] = 12, ["name"] = "wool:blue"}, {["x"] = 4, ["y"] = 8, ["z"] = 3, ["name"] = "wool:blue"}, {["x"] = 4, ["y"] = 8, ["z"] = 4, ["name"] = "wool:blue"}, {["x"] = 4, ["y"] = 8, ["z"] = 5, ["name"] = "wool:blue"}, {["x"] = 4, ["y"] = 8, ["z"] = 6, ["name"] = "wool:blue"}, {["x"] = 4, ["y"] = 8, ["z"] = 7, ["name"] = "wool:blue"}, {["x"] = 4, ["y"] = 8, ["z"] = 8, ["name"] = "wool:blue"}, {["x"] = 4, ["y"] = 8, ["z"] = 9, ["name"] = "wool:blue"}, {["x"] = 4, ["y"] = 8, ["z"] = 10, ["name"] = "wool:blue"}, {["x"] = 4, ["y"] = 8, ["z"] = 11, ["name"] = "wool:blue"}, {["x"] = 4, ["y"] = 8, ["z"] = 12, ["name"] = "wool:blue"}, {["x"] = 5, ["y"] = 1, ["z"] = 3, ["name"] = "wool:blue"}, {["x"] = 5, ["y"] = 1, ["z"] = 4, ["name"] = "wool:blue"}, {["x"] = 5, ["y"] = 1, ["z"] = 5, ["name"] = "wool:blue"}, {["x"] = 5, ["y"] = 1, ["z"] = 6, ["name"] = "wool:blue"}, {["x"] = 5, ["y"] = 1, ["z"] = 7, ["name"] = "wool:blue"}, {["x"] = 5, ["y"] = 1, ["z"] = 8, ["name"] = "wool:blue"}, {["x"] = 5, ["y"] = 1, ["z"] = 9, ["name"] = "wool:blue"}, {["x"] = 5, ["y"] = 1, ["z"] = 10, ["name"] = "wool:blue"}, {["x"] = 5, ["y"] = 1, ["z"] = 11, ["name"] = "wool:blue"}, {["x"] = 5, ["y"] = 1, ["z"] = 12, ["name"] = "wool:blue"}, {["x"] = 5, ["y"] = 2, ["z"] = 3, ["name"] = "wool:blue"}, {["x"] = 5, ["y"] = 2, ["z"] = 4, ["name"] = "wool:blue"}, {["x"] = 5, ["y"] = 2, ["z"] = 5, ["name"] = "wool:blue"}, {["x"] = 5, ["y"] = 2, ["z"] = 6, ["name"] = "wool:blue"}, {["x"] = 5, ["y"] = 2, ["z"] = 7, ["name"] = "wool:blue"}, {["x"] = 5, ["y"] = 2, ["z"] = 8, ["name"] = "wool:blue"}, {["x"] = 5, ["y"] = 2, ["z"] = 9, ["name"] = "wool:blue"}, {["x"] = 5, ["y"] = 2, ["z"] = 10, ["name"] = "wool:blue"}, {["x"] = 5, ["y"] = 2, ["z"] = 11, ["name"] = "wool:blue"}, {["x"] = 5, ["y"] = 2, ["z"] = 12, ["name"] = "wool:blue"}, {["x"] = 5, ["y"] = 3, ["z"] = 3, ["name"] = "wool:blue"}, {["x"] = 5, ["y"] = 3, ["z"] = 4, ["name"] = "wool:blue"}, {["x"] = 5, ["y"] = 3, ["z"] = 5, ["name"] = "wool:blue"}, {["x"] = 5, ["y"] = 3, ["z"] = 6, ["name"] = "wool:blue"}, {["x"] = 5, ["y"] = 3, ["z"] = 7, ["name"] = "wool:blue"}, {["x"] = 5, ["y"] = 3, ["z"] = 8, ["name"] = "wool:blue"}, {["x"] = 5, ["y"] = 3, ["z"] = 9, ["name"] = "wool:blue"}, {["x"] = 5, ["y"] = 3, ["z"] = 10, ["name"] = "wool:blue"}, {["x"] = 5, ["y"] = 3, ["z"] = 11, ["name"] = "wool:blue"}, {["x"] = 5, ["y"] = 3, ["z"] = 12, ["name"] = "wool:blue"}, {["x"] = 5, ["y"] = 4, ["z"] = 3, ["name"] = "wool:blue"}, {["x"] = 5, ["y"] = 4, ["z"] = 4, ["name"] = "wool:blue"}, {["x"] = 5, ["y"] = 4, ["z"] = 5, ["name"] = "wool:blue"}, {["x"] = 5, ["y"] = 4, ["z"] = 6, ["name"] = "wool:blue"}, {["x"] = 5, ["y"] = 4, ["z"] = 7, ["name"] = "wool:blue"}, {["x"] = 5, ["y"] = 4, ["z"] = 8, ["name"] = "wool:blue"}, {["x"] = 5, ["y"] = 4, ["z"] = 9, ["name"] = "wool:blue"}, {["x"] = 5, ["y"] = 4, ["z"] = 10, ["name"] = "wool:blue"}, {["x"] = 5, ["y"] = 4, ["z"] = 11, ["name"] = "wool:blue"}, {["x"] = 5, ["y"] = 4, ["z"] = 12, ["name"] = "wool:blue"}, {["x"] = 5, ["y"] = 5, ["z"] = 3, ["name"] = "wool:blue"}, {["x"] = 5, ["y"] = 5, ["z"] = 4, ["name"] = "wool:blue"}, {["x"] = 5, ["y"] = 5, ["z"] = 5, ["name"] = "wool:blue"}, {["x"] = 5, ["y"] = 5, ["z"] = 6, ["name"] = "wool:blue"}, {["x"] = 5, ["y"] = 5, ["z"] = 7, ["name"] = "wool:blue"}, {["x"] = 5, ["y"] = 5, ["z"] = 8, ["name"] = "wool:blue"}, {["x"] = 5, ["y"] = 5, ["z"] = 9, ["name"] = "wool:blue"}, {["x"] = 5, ["y"] = 5, ["z"] = 10, ["name"] = "wool:blue"}, {["x"] = 5, ["y"] = 5, ["z"] = 11, ["name"] = "wool:blue"}, {["x"] = 5, ["y"] = 5, ["z"] = 12, ["name"] = "wool:blue"}, {["x"] = 5, ["y"] = 6, ["z"] = 3, ["name"] = "wool:blue"}, {["x"] = 5, ["y"] = 6, ["z"] = 4, ["name"] = "wool:blue"}, {["x"] = 5, ["y"] = 6, ["z"] = 5, ["name"] = "wool:blue"}, {["x"] = 5, ["y"] = 6, ["z"] = 6, ["name"] = "wool:blue"}, {["x"] = 5, ["y"] = 6, ["z"] = 7, ["name"] = "wool:blue"}, {["x"] = 5, ["y"] = 6, ["z"] = 8, ["name"] = "wool:blue"}, {["x"] = 5, ["y"] = 6, ["z"] = 9, ["name"] = "wool:blue"}, {["x"] = 5, ["y"] = 6, ["z"] = 10, ["name"] = "wool:blue"}, {["x"] = 5, ["y"] = 6, ["z"] = 11, ["name"] = "wool:blue"}, {["x"] = 5, ["y"] = 6, ["z"] = 12, ["name"] = "wool:blue"}, {["x"] = 5, ["y"] = 7, ["z"] = 3, ["name"] = "wool:blue"}, {["x"] = 5, ["y"] = 7, ["z"] = 4, ["name"] = "wool:blue"}, {["x"] = 5, ["y"] = 7, ["z"] = 5, ["name"] = "wool:blue"}, {["x"] = 5, ["y"] = 7, ["z"] = 6, ["name"] = "wool:blue"}, {["x"] = 5, ["y"] = 7, ["z"] = 7, ["name"] = "wool:blue"}, {["x"] = 5, ["y"] = 7, ["z"] = 8, ["name"] = "wool:blue"}, {["x"] = 5, ["y"] = 7, ["z"] = 9, ["name"] = "wool:blue"}, {["x"] = 5, ["y"] = 7, ["z"] = 10, ["name"] = "wool:blue"}, {["x"] = 5, ["y"] = 7, ["z"] = 11, ["name"] = "wool:blue"}, {["x"] = 5, ["y"] = 7, ["z"] = 12, ["name"] = "wool:blue"}, {["x"] = 5, ["y"] = 8, ["z"] = 3, ["name"] = "wool:blue"}, {["x"] = 5, ["y"] = 8, ["z"] = 4, ["name"] = "wool:blue"}, {["x"] = 5, ["y"] = 8, ["z"] = 5, ["name"] = "wool:blue"}, {["x"] = 5, ["y"] = 8, ["z"] = 6, ["name"] = "wool:blue"}, {["x"] = 5, ["y"] = 8, ["z"] = 7, ["name"] = "wool:blue"}, {["x"] = 5, ["y"] = 8, ["z"] = 8, ["name"] = "wool:blue"}, {["x"] = 5, ["y"] = 8, ["z"] = 9, ["name"] = "wool:blue"}, {["x"] = 5, ["y"] = 8, ["z"] = 10, ["name"] = "wool:blue"}, {["x"] = 5, ["y"] = 8, ["z"] = 11, ["name"] = "wool:blue"}, {["x"] = 5, ["y"] = 8, ["z"] = 12, ["name"] = "wool:blue"}, {["x"] = 6, ["y"] = 1, ["z"] = 2, ["name"] = "wool:blue"}, {["x"] = 6, ["y"] = 1, ["z"] = 3, ["name"] = "wool:blue"}, {["x"] = 6, ["y"] = 1, ["z"] = 4, ["name"] = "wool:blue"}, {["x"] = 6, ["y"] = 1, ["z"] = 5, ["name"] = "wool:blue"}, {["x"] = 6, ["y"] = 1, ["z"] = 6, ["name"] = "wool:blue"}, {["x"] = 6, ["y"] = 1, ["z"] = 7, ["name"] = "wool:blue"}, {["x"] = 6, ["y"] = 1, ["z"] = 8, ["name"] = "wool:blue"}, {["x"] = 6, ["y"] = 1, ["z"] = 9, ["name"] = "wool:blue"}, {["x"] = 6, ["y"] = 1, ["z"] = 10, ["name"] = "wool:blue"}, {["x"] = 6, ["y"] = 1, ["z"] = 11, ["name"] = "wool:blue"}, {["x"] = 6, ["y"] = 1, ["z"] = 12, ["name"] = "wool:blue"}, {["x"] = 6, ["y"] = 1, ["z"] = 13, ["name"] = "wool:blue"}, {["x"] = 6, ["y"] = 2, ["z"] = 2, ["name"] = "wool:blue"}, {["x"] = 6, ["y"] = 2, ["z"] = 3, ["name"] = "wool:blue"}, {["x"] = 6, ["y"] = 2, ["z"] = 4, ["name"] = "wool:blue"}, {["x"] = 6, ["y"] = 2, ["z"] = 5, ["name"] = "wool:blue"}, {["x"] = 6, ["y"] = 2, ["z"] = 6, ["name"] = "wool:blue"}, {["x"] = 6, ["y"] = 2, ["z"] = 7, ["name"] = "wool:blue"}, {["x"] = 6, ["y"] = 2, ["z"] = 8, ["name"] = "wool:blue"}, {["x"] = 6, ["y"] = 2, ["z"] = 9, ["name"] = "wool:blue"}, {["x"] = 6, ["y"] = 2, ["z"] = 10, ["name"] = "wool:blue"}, {["x"] = 6, ["y"] = 2, ["z"] = 11, ["name"] = "wool:blue"}, {["x"] = 6, ["y"] = 2, ["z"] = 12, ["name"] = "wool:blue"}, {["x"] = 6, ["y"] = 2, ["z"] = 13, ["name"] = "wool:blue"}, {["x"] = 6, ["y"] = 3, ["z"] = 2, ["name"] = "wool:blue"}, {["x"] = 6, ["y"] = 3, ["z"] = 3, ["name"] = "wool:blue"}, {["x"] = 6, ["y"] = 3, ["z"] = 4, ["name"] = "wool:blue"}, {["x"] = 6, ["y"] = 3, ["z"] = 5, ["name"] = "wool:blue"}, {["x"] = 6, ["y"] = 3, ["z"] = 6, ["name"] = "wool:blue"}, {["x"] = 6, ["y"] = 3, ["z"] = 7, ["name"] = "wool:blue"}, {["x"] = 6, ["y"] = 3, ["z"] = 8, ["name"] = "wool:blue"}, {["x"] = 6, ["y"] = 3, ["z"] = 9, ["name"] = "wool:blue"}, {["x"] = 6, ["y"] = 3, ["z"] = 10, ["name"] = "wool:blue"}, {["x"] = 6, ["y"] = 3, ["z"] = 11, ["name"] = "wool:blue"}, {["x"] = 6, ["y"] = 3, ["z"] = 12, ["name"] = "wool:blue"}, {["x"] = 6, ["y"] = 3, ["z"] = 13, ["name"] = "wool:blue"}, {["x"] = 6, ["y"] = 4, ["z"] = 2, ["name"] = "wool:blue"}, {["x"] = 6, ["y"] = 4, ["z"] = 3, ["name"] = "wool:blue"}, {["x"] = 6, ["y"] = 4, ["z"] = 4, ["name"] = "wool:blue"}, {["x"] = 6, ["y"] = 4, ["z"] = 5, ["name"] = "wool:blue"}, {["x"] = 6, ["y"] = 4, ["z"] = 6, ["name"] = "wool:blue"}, {["x"] = 6, ["y"] = 4, ["z"] = 7, ["name"] = "wool:blue"}, {["x"] = 6, ["y"] = 4, ["z"] = 8, ["name"] = "wool:blue"}, {["x"] = 6, ["y"] = 4, ["z"] = 9, ["name"] = "wool:blue"}, {["x"] = 6, ["y"] = 4, ["z"] = 10, ["name"] = "wool:blue"}, {["x"] = 6, ["y"] = 4, ["z"] = 11, ["name"] = "wool:blue"}, {["x"] = 6, ["y"] = 4, ["z"] = 12, ["name"] = "wool:blue"}, {["x"] = 6, ["y"] = 4, ["z"] = 13, ["name"] = "wool:blue"}, {["x"] = 6, ["y"] = 5, ["z"] = 2, ["name"] = "wool:blue"}, {["x"] = 6, ["y"] = 5, ["z"] = 3, ["name"] = "wool:blue"}, {["x"] = 6, ["y"] = 5, ["z"] = 4, ["name"] = "wool:blue"}, {["x"] = 6, ["y"] = 5, ["z"] = 5, ["name"] = "wool:blue"}, {["x"] = 6, ["y"] = 5, ["z"] = 6, ["name"] = "wool:blue"}, {["x"] = 6, ["y"] = 5, ["z"] = 7, ["name"] = "wool:blue"}, {["x"] = 6, ["y"] = 5, ["z"] = 8, ["name"] = "wool:blue"}, {["x"] = 6, ["y"] = 5, ["z"] = 9, ["name"] = "wool:blue"}, {["x"] = 6, ["y"] = 5, ["z"] = 10, ["name"] = "wool:blue"}, {["x"] = 6, ["y"] = 5, ["z"] = 11, ["name"] = "wool:blue"}, {["x"] = 6, ["y"] = 5, ["z"] = 12, ["name"] = "wool:blue"}, {["x"] = 6, ["y"] = 5, ["z"] = 13, ["name"] = "wool:blue"}, {["x"] = 6, ["y"] = 6, ["z"] = 2, ["name"] = "wool:blue"}, {["x"] = 6, ["y"] = 6, ["z"] = 3, ["name"] = "wool:blue"}, {["x"] = 6, ["y"] = 6, ["z"] = 4, ["name"] = "wool:blue"}, {["x"] = 6, ["y"] = 6, ["z"] = 5, ["name"] = "wool:blue"}, {["x"] = 6, ["y"] = 6, ["z"] = 6, ["name"] = "wool:blue"}, {["x"] = 6, ["y"] = 6, ["z"] = 7, ["name"] = "wool:blue"}, {["x"] = 6, ["y"] = 6, ["z"] = 8, ["name"] = "wool:blue"}, {["x"] = 6, ["y"] = 6, ["z"] = 9, ["name"] = "wool:blue"}, {["x"] = 6, ["y"] = 6, ["z"] = 10, ["name"] = "wool:blue"}, {["x"] = 6, ["y"] = 6, ["z"] = 11, ["name"] = "wool:blue"}, {["x"] = 6, ["y"] = 6, ["z"] = 12, ["name"] = "wool:blue"}, {["x"] = 6, ["y"] = 6, ["z"] = 13, ["name"] = "wool:blue"}, {["x"] = 6, ["y"] = 7, ["z"] = 2, ["name"] = "wool:blue"}, {["x"] = 6, ["y"] = 7, ["z"] = 3, ["name"] = "wool:blue"}, {["x"] = 6, ["y"] = 7, ["z"] = 4, ["name"] = "wool:blue"}, {["x"] = 6, ["y"] = 7, ["z"] = 5, ["name"] = "wool:blue"}, {["x"] = 6, ["y"] = 7, ["z"] = 6, ["name"] = "wool:blue"}, {["x"] = 6, ["y"] = 7, ["z"] = 7, ["name"] = "wool:blue"}, {["x"] = 6, ["y"] = 7, ["z"] = 8, ["name"] = "wool:blue"}, {["x"] = 6, ["y"] = 7, ["z"] = 9, ["name"] = "wool:blue"}, {["x"] = 6, ["y"] = 7, ["z"] = 10, ["name"] = "wool:blue"}, {["x"] = 6, ["y"] = 7, ["z"] = 11, ["name"] = "wool:blue"}, {["x"] = 6, ["y"] = 7, ["z"] = 12, ["name"] = "wool:blue"}, {["x"] = 6, ["y"] = 7, ["z"] = 13, ["name"] = "wool:blue"}, {["x"] = 6, ["y"] = 8, ["z"] = 2, ["name"] = "wool:blue"}, {["x"] = 6, ["y"] = 8, ["z"] = 3, ["name"] = "wool:blue"}, {["x"] = 6, ["y"] = 8, ["z"] = 4, ["name"] = "wool:blue"}, {["x"] = 6, ["y"] = 8, ["z"] = 5, ["name"] = "wool:blue"}, {["x"] = 6, ["y"] = 8, ["z"] = 6, ["name"] = "wool:blue"}, {["x"] = 6, ["y"] = 8, ["z"] = 7, ["name"] = "wool:blue"}, {["x"] = 6, ["y"] = 8, ["z"] = 8, ["name"] = "wool:blue"}, {["x"] = 6, ["y"] = 8, ["z"] = 9, ["name"] = "wool:blue"}, {["x"] = 6, ["y"] = 8, ["z"] = 10, ["name"] = "wool:blue"}, {["x"] = 6, ["y"] = 8, ["z"] = 11, ["name"] = "wool:blue"}, {["x"] = 6, ["y"] = 8, ["z"] = 12, ["name"] = "wool:blue"}, {["x"] = 6, ["y"] = 8, ["z"] = 13, ["name"] = "wool:blue"}, {["x"] = 7, ["y"] = 1, ["z"] = 2, ["name"] = "wool:blue"}, {["x"] = 7, ["y"] = 1, ["z"] = 3, ["name"] = "wool:blue"}, {["x"] = 7, ["y"] = 1, ["z"] = 4, ["name"] = "wool:blue"}, {["x"] = 7, ["y"] = 1, ["z"] = 5, ["name"] = "wool:blue"}, {["x"] = 7, ["y"] = 1, ["z"] = 6, ["name"] = "wool:blue"}, {["x"] = 7, ["y"] = 1, ["z"] = 7, ["name"] = "wool:blue"}, {["x"] = 7, ["y"] = 1, ["z"] = 8, ["name"] = "wool:blue"}, {["x"] = 7, ["y"] = 1, ["z"] = 9, ["name"] = "wool:blue"}, {["x"] = 7, ["y"] = 1, ["z"] = 10, ["name"] = "wool:blue"}, {["x"] = 7, ["y"] = 1, ["z"] = 11, ["name"] = "wool:blue"}, {["x"] = 7, ["y"] = 1, ["z"] = 12, ["name"] = "wool:blue"}, {["x"] = 7, ["y"] = 1, ["z"] = 13, ["name"] = "wool:blue"}, {["x"] = 7, ["y"] = 2, ["z"] = 2, ["name"] = "wool:blue"}, {["x"] = 7, ["y"] = 2, ["z"] = 3, ["name"] = "wool:blue"}, {["x"] = 7, ["y"] = 2, ["z"] = 4, ["name"] = "wool:blue"}, {["x"] = 7, ["y"] = 2, ["z"] = 5, ["name"] = "wool:blue"}, {["x"] = 7, ["y"] = 2, ["z"] = 6, ["name"] = "wool:blue"}, {["x"] = 7, ["y"] = 2, ["z"] = 7, ["name"] = "wool:blue"}, {["x"] = 7, ["y"] = 2, ["z"] = 8, ["name"] = "wool:blue"}, {["x"] = 7, ["y"] = 2, ["z"] = 9, ["name"] = "wool:blue"}, {["x"] = 7, ["y"] = 2, ["z"] = 10, ["name"] = "wool:blue"}, {["x"] = 7, ["y"] = 2, ["z"] = 11, ["name"] = "wool:blue"}, {["x"] = 7, ["y"] = 2, ["z"] = 12, ["name"] = "wool:blue"}, {["x"] = 7, ["y"] = 2, ["z"] = 13, ["name"] = "wool:blue"}, {["x"] = 7, ["y"] = 3, ["z"] = 2, ["name"] = "wool:blue"}, {["x"] = 7, ["y"] = 3, ["z"] = 3, ["name"] = "wool:blue"}, {["x"] = 7, ["y"] = 3, ["z"] = 4, ["name"] = "wool:blue"}, {["x"] = 7, ["y"] = 3, ["z"] = 5, ["name"] = "wool:blue"}, {["x"] = 7, ["y"] = 3, ["z"] = 6, ["name"] = "wool:blue"}, {["x"] = 7, ["y"] = 3, ["z"] = 7, ["name"] = "wool:blue"}, {["x"] = 7, ["y"] = 3, ["z"] = 8, ["name"] = "wool:blue"}, {["x"] = 7, ["y"] = 3, ["z"] = 9, ["name"] = "wool:blue"}, {["x"] = 7, ["y"] = 3, ["z"] = 10, ["name"] = "wool:blue"}, {["x"] = 7, ["y"] = 3, ["z"] = 11, ["name"] = "wool:blue"}, {["x"] = 7, ["y"] = 3, ["z"] = 12, ["name"] = "wool:blue"}, {["x"] = 7, ["y"] = 3, ["z"] = 13, ["name"] = "wool:blue"}, {["x"] = 7, ["y"] = 4, ["z"] = 2, ["name"] = "wool:blue"}, {["x"] = 7, ["y"] = 4, ["z"] = 3, ["name"] = "wool:blue"}, {["x"] = 7, ["y"] = 4, ["z"] = 4, ["name"] = "wool:blue"}, {["x"] = 7, ["y"] = 4, ["z"] = 5, ["name"] = "wool:blue"}, {["x"] = 7, ["y"] = 4, ["z"] = 6, ["name"] = "wool:blue"}, {["x"] = 7, ["y"] = 4, ["z"] = 7, ["name"] = "wool:blue"}, {["x"] = 7, ["y"] = 4, ["z"] = 8, ["name"] = "wool:blue"}, {["x"] = 7, ["y"] = 4, ["z"] = 9, ["name"] = "wool:blue"}, {["x"] = 7, ["y"] = 4, ["z"] = 10, ["name"] = "wool:blue"}, {["x"] = 7, ["y"] = 4, ["z"] = 11, ["name"] = "wool:blue"}, {["x"] = 7, ["y"] = 4, ["z"] = 12, ["name"] = "wool:blue"}, {["x"] = 7, ["y"] = 4, ["z"] = 13, ["name"] = "wool:blue"}, {["x"] = 7, ["y"] = 5, ["z"] = 2, ["name"] = "wool:blue"}, {["x"] = 7, ["y"] = 5, ["z"] = 3, ["name"] = "wool:blue"}, {["x"] = 7, ["y"] = 5, ["z"] = 4, ["name"] = "wool:blue"}, {["x"] = 7, ["y"] = 5, ["z"] = 5, ["name"] = "wool:blue"}, {["x"] = 7, ["y"] = 5, ["z"] = 6, ["name"] = "wool:blue"}, {["x"] = 7, ["y"] = 5, ["z"] = 7, ["name"] = "wool:blue"}, {["x"] = 7, ["y"] = 5, ["z"] = 8, ["name"] = "wool:blue"}, {["x"] = 7, ["y"] = 5, ["z"] = 9, ["name"] = "wool:blue"}, {["x"] = 7, ["y"] = 5, ["z"] = 10, ["name"] = "wool:blue"}, {["x"] = 7, ["y"] = 5, ["z"] = 11, ["name"] = "wool:blue"}, {["x"] = 7, ["y"] = 5, ["z"] = 12, ["name"] = "wool:blue"}, {["x"] = 7, ["y"] = 5, ["z"] = 13, ["name"] = "wool:blue"}, {["x"] = 7, ["y"] = 6, ["z"] = 2, ["name"] = "wool:blue"}, {["x"] = 7, ["y"] = 6, ["z"] = 3, ["name"] = "wool:blue"}, {["x"] = 7, ["y"] = 6, ["z"] = 4, ["name"] = "wool:blue"}, {["x"] = 7, ["y"] = 6, ["z"] = 5, ["name"] = "wool:blue"}, {["x"] = 7, ["y"] = 6, ["z"] = 6, ["name"] = "wool:blue"}, {["x"] = 7, ["y"] = 6, ["z"] = 7, ["name"] = "wool:blue"}, {["x"] = 7, ["y"] = 6, ["z"] = 8, ["name"] = "wool:blue"}, {["x"] = 7, ["y"] = 6, ["z"] = 9, ["name"] = "wool:blue"}, {["x"] = 7, ["y"] = 6, ["z"] = 10, ["name"] = "wool:blue"}, {["x"] = 7, ["y"] = 6, ["z"] = 11, ["name"] = "wool:blue"}, {["x"] = 7, ["y"] = 6, ["z"] = 12, ["name"] = "wool:blue"}, {["x"] = 7, ["y"] = 6, ["z"] = 13, ["name"] = "wool:blue"}, {["x"] = 7, ["y"] = 7, ["z"] = 2, ["name"] = "wool:blue"}, {["x"] = 7, ["y"] = 7, ["z"] = 3, ["name"] = "wool:blue"}, {["x"] = 7, ["y"] = 7, ["z"] = 4, ["name"] = "wool:blue"}, {["x"] = 7, ["y"] = 7, ["z"] = 5, ["name"] = "wool:blue"}, {["x"] = 7, ["y"] = 7, ["z"] = 6, ["name"] = "wool:blue"}, {["x"] = 7, ["y"] = 7, ["z"] = 7, ["name"] = "wool:blue"}, {["x"] = 7, ["y"] = 7, ["z"] = 8, ["name"] = "wool:blue"}, {["x"] = 7, ["y"] = 7, ["z"] = 9, ["name"] = "wool:blue"}, {["x"] = 7, ["y"] = 7, ["z"] = 10, ["name"] = "wool:blue"}, {["x"] = 7, ["y"] = 7, ["z"] = 11, ["name"] = "wool:blue"}, {["x"] = 7, ["y"] = 7, ["z"] = 12, ["name"] = "wool:blue"}, {["x"] = 7, ["y"] = 7, ["z"] = 13, ["name"] = "wool:blue"}, {["x"] = 7, ["y"] = 8, ["z"] = 2, ["name"] = "wool:blue"}, {["x"] = 7, ["y"] = 8, ["z"] = 3, ["name"] = "wool:blue"}, {["x"] = 7, ["y"] = 8, ["z"] = 4, ["name"] = "wool:blue"}, {["x"] = 7, ["y"] = 8, ["z"] = 5, ["name"] = "wool:blue"}, {["x"] = 7, ["y"] = 8, ["z"] = 6, ["name"] = "wool:blue"}, {["x"] = 7, ["y"] = 8, ["z"] = 7, ["name"] = "wool:blue"}, {["x"] = 7, ["y"] = 8, ["z"] = 8, ["name"] = "wool:blue"}, {["x"] = 7, ["y"] = 8, ["z"] = 9, ["name"] = "wool:blue"}, {["x"] = 7, ["y"] = 8, ["z"] = 10, ["name"] = "wool:blue"}, {["x"] = 7, ["y"] = 8, ["z"] = 11, ["name"] = "wool:blue"}, {["x"] = 7, ["y"] = 8, ["z"] = 12, ["name"] = "wool:blue"}, {["x"] = 7, ["y"] = 8, ["z"] = 13, ["name"] = "wool:blue"}, {["x"] = 8, ["y"] = 1, ["z"] = 2, ["name"] = "wool:blue"}, {["x"] = 8, ["y"] = 1, ["z"] = 3, ["name"] = "wool:blue"}, {["x"] = 8, ["y"] = 1, ["z"] = 4, ["name"] = "wool:blue"}, {["x"] = 8, ["y"] = 1, ["z"] = 5, ["name"] = "wool:blue"}, {["x"] = 8, ["y"] = 1, ["z"] = 6, ["name"] = "wool:blue"}, {["x"] = 8, ["y"] = 1, ["z"] = 7, ["name"] = "wool:blue"}, {["x"] = 8, ["y"] = 1, ["z"] = 8, ["name"] = "wool:blue"}, {["x"] = 8, ["y"] = 1, ["z"] = 9, ["name"] = "wool:blue"}, {["x"] = 8, ["y"] = 1, ["z"] = 10, ["name"] = "wool:blue"}, {["x"] = 8, ["y"] = 1, ["z"] = 11, ["name"] = "wool:blue"}, {["x"] = 8, ["y"] = 1, ["z"] = 12, ["name"] = "wool:blue"}, {["x"] = 8, ["y"] = 1, ["z"] = 13, ["name"] = "wool:blue"}, {["x"] = 8, ["y"] = 2, ["z"] = 2, ["name"] = "wool:blue"}, {["x"] = 8, ["y"] = 2, ["z"] = 3, ["name"] = "wool:blue"}, {["x"] = 8, ["y"] = 2, ["z"] = 4, ["name"] = "wool:blue"}, {["x"] = 8, ["y"] = 2, ["z"] = 5, ["name"] = "wool:blue"}, {["x"] = 8, ["y"] = 2, ["z"] = 6, ["name"] = "wool:blue"}, {["x"] = 8, ["y"] = 2, ["z"] = 7, ["name"] = "wool:blue"}, {["x"] = 8, ["y"] = 2, ["z"] = 8, ["name"] = "wool:blue"}, {["x"] = 8, ["y"] = 2, ["z"] = 9, ["name"] = "wool:blue"}, {["x"] = 8, ["y"] = 2, ["z"] = 10, ["name"] = "wool:blue"}, {["x"] = 8, ["y"] = 2, ["z"] = 11, ["name"] = "wool:blue"}, {["x"] = 8, ["y"] = 2, ["z"] = 12, ["name"] = "wool:blue"}, {["x"] = 8, ["y"] = 2, ["z"] = 13, ["name"] = "wool:blue"}, {["x"] = 8, ["y"] = 3, ["z"] = 2, ["name"] = "wool:blue"}, {["x"] = 8, ["y"] = 3, ["z"] = 3, ["name"] = "wool:blue"}, {["x"] = 8, ["y"] = 3, ["z"] = 4, ["name"] = "wool:blue"}, {["x"] = 8, ["y"] = 3, ["z"] = 5, ["name"] = "wool:blue"}, {["x"] = 8, ["y"] = 3, ["z"] = 6, ["name"] = "wool:blue"}, {["x"] = 8, ["y"] = 3, ["z"] = 7, ["name"] = "wool:blue"}, {["x"] = 8, ["y"] = 3, ["z"] = 8, ["name"] = "wool:blue"}, {["x"] = 8, ["y"] = 3, ["z"] = 9, ["name"] = "wool:blue"}, {["x"] = 8, ["y"] = 3, ["z"] = 10, ["name"] = "wool:blue"}, {["x"] = 8, ["y"] = 3, ["z"] = 11, ["name"] = "wool:blue"}, {["x"] = 8, ["y"] = 3, ["z"] = 12, ["name"] = "wool:blue"}, {["x"] = 8, ["y"] = 3, ["z"] = 13, ["name"] = "wool:blue"}, {["x"] = 8, ["y"] = 4, ["z"] = 2, ["name"] = "wool:blue"}, {["x"] = 8, ["y"] = 4, ["z"] = 3, ["name"] = "wool:blue"}, {["x"] = 8, ["y"] = 4, ["z"] = 4, ["name"] = "wool:blue"}, {["x"] = 8, ["y"] = 4, ["z"] = 5, ["name"] = "wool:blue"}, {["x"] = 8, ["y"] = 4, ["z"] = 6, ["name"] = "wool:blue"}, {["x"] = 8, ["y"] = 4, ["z"] = 7, ["name"] = "wool:blue"}, {["x"] = 8, ["y"] = 4, ["z"] = 8, ["name"] = "wool:blue"}, {["x"] = 8, ["y"] = 4, ["z"] = 9, ["name"] = "wool:blue"}, {["x"] = 8, ["y"] = 4, ["z"] = 10, ["name"] = "wool:blue"}, {["x"] = 8, ["y"] = 4, ["z"] = 11, ["name"] = "wool:blue"}, {["x"] = 8, ["y"] = 4, ["z"] = 12, ["name"] = "wool:blue"}, {["x"] = 8, ["y"] = 4, ["z"] = 13, ["name"] = "wool:blue"}, {["x"] = 8, ["y"] = 5, ["z"] = 2, ["name"] = "wool:blue"}, {["x"] = 8, ["y"] = 5, ["z"] = 3, ["name"] = "wool:blue"}, {["x"] = 8, ["y"] = 5, ["z"] = 4, ["name"] = "wool:blue"}, {["x"] = 8, ["y"] = 5, ["z"] = 5, ["name"] = "wool:blue"}, {["x"] = 8, ["y"] = 5, ["z"] = 6, ["name"] = "wool:blue"}, {["x"] = 8, ["y"] = 5, ["z"] = 7, ["name"] = "wool:blue"}, {["x"] = 8, ["y"] = 5, ["z"] = 8, ["name"] = "wool:blue"}, {["x"] = 8, ["y"] = 5, ["z"] = 9, ["name"] = "wool:blue"}, {["x"] = 8, ["y"] = 5, ["z"] = 10, ["name"] = "wool:blue"}, {["x"] = 8, ["y"] = 5, ["z"] = 11, ["name"] = "wool:blue"}, {["x"] = 8, ["y"] = 5, ["z"] = 12, ["name"] = "wool:blue"}, {["x"] = 8, ["y"] = 5, ["z"] = 13, ["name"] = "wool:blue"}, {["x"] = 8, ["y"] = 6, ["z"] = 2, ["name"] = "wool:blue"}, {["x"] = 8, ["y"] = 6, ["z"] = 3, ["name"] = "wool:blue"}, {["x"] = 8, ["y"] = 6, ["z"] = 4, ["name"] = "wool:blue"}, {["x"] = 8, ["y"] = 6, ["z"] = 5, ["name"] = "wool:blue"}, {["x"] = 8, ["y"] = 6, ["z"] = 6, ["name"] = "wool:blue"}, {["x"] = 8, ["y"] = 6, ["z"] = 7, ["name"] = "wool:blue"}, {["x"] = 8, ["y"] = 6, ["z"] = 8, ["name"] = "wool:blue"}, {["x"] = 8, ["y"] = 6, ["z"] = 9, ["name"] = "wool:blue"}, {["x"] = 8, ["y"] = 6, ["z"] = 10, ["name"] = "wool:blue"}, {["x"] = 8, ["y"] = 6, ["z"] = 11, ["name"] = "wool:blue"}, {["x"] = 8, ["y"] = 6, ["z"] = 12, ["name"] = "wool:blue"}, {["x"] = 8, ["y"] = 6, ["z"] = 13, ["name"] = "wool:blue"}, {["x"] = 8, ["y"] = 7, ["z"] = 2, ["name"] = "wool:blue"}, {["x"] = 8, ["y"] = 7, ["z"] = 3, ["name"] = "wool:blue"}, {["x"] = 8, ["y"] = 7, ["z"] = 4, ["name"] = "wool:blue"}, {["x"] = 8, ["y"] = 7, ["z"] = 5, ["name"] = "wool:blue"}, {["x"] = 8, ["y"] = 7, ["z"] = 6, ["name"] = "wool:blue"}, {["x"] = 8, ["y"] = 7, ["z"] = 7, ["name"] = "wool:blue"}, {["x"] = 8, ["y"] = 7, ["z"] = 8, ["name"] = "wool:blue"}, {["x"] = 8, ["y"] = 7, ["z"] = 9, ["name"] = "wool:blue"}, {["x"] = 8, ["y"] = 7, ["z"] = 10, ["name"] = "wool:blue"}, {["x"] = 8, ["y"] = 7, ["z"] = 11, ["name"] = "wool:blue"}, {["x"] = 8, ["y"] = 7, ["z"] = 12, ["name"] = "wool:blue"}, {["x"] = 8, ["y"] = 7, ["z"] = 13, ["name"] = "wool:blue"}, {["x"] = 8, ["y"] = 8, ["z"] = 2, ["name"] = "wool:blue"}, {["x"] = 8, ["y"] = 8, ["z"] = 3, ["name"] = "wool:blue"}, {["x"] = 8, ["y"] = 8, ["z"] = 4, ["name"] = "wool:blue"}, {["x"] = 8, ["y"] = 8, ["z"] = 5, ["name"] = "wool:blue"}, {["x"] = 8, ["y"] = 8, ["z"] = 6, ["name"] = "wool:blue"}, {["x"] = 8, ["y"] = 8, ["z"] = 7, ["name"] = "wool:blue"}, {["x"] = 8, ["y"] = 8, ["z"] = 8, ["name"] = "wool:blue"}, {["x"] = 8, ["y"] = 8, ["z"] = 9, ["name"] = "wool:blue"}, {["x"] = 8, ["y"] = 8, ["z"] = 10, ["name"] = "wool:blue"}, {["x"] = 8, ["y"] = 8, ["z"] = 11, ["name"] = "wool:blue"}, {["x"] = 8, ["y"] = 8, ["z"] = 12, ["name"] = "wool:blue"}, {["x"] = 8, ["y"] = 8, ["z"] = 13, ["name"] = "wool:blue"}, {["x"] = 9, ["y"] = 1, ["z"] = 2, ["name"] = "wool:blue"}, {["x"] = 9, ["y"] = 1, ["z"] = 3, ["name"] = "wool:blue"}, {["x"] = 9, ["y"] = 1, ["z"] = 4, ["name"] = "wool:blue"}, {["x"] = 9, ["y"] = 1, ["z"] = 5, ["name"] = "wool:blue"}, {["x"] = 9, ["y"] = 1, ["z"] = 6, ["name"] = "wool:blue"}, {["x"] = 9, ["y"] = 1, ["z"] = 7, ["name"] = "wool:blue"}, {["x"] = 9, ["y"] = 1, ["z"] = 8, ["name"] = "wool:blue"}, {["x"] = 9, ["y"] = 1, ["z"] = 9, ["name"] = "wool:blue"}, {["x"] = 9, ["y"] = 1, ["z"] = 10, ["name"] = "wool:blue"}, {["x"] = 9, ["y"] = 1, ["z"] = 11, ["name"] = "wool:blue"}, {["x"] = 9, ["y"] = 1, ["z"] = 12, ["name"] = "wool:blue"}, {["x"] = 9, ["y"] = 1, ["z"] = 13, ["name"] = "wool:blue"}, {["x"] = 9, ["y"] = 2, ["z"] = 2, ["name"] = "wool:blue"}, {["x"] = 9, ["y"] = 2, ["z"] = 3, ["name"] = "wool:blue"}, {["x"] = 9, ["y"] = 2, ["z"] = 4, ["name"] = "wool:blue"}, {["x"] = 9, ["y"] = 2, ["z"] = 5, ["name"] = "wool:blue"}, {["x"] = 9, ["y"] = 2, ["z"] = 6, ["name"] = "wool:blue"}, {["x"] = 9, ["y"] = 2, ["z"] = 7, ["name"] = "wool:blue"}, {["x"] = 9, ["y"] = 2, ["z"] = 8, ["name"] = "wool:blue"}, {["x"] = 9, ["y"] = 2, ["z"] = 9, ["name"] = "wool:blue"}, {["x"] = 9, ["y"] = 2, ["z"] = 10, ["name"] = "wool:blue"}, {["x"] = 9, ["y"] = 2, ["z"] = 11, ["name"] = "wool:blue"}, {["x"] = 9, ["y"] = 2, ["z"] = 12, ["name"] = "wool:blue"}, {["x"] = 9, ["y"] = 2, ["z"] = 13, ["name"] = "wool:blue"}, {["x"] = 9, ["y"] = 3, ["z"] = 2, ["name"] = "wool:blue"}, {["x"] = 9, ["y"] = 3, ["z"] = 3, ["name"] = "wool:blue"}, {["x"] = 9, ["y"] = 3, ["z"] = 4, ["name"] = "wool:blue"}, {["x"] = 9, ["y"] = 3, ["z"] = 5, ["name"] = "wool:blue"}, {["x"] = 9, ["y"] = 3, ["z"] = 6, ["name"] = "wool:blue"}, {["x"] = 9, ["y"] = 3, ["z"] = 7, ["name"] = "wool:blue"}, {["x"] = 9, ["y"] = 3, ["z"] = 8, ["name"] = "wool:blue"}, {["x"] = 9, ["y"] = 3, ["z"] = 9, ["name"] = "wool:blue"}, {["x"] = 9, ["y"] = 3, ["z"] = 10, ["name"] = "wool:blue"}, {["x"] = 9, ["y"] = 3, ["z"] = 11, ["name"] = "wool:blue"}, {["x"] = 9, ["y"] = 3, ["z"] = 12, ["name"] = "wool:blue"}, {["x"] = 9, ["y"] = 3, ["z"] = 13, ["name"] = "wool:blue"}, {["x"] = 9, ["y"] = 4, ["z"] = 2, ["name"] = "wool:blue"}, {["x"] = 9, ["y"] = 4, ["z"] = 3, ["name"] = "wool:blue"}, {["x"] = 9, ["y"] = 4, ["z"] = 4, ["name"] = "wool:blue"}, {["x"] = 9, ["y"] = 4, ["z"] = 5, ["name"] = "wool:blue"}, {["x"] = 9, ["y"] = 4, ["z"] = 6, ["name"] = "wool:blue"}, {["x"] = 9, ["y"] = 4, ["z"] = 7, ["name"] = "wool:blue"}, {["x"] = 9, ["y"] = 4, ["z"] = 8, ["name"] = "wool:blue"}, {["x"] = 9, ["y"] = 4, ["z"] = 9, ["name"] = "wool:blue"}, {["x"] = 9, ["y"] = 4, ["z"] = 10, ["name"] = "wool:blue"}, {["x"] = 9, ["y"] = 4, ["z"] = 11, ["name"] = "wool:blue"}, {["x"] = 9, ["y"] = 4, ["z"] = 12, ["name"] = "wool:blue"}, {["x"] = 9, ["y"] = 4, ["z"] = 13, ["name"] = "wool:blue"}, {["x"] = 9, ["y"] = 5, ["z"] = 2, ["name"] = "wool:blue"}, {["x"] = 9, ["y"] = 5, ["z"] = 3, ["name"] = "wool:blue"}, {["x"] = 9, ["y"] = 5, ["z"] = 4, ["name"] = "wool:blue"}, {["x"] = 9, ["y"] = 5, ["z"] = 5, ["name"] = "wool:blue"}, {["x"] = 9, ["y"] = 5, ["z"] = 6, ["name"] = "wool:blue"}, {["x"] = 9, ["y"] = 5, ["z"] = 7, ["name"] = "wool:blue"}, {["x"] = 9, ["y"] = 5, ["z"] = 8, ["name"] = "wool:blue"}, {["x"] = 9, ["y"] = 5, ["z"] = 9, ["name"] = "wool:blue"}, {["x"] = 9, ["y"] = 5, ["z"] = 10, ["name"] = "wool:blue"}, {["x"] = 9, ["y"] = 5, ["z"] = 11, ["name"] = "wool:blue"}, {["x"] = 9, ["y"] = 5, ["z"] = 12, ["name"] = "wool:blue"}, {["x"] = 9, ["y"] = 5, ["z"] = 13, ["name"] = "wool:blue"}, {["x"] = 9, ["y"] = 6, ["z"] = 2, ["name"] = "wool:blue"}, {["x"] = 9, ["y"] = 6, ["z"] = 3, ["name"] = "wool:blue"}, {["x"] = 9, ["y"] = 6, ["z"] = 4, ["name"] = "wool:blue"}, {["x"] = 9, ["y"] = 6, ["z"] = 5, ["name"] = "wool:blue"}, {["x"] = 9, ["y"] = 6, ["z"] = 6, ["name"] = "wool:blue"}, {["x"] = 9, ["y"] = 6, ["z"] = 7, ["name"] = "wool:blue"}, {["x"] = 9, ["y"] = 6, ["z"] = 8, ["name"] = "wool:blue"}, {["x"] = 9, ["y"] = 6, ["z"] = 9, ["name"] = "wool:blue"}, {["x"] = 9, ["y"] = 6, ["z"] = 10, ["name"] = "wool:blue"}, {["x"] = 9, ["y"] = 6, ["z"] = 11, ["name"] = "wool:blue"}, {["x"] = 9, ["y"] = 6, ["z"] = 12, ["name"] = "wool:blue"}, {["x"] = 9, ["y"] = 6, ["z"] = 13, ["name"] = "wool:blue"}, {["x"] = 9, ["y"] = 7, ["z"] = 2, ["name"] = "wool:blue"}, {["x"] = 9, ["y"] = 7, ["z"] = 3, ["name"] = "wool:blue"}, {["x"] = 9, ["y"] = 7, ["z"] = 4, ["name"] = "wool:blue"}, {["x"] = 9, ["y"] = 7, ["z"] = 5, ["name"] = "wool:blue"}, {["x"] = 9, ["y"] = 7, ["z"] = 6, ["name"] = "wool:blue"}, {["x"] = 9, ["y"] = 7, ["z"] = 7, ["name"] = "wool:blue"}, {["x"] = 9, ["y"] = 7, ["z"] = 8, ["name"] = "wool:blue"}, {["x"] = 9, ["y"] = 7, ["z"] = 9, ["name"] = "wool:blue"}, {["x"] = 9, ["y"] = 7, ["z"] = 10, ["name"] = "wool:blue"}, {["x"] = 9, ["y"] = 7, ["z"] = 11, ["name"] = "wool:blue"}, {["x"] = 9, ["y"] = 7, ["z"] = 12, ["name"] = "wool:blue"}, {["x"] = 9, ["y"] = 7, ["z"] = 13, ["name"] = "wool:blue"}, {["x"] = 9, ["y"] = 8, ["z"] = 2, ["name"] = "wool:blue"}, {["x"] = 9, ["y"] = 8, ["z"] = 3, ["name"] = "wool:blue"}, {["x"] = 9, ["y"] = 8, ["z"] = 4, ["name"] = "wool:blue"}, {["x"] = 9, ["y"] = 8, ["z"] = 5, ["name"] = "wool:blue"}, {["x"] = 9, ["y"] = 8, ["z"] = 6, ["name"] = "wool:blue"}, {["x"] = 9, ["y"] = 8, ["z"] = 7, ["name"] = "wool:blue"}, {["x"] = 9, ["y"] = 8, ["z"] = 8, ["name"] = "wool:blue"}, {["x"] = 9, ["y"] = 8, ["z"] = 9, ["name"] = "wool:blue"}, {["x"] = 9, ["y"] = 8, ["z"] = 10, ["name"] = "wool:blue"}, {["x"] = 9, ["y"] = 8, ["z"] = 11, ["name"] = "wool:blue"}, {["x"] = 9, ["y"] = 8, ["z"] = 12, ["name"] = "wool:blue"}, {["x"] = 9, ["y"] = 8, ["z"] = 13, ["name"] = "wool:blue"}, {["x"] = 10, ["y"] = 1, ["z"] = 3, ["name"] = "wool:blue"}, {["x"] = 10, ["y"] = 1, ["z"] = 4, ["name"] = "wool:blue"}, {["x"] = 10, ["y"] = 1, ["z"] = 5, ["name"] = "wool:blue"}, {["x"] = 10, ["y"] = 1, ["z"] = 6, ["name"] = "wool:blue"}, {["x"] = 10, ["y"] = 1, ["z"] = 7, ["name"] = "wool:blue"}, {["x"] = 10, ["y"] = 1, ["z"] = 8, ["name"] = "wool:blue"}, {["x"] = 10, ["y"] = 1, ["z"] = 9, ["name"] = "wool:blue"}, {["x"] = 10, ["y"] = 1, ["z"] = 10, ["name"] = "wool:blue"}, {["x"] = 10, ["y"] = 1, ["z"] = 11, ["name"] = "wool:blue"}, {["x"] = 10, ["y"] = 1, ["z"] = 12, ["name"] = "wool:blue"}, {["x"] = 10, ["y"] = 2, ["z"] = 3, ["name"] = "wool:blue"}, {["x"] = 10, ["y"] = 2, ["z"] = 4, ["name"] = "wool:blue"}, {["x"] = 10, ["y"] = 2, ["z"] = 5, ["name"] = "wool:blue"}, {["x"] = 10, ["y"] = 2, ["z"] = 6, ["name"] = "wool:blue"}, {["x"] = 10, ["y"] = 2, ["z"] = 7, ["name"] = "wool:blue"}, {["x"] = 10, ["y"] = 2, ["z"] = 8, ["name"] = "wool:blue"}, {["x"] = 10, ["y"] = 2, ["z"] = 9, ["name"] = "wool:blue"}, {["x"] = 10, ["y"] = 2, ["z"] = 10, ["name"] = "wool:blue"}, {["x"] = 10, ["y"] = 2, ["z"] = 11, ["name"] = "wool:blue"}, {["x"] = 10, ["y"] = 2, ["z"] = 12, ["name"] = "wool:blue"}, {["x"] = 10, ["y"] = 3, ["z"] = 3, ["name"] = "wool:blue"}, {["x"] = 10, ["y"] = 3, ["z"] = 4, ["name"] = "wool:blue"}, {["x"] = 10, ["y"] = 3, ["z"] = 5, ["name"] = "wool:blue"}, {["x"] = 10, ["y"] = 3, ["z"] = 6, ["name"] = "wool:blue"}, {["x"] = 10, ["y"] = 3, ["z"] = 7, ["name"] = "wool:blue"}, {["x"] = 10, ["y"] = 3, ["z"] = 8, ["name"] = "wool:blue"}, {["x"] = 10, ["y"] = 3, ["z"] = 9, ["name"] = "wool:blue"}, {["x"] = 10, ["y"] = 3, ["z"] = 10, ["name"] = "wool:blue"}, {["x"] = 10, ["y"] = 3, ["z"] = 11, ["name"] = "wool:blue"}, {["x"] = 10, ["y"] = 3, ["z"] = 12, ["name"] = "wool:blue"}, {["x"] = 10, ["y"] = 4, ["z"] = 3, ["name"] = "wool:blue"}, {["x"] = 10, ["y"] = 4, ["z"] = 4, ["name"] = "wool:blue"}, {["x"] = 10, ["y"] = 4, ["z"] = 5, ["name"] = "wool:blue"}, {["x"] = 10, ["y"] = 4, ["z"] = 6, ["name"] = "wool:blue"}, {["x"] = 10, ["y"] = 4, ["z"] = 7, ["name"] = "wool:blue"}, {["x"] = 10, ["y"] = 4, ["z"] = 8, ["name"] = "wool:blue"}, {["x"] = 10, ["y"] = 4, ["z"] = 9, ["name"] = "wool:blue"}, {["x"] = 10, ["y"] = 4, ["z"] = 10, ["name"] = "wool:blue"}, {["x"] = 10, ["y"] = 4, ["z"] = 11, ["name"] = "wool:blue"}, {["x"] = 10, ["y"] = 4, ["z"] = 12, ["name"] = "wool:blue"}, {["x"] = 10, ["y"] = 5, ["z"] = 3, ["name"] = "wool:blue"}, {["x"] = 10, ["y"] = 5, ["z"] = 4, ["name"] = "wool:blue"}, {["x"] = 10, ["y"] = 5, ["z"] = 5, ["name"] = "wool:blue"}, {["x"] = 10, ["y"] = 5, ["z"] = 6, ["name"] = "wool:blue"}, {["x"] = 10, ["y"] = 5, ["z"] = 7, ["name"] = "wool:blue"}, {["x"] = 10, ["y"] = 5, ["z"] = 8, ["name"] = "wool:blue"}, {["x"] = 10, ["y"] = 5, ["z"] = 9, ["name"] = "wool:blue"}, {["x"] = 10, ["y"] = 5, ["z"] = 10, ["name"] = "wool:blue"}, {["x"] = 10, ["y"] = 5, ["z"] = 11, ["name"] = "wool:blue"}, {["x"] = 10, ["y"] = 5, ["z"] = 12, ["name"] = "wool:blue"}, {["x"] = 10, ["y"] = 6, ["z"] = 3, ["name"] = "wool:blue"}, {["x"] = 10, ["y"] = 6, ["z"] = 4, ["name"] = "wool:blue"}, {["x"] = 10, ["y"] = 6, ["z"] = 5, ["name"] = "wool:blue"}, {["x"] = 10, ["y"] = 6, ["z"] = 6, ["name"] = "wool:blue"}, {["x"] = 10, ["y"] = 6, ["z"] = 7, ["name"] = "wool:blue"}, {["x"] = 10, ["y"] = 6, ["z"] = 8, ["name"] = "wool:blue"}, {["x"] = 10, ["y"] = 6, ["z"] = 9, ["name"] = "wool:blue"}, {["x"] = 10, ["y"] = 6, ["z"] = 10, ["name"] = "wool:blue"}, {["x"] = 10, ["y"] = 6, ["z"] = 11, ["name"] = "wool:blue"}, {["x"] = 10, ["y"] = 6, ["z"] = 12, ["name"] = "wool:blue"}, {["x"] = 10, ["y"] = 7, ["z"] = 3, ["name"] = "wool:blue"}, {["x"] = 10, ["y"] = 7, ["z"] = 4, ["name"] = "wool:blue"}, {["x"] = 10, ["y"] = 7, ["z"] = 5, ["name"] = "wool:blue"}, {["x"] = 10, ["y"] = 7, ["z"] = 6, ["name"] = "wool:blue"}, {["x"] = 10, ["y"] = 7, ["z"] = 7, ["name"] = "wool:blue"}, {["x"] = 10, ["y"] = 7, ["z"] = 8, ["name"] = "wool:blue"}, {["x"] = 10, ["y"] = 7, ["z"] = 9, ["name"] = "wool:blue"}, {["x"] = 10, ["y"] = 7, ["z"] = 10, ["name"] = "wool:blue"}, {["x"] = 10, ["y"] = 7, ["z"] = 11, ["name"] = "wool:blue"}, {["x"] = 10, ["y"] = 7, ["z"] = 12, ["name"] = "wool:blue"}, {["x"] = 10, ["y"] = 8, ["z"] = 3, ["name"] = "wool:blue"}, {["x"] = 10, ["y"] = 8, ["z"] = 4, ["name"] = "wool:blue"}, {["x"] = 10, ["y"] = 8, ["z"] = 5, ["name"] = "wool:blue"}, {["x"] = 10, ["y"] = 8, ["z"] = 6, ["name"] = "wool:blue"}, {["x"] = 10, ["y"] = 8, ["z"] = 7, ["name"] = "wool:blue"}, {["x"] = 10, ["y"] = 8, ["z"] = 8, ["name"] = "wool:blue"}, {["x"] = 10, ["y"] = 8, ["z"] = 9, ["name"] = "wool:blue"}, {["x"] = 10, ["y"] = 8, ["z"] = 10, ["name"] = "wool:blue"}, {["x"] = 10, ["y"] = 8, ["z"] = 11, ["name"] = "wool:blue"}, {["x"] = 10, ["y"] = 8, ["z"] = 12, ["name"] = "wool:blue"}, {["x"] = 11, ["y"] = 1, ["z"] = 3, ["name"] = "wool:blue"}, {["x"] = 11, ["y"] = 1, ["z"] = 4, ["name"] = "wool:blue"}, {["x"] = 11, ["y"] = 1, ["z"] = 5, ["name"] = "wool:blue"}, {["x"] = 11, ["y"] = 1, ["z"] = 6, ["name"] = "wool:blue"}, {["x"] = 11, ["y"] = 1, ["z"] = 7, ["name"] = "wool:blue"}, {["x"] = 11, ["y"] = 1, ["z"] = 8, ["name"] = "wool:blue"}, {["x"] = 11, ["y"] = 1, ["z"] = 9, ["name"] = "wool:blue"}, {["x"] = 11, ["y"] = 1, ["z"] = 10, ["name"] = "wool:blue"}, {["x"] = 11, ["y"] = 1, ["z"] = 11, ["name"] = "wool:blue"}, {["x"] = 11, ["y"] = 1, ["z"] = 12, ["name"] = "wool:blue"}, {["x"] = 11, ["y"] = 2, ["z"] = 3, ["name"] = "wool:blue"}, {["x"] = 11, ["y"] = 2, ["z"] = 4, ["name"] = "wool:blue"}, {["x"] = 11, ["y"] = 2, ["z"] = 5, ["name"] = "wool:blue"}, {["x"] = 11, ["y"] = 2, ["z"] = 6, ["name"] = "wool:blue"}, {["x"] = 11, ["y"] = 2, ["z"] = 7, ["name"] = "wool:blue"}, {["x"] = 11, ["y"] = 2, ["z"] = 8, ["name"] = "wool:blue"}, {["x"] = 11, ["y"] = 2, ["z"] = 9, ["name"] = "wool:blue"}, {["x"] = 11, ["y"] = 2, ["z"] = 10, ["name"] = "wool:blue"}, {["x"] = 11, ["y"] = 2, ["z"] = 11, ["name"] = "wool:blue"}, {["x"] = 11, ["y"] = 2, ["z"] = 12, ["name"] = "wool:blue"}, {["x"] = 11, ["y"] = 3, ["z"] = 3, ["name"] = "wool:blue"}, {["x"] = 11, ["y"] = 3, ["z"] = 4, ["name"] = "wool:blue"}, {["x"] = 11, ["y"] = 3, ["z"] = 5, ["name"] = "wool:blue"}, {["x"] = 11, ["y"] = 3, ["z"] = 6, ["name"] = "wool:blue"}, {["x"] = 11, ["y"] = 3, ["z"] = 7, ["name"] = "wool:blue"}, {["x"] = 11, ["y"] = 3, ["z"] = 8, ["name"] = "wool:blue"}, {["x"] = 11, ["y"] = 3, ["z"] = 9, ["name"] = "wool:blue"}, {["x"] = 11, ["y"] = 3, ["z"] = 10, ["name"] = "wool:blue"}, {["x"] = 11, ["y"] = 3, ["z"] = 11, ["name"] = "wool:blue"}, {["x"] = 11, ["y"] = 3, ["z"] = 12, ["name"] = "wool:blue"}, {["x"] = 11, ["y"] = 4, ["z"] = 3, ["name"] = "wool:blue"}, {["x"] = 11, ["y"] = 4, ["z"] = 4, ["name"] = "wool:blue"}, {["x"] = 11, ["y"] = 4, ["z"] = 5, ["name"] = "wool:blue"}, {["x"] = 11, ["y"] = 4, ["z"] = 6, ["name"] = "wool:blue"}, {["x"] = 11, ["y"] = 4, ["z"] = 7, ["name"] = "wool:blue"}, {["x"] = 11, ["y"] = 4, ["z"] = 8, ["name"] = "wool:blue"}, {["x"] = 11, ["y"] = 4, ["z"] = 9, ["name"] = "wool:blue"}, {["x"] = 11, ["y"] = 4, ["z"] = 10, ["name"] = "wool:blue"}, {["x"] = 11, ["y"] = 4, ["z"] = 11, ["name"] = "wool:blue"}, {["x"] = 11, ["y"] = 4, ["z"] = 12, ["name"] = "wool:blue"}, {["x"] = 11, ["y"] = 5, ["z"] = 3, ["name"] = "wool:blue"}, {["x"] = 11, ["y"] = 5, ["z"] = 4, ["name"] = "wool:blue"}, {["x"] = 11, ["y"] = 5, ["z"] = 5, ["name"] = "wool:blue"}, {["x"] = 11, ["y"] = 5, ["z"] = 6, ["name"] = "wool:blue"}, {["x"] = 11, ["y"] = 5, ["z"] = 7, ["name"] = "wool:blue"}, {["x"] = 11, ["y"] = 5, ["z"] = 8, ["name"] = "wool:blue"}, {["x"] = 11, ["y"] = 5, ["z"] = 9, ["name"] = "wool:blue"}, {["x"] = 11, ["y"] = 5, ["z"] = 10, ["name"] = "wool:blue"}, {["x"] = 11, ["y"] = 5, ["z"] = 11, ["name"] = "wool:blue"}, {["x"] = 11, ["y"] = 5, ["z"] = 12, ["name"] = "wool:blue"}, {["x"] = 11, ["y"] = 6, ["z"] = 3, ["name"] = "wool:blue"}, {["x"] = 11, ["y"] = 6, ["z"] = 4, ["name"] = "wool:blue"}, {["x"] = 11, ["y"] = 6, ["z"] = 5, ["name"] = "wool:blue"}, {["x"] = 11, ["y"] = 6, ["z"] = 6, ["name"] = "wool:blue"}, {["x"] = 11, ["y"] = 6, ["z"] = 7, ["name"] = "wool:blue"}, {["x"] = 11, ["y"] = 6, ["z"] = 8, ["name"] = "wool:blue"}, {["x"] = 11, ["y"] = 6, ["z"] = 9, ["name"] = "wool:blue"}, {["x"] = 11, ["y"] = 6, ["z"] = 10, ["name"] = "wool:blue"}, {["x"] = 11, ["y"] = 6, ["z"] = 11, ["name"] = "wool:blue"}, {["x"] = 11, ["y"] = 6, ["z"] = 12, ["name"] = "wool:blue"}, {["x"] = 11, ["y"] = 7, ["z"] = 3, ["name"] = "wool:blue"}, {["x"] = 11, ["y"] = 7, ["z"] = 4, ["name"] = "wool:blue"}, {["x"] = 11, ["y"] = 7, ["z"] = 5, ["name"] = "wool:blue"}, {["x"] = 11, ["y"] = 7, ["z"] = 6, ["name"] = "wool:blue"}, {["x"] = 11, ["y"] = 7, ["z"] = 7, ["name"] = "wool:blue"}, {["x"] = 11, ["y"] = 7, ["z"] = 8, ["name"] = "wool:blue"}, {["x"] = 11, ["y"] = 7, ["z"] = 9, ["name"] = "wool:blue"}, {["x"] = 11, ["y"] = 7, ["z"] = 10, ["name"] = "wool:blue"}, {["x"] = 11, ["y"] = 7, ["z"] = 11, ["name"] = "wool:blue"}, {["x"] = 11, ["y"] = 7, ["z"] = 12, ["name"] = "wool:blue"}, {["x"] = 11, ["y"] = 8, ["z"] = 3, ["name"] = "wool:blue"}, {["x"] = 11, ["y"] = 8, ["z"] = 4, ["name"] = "wool:blue"}, {["x"] = 11, ["y"] = 8, ["z"] = 5, ["name"] = "wool:blue"}, {["x"] = 11, ["y"] = 8, ["z"] = 6, ["name"] = "wool:blue"}, {["x"] = 11, ["y"] = 8, ["z"] = 7, ["name"] = "wool:blue"}, {["x"] = 11, ["y"] = 8, ["z"] = 8, ["name"] = "wool:blue"}, {["x"] = 11, ["y"] = 8, ["z"] = 9, ["name"] = "wool:blue"}, {["x"] = 11, ["y"] = 8, ["z"] = 10, ["name"] = "wool:blue"}, {["x"] = 11, ["y"] = 8, ["z"] = 11, ["name"] = "wool:blue"}, {["x"] = 11, ["y"] = 8, ["z"] = 12, ["name"] = "wool:blue"}, {["x"] = 12, ["y"] = 1, ["z"] = 4, ["name"] = "wool:blue"}, {["x"] = 12, ["y"] = 1, ["z"] = 5, ["name"] = "wool:blue"}, {["x"] = 12, ["y"] = 1, ["z"] = 6, ["name"] = "wool:blue"}, {["x"] = 12, ["y"] = 1, ["z"] = 7, ["name"] = "wool:blue"}, {["x"] = 12, ["y"] = 1, ["z"] = 8, ["name"] = "wool:blue"}, {["x"] = 12, ["y"] = 1, ["z"] = 9, ["name"] = "wool:blue"}, {["x"] = 12, ["y"] = 1, ["z"] = 10, ["name"] = "wool:blue"}, {["x"] = 12, ["y"] = 1, ["z"] = 11, ["name"] = "wool:blue"}, {["x"] = 12, ["y"] = 2, ["z"] = 4, ["name"] = "wool:blue"}, {["x"] = 12, ["y"] = 2, ["z"] = 5, ["name"] = "wool:blue"}, {["x"] = 12, ["y"] = 2, ["z"] = 6, ["name"] = "wool:blue"}, {["x"] = 12, ["y"] = 2, ["z"] = 7, ["name"] = "wool:blue"}, {["x"] = 12, ["y"] = 2, ["z"] = 8, ["name"] = "wool:blue"}, {["x"] = 12, ["y"] = 2, ["z"] = 9, ["name"] = "wool:blue"}, {["x"] = 12, ["y"] = 2, ["z"] = 10, ["name"] = "wool:blue"}, {["x"] = 12, ["y"] = 2, ["z"] = 11, ["name"] = "wool:blue"}, {["x"] = 12, ["y"] = 3, ["z"] = 4, ["name"] = "wool:blue"}, {["x"] = 12, ["y"] = 3, ["z"] = 5, ["name"] = "wool:blue"}, {["x"] = 12, ["y"] = 3, ["z"] = 6, ["name"] = "wool:blue"}, {["x"] = 12, ["y"] = 3, ["z"] = 7, ["name"] = "wool:blue"}, {["x"] = 12, ["y"] = 3, ["z"] = 8, ["name"] = "wool:blue"}, {["x"] = 12, ["y"] = 3, ["z"] = 9, ["name"] = "wool:blue"}, {["x"] = 12, ["y"] = 3, ["z"] = 10, ["name"] = "wool:blue"}, {["x"] = 12, ["y"] = 3, ["z"] = 11, ["name"] = "wool:blue"}, {["x"] = 12, ["y"] = 4, ["z"] = 4, ["name"] = "wool:blue"}, {["x"] = 12, ["y"] = 4, ["z"] = 5, ["name"] = "wool:blue"}, {["x"] = 12, ["y"] = 4, ["z"] = 6, ["name"] = "wool:blue"}, {["x"] = 12, ["y"] = 4, ["z"] = 7, ["name"] = "wool:blue"}, {["x"] = 12, ["y"] = 4, ["z"] = 8, ["name"] = "wool:blue"}, {["x"] = 12, ["y"] = 4, ["z"] = 9, ["name"] = "wool:blue"}, {["x"] = 12, ["y"] = 4, ["z"] = 10, ["name"] = "wool:blue"}, {["x"] = 12, ["y"] = 4, ["z"] = 11, ["name"] = "wool:blue"}, {["x"] = 12, ["y"] = 5, ["z"] = 4, ["name"] = "wool:blue"}, {["x"] = 12, ["y"] = 5, ["z"] = 5, ["name"] = "wool:blue"}, {["x"] = 12, ["y"] = 5, ["z"] = 6, ["name"] = "wool:blue"}, {["x"] = 12, ["y"] = 5, ["z"] = 7, ["name"] = "wool:blue"}, {["x"] = 12, ["y"] = 5, ["z"] = 8, ["name"] = "wool:blue"}, {["x"] = 12, ["y"] = 5, ["z"] = 9, ["name"] = "wool:blue"}, {["x"] = 12, ["y"] = 5, ["z"] = 10, ["name"] = "wool:blue"}, {["x"] = 12, ["y"] = 5, ["z"] = 11, ["name"] = "wool:blue"}, {["x"] = 12, ["y"] = 6, ["z"] = 4, ["name"] = "wool:blue"}, {["x"] = 12, ["y"] = 6, ["z"] = 5, ["name"] = "wool:blue"}, {["x"] = 12, ["y"] = 6, ["z"] = 6, ["name"] = "wool:blue"}, {["x"] = 12, ["y"] = 6, ["z"] = 7, ["name"] = "wool:blue"}, {["x"] = 12, ["y"] = 6, ["z"] = 8, ["name"] = "wool:blue"}, {["x"] = 12, ["y"] = 6, ["z"] = 9, ["name"] = "wool:blue"}, {["x"] = 12, ["y"] = 6, ["z"] = 10, ["name"] = "wool:blue"}, {["x"] = 12, ["y"] = 6, ["z"] = 11, ["name"] = "wool:blue"}, {["x"] = 12, ["y"] = 7, ["z"] = 4, ["name"] = "wool:blue"}, {["x"] = 12, ["y"] = 7, ["z"] = 5, ["name"] = "wool:blue"}, {["x"] = 12, ["y"] = 7, ["z"] = 6, ["name"] = "wool:blue"}, {["x"] = 12, ["y"] = 7, ["z"] = 7, ["name"] = "wool:blue"}, {["x"] = 12, ["y"] = 7, ["z"] = 8, ["name"] = "wool:blue"}, {["x"] = 12, ["y"] = 7, ["z"] = 9, ["name"] = "wool:blue"}, {["x"] = 12, ["y"] = 7, ["z"] = 10, ["name"] = "wool:blue"}, {["x"] = 12, ["y"] = 7, ["z"] = 11, ["name"] = "wool:blue"}, {["x"] = 12, ["y"] = 8, ["z"] = 4, ["name"] = "wool:blue"}, {["x"] = 12, ["y"] = 8, ["z"] = 5, ["name"] = "wool:blue"}, {["x"] = 12, ["y"] = 8, ["z"] = 6, ["name"] = "wool:blue"}, {["x"] = 12, ["y"] = 8, ["z"] = 7, ["name"] = "wool:blue"}, {["x"] = 12, ["y"] = 8, ["z"] = 8, ["name"] = "wool:blue"}, {["x"] = 12, ["y"] = 8, ["z"] = 9, ["name"] = "wool:blue"}, {["x"] = 12, ["y"] = 8, ["z"] = 10, ["name"] = "wool:blue"}, {["x"] = 12, ["y"] = 8, ["z"] = 11, ["name"] = "wool:blue"}, {["x"] = 13, ["y"] = 1, ["z"] = 6, ["name"] = "wool:blue"}, {["x"] = 13, ["y"] = 1, ["z"] = 7, ["name"] = "wool:blue"}, {["x"] = 13, ["y"] = 1, ["z"] = 8, ["name"] = "wool:blue"}, {["x"] = 13, ["y"] = 1, ["z"] = 9, ["name"] = "wool:blue"}, {["x"] = 13, ["y"] = 2, ["z"] = 6, ["name"] = "wool:blue"}, {["x"] = 13, ["y"] = 2, ["z"] = 7, ["name"] = "wool:blue"}, {["x"] = 13, ["y"] = 2, ["z"] = 8, ["name"] = "wool:blue"}, {["x"] = 13, ["y"] = 2, ["z"] = 9, ["name"] = "wool:blue"}, {["x"] = 13, ["y"] = 3, ["z"] = 6, ["name"] = "wool:blue"}, {["x"] = 13, ["y"] = 3, ["z"] = 7, ["name"] = "wool:blue"}, {["x"] = 13, ["y"] = 3, ["z"] = 8, ["name"] = "wool:blue"}, {["x"] = 13, ["y"] = 3, ["z"] = 9, ["name"] = "wool:blue"}, {["x"] = 13, ["y"] = 4, ["z"] = 6, ["name"] = "wool:blue"}, {["x"] = 13, ["y"] = 4, ["z"] = 7, ["name"] = "wool:blue"}, {["x"] = 13, ["y"] = 4, ["z"] = 8, ["name"] = "wool:blue"}, {["x"] = 13, ["y"] = 4, ["z"] = 9, ["name"] = "wool:blue"}, {["x"] = 13, ["y"] = 5, ["z"] = 6, ["name"] = "wool:blue"}, {["x"] = 13, ["y"] = 5, ["z"] = 7, ["name"] = "wool:blue"}, {["x"] = 13, ["y"] = 5, ["z"] = 8, ["name"] = "wool:blue"}, {["x"] = 13, ["y"] = 5, ["z"] = 9, ["name"] = "wool:blue"}, {["x"] = 13, ["y"] = 6, ["z"] = 6, ["name"] = "wool:blue"}, {["x"] = 13, ["y"] = 6, ["z"] = 7, ["name"] = "wool:blue"}, {["x"] = 13, ["y"] = 6, ["z"] = 8, ["name"] = "wool:blue"}, {["x"] = 13, ["y"] = 6, ["z"] = 9, ["name"] = "wool:blue"}, {["x"] = 13, ["y"] = 7, ["z"] = 6, ["name"] = "wool:blue"}, {["x"] = 13, ["y"] = 7, ["z"] = 7, ["name"] = "wool:blue"}, {["x"] = 13, ["y"] = 7, ["z"] = 8, ["name"] = "wool:blue"}, {["x"] = 13, ["y"] = 7, ["z"] = 9, ["name"] = "wool:blue"}, {["x"] = 13, ["y"] = 8, ["z"] = 6, ["name"] = "wool:blue"}, {["x"] = 13, ["y"] = 8, ["z"] = 7, ["name"] = "wool:blue"}, {["x"] = 13, ["y"] = 8, ["z"] = 8, ["name"] = "wool:blue"}, {["x"] = 13, ["y"] = 8, ["z"] = 9, ["name"] = "wool:blue"}}