5:return {{["x"] = 0, ["meta"] = {["fields"] = {}, ["inventory"] = {}}, ["y"] = 12, ["param1"] = 62, ["z"] = 0, ["name"] = "default:junglewood"}, {["x"] = 0, ["meta"] = {["fields"] = {}, ["inventory"] = {}}, ["y"] = 12, ["param1"] = 62, ["z"] = 1, ["name"] = "default:junglewood"}, {["x"] = 0, ["meta"] = {["fields"] = {}, ["inventory"] = {}}, ["y"] = 12, ["param1"] = 62, ["z"] = 2, ["name"] = "default:junglewood"}, {["x"] = 0, ["meta"] = {["fields"] = {}, ["inventory"] = {}}, ["y"] = 12, ["param1"] = 62, ["z"] = 3, ["name"] = "default:junglewood"}, {["x"] = 0, ["meta"] = {["fields"] = {}, ["inventory"] = {}}, ["y"] = 12, ["param1"] = 62, ["z"] = 4, ["name"] = "default:junglewood"}, {["x"] = 0, ["meta"] = {["fields"] = {}, ["inventory"] = {}}, ["y"] = 12, ["param1"] = 62, ["z"] = 5, ["name"] = "default:junglewood"}, {["x"] = 0, ["meta"] = {["fields"] = {}, ["inventory"] = {}}, ["y"] = 12, ["param1"] = 62, ["z"] = 6, ["name"] = "default:junglewood"}, {["x"] = 0, ["meta"] = {["fields"] = {}, ["inventory"] = {}}, ["y"] = 12, ["param1"] = 62, ["z"] = 7, ["name"] = "default:junglewood"}, {["x"] = 0, ["meta"] = {["fields"] = {}, ["inventory"] = {}}, ["y"] = 12, ["param1"] = 62, ["z"] = 8, ["name"] = "default:junglewood"}, {["x"] = 0, ["meta"] = {["fields"] = {}, ["inventory"] = {}}, ["y"] = 12, ["param1"] = 62, ["z"] = 9, ["name"] = "default:junglewood"}, {["x"] = 0, ["meta"] = {["fields"] = {}, ["inventory"] = {}}, ["y"] = 12, ["param1"] = 62, ["z"] = 10, ["name"] = "default:junglewood"}, {["x"] = 0, ["meta"] = {["fields"] = {}, ["inventory"] = {}}, ["y"] = 12, ["param1"] = 62, ["z"] = 11, ["name"] = "default:junglewood"}, {["x"] = 0, ["meta"] = {["fields"] = {}, ["inventory"] = {}}, ["y"] = 12, ["param1"] = 62, ["z"] = 12, ["name"] = "default:junglewood"}, {["x"] = 0, ["meta"] = {["fields"] = {}, ["inventory"] = {}}, ["y"] = 12, ["param1"] = 62, ["z"] = 13, ["name"] = "default:junglewood"}, {["x"] = 0, ["meta"] = {["fields"] = {}, ["inventory"] = {}}, ["y"] = 12, ["param1"] = 62, ["z"] = 14, ["name"] = "default:junglewood"}, {["x"] = 0, ["meta"] = {["fields"] = {}, ["inventory"] = {}}, ["y"] = 12, ["param1"] = 62, ["z"] = 15, ["name"] = "default:junglewood"}, {["x"] = 0, ["meta"] = {["fields"] = {}, ["inventory"] = {}}, ["y"] = 13, ["param1"] = 62, ["z"] = 0, ["name"] = "default:junglewood"}, {["x"] = 0, ["meta"] = {["fields"] = {}, ["inventory"] = {}}, ["y"] = 13, ["param1"] = 62, ["z"] = 1, ["name"] = "default:junglewood"}, {["x"] = 0, ["meta"] = {["fields"] = {}, ["inventory"] = {}}, ["y"] = 13, ["param1"] = 62, ["z"] = 2, ["name"] = "default:junglewood"}, {["x"] = 0, ["meta"] = {["fields"] = {}, ["inventory"] = {}}, ["y"] = 13, ["param1"] = 62, ["z"] = 3, ["name"] = "default:junglewood"}, {["x"] = 0, ["meta"] = {["fields"] = {}, ["inventory"] = {}}, ["y"] = 13, ["param1"] = 62, ["z"] = 4, ["name"] = "default:junglewood"}, {["x"] = 0, ["meta"] = {["fields"] = {}, ["inventory"] = {}}, ["y"] = 13, ["param1"] = 62, ["z"] = 5, ["name"] = "default:junglewood"}, {["x"] = 0, ["meta"] = {["fields"] = {}, ["inventory"] = {}}, ["y"] = 13, ["param1"] = 62, ["z"] = 6, ["name"] = "default:junglewood"}, {["x"] = 0, ["meta"] = {["fields"] = {}, ["inventory"] = {}}, ["y"] = 13, ["param1"] = 62, ["z"] = 7, ["name"] = "default:junglewood"}, {["x"] = 0, ["meta"] = {["fields"] = {}, ["inventory"] = {}}, ["y"] = 13, ["param1"] = 62, ["z"] = 8, ["name"] = "default:junglewood"}, {["x"] = 0, ["meta"] = {["fields"] = {}, ["inventory"] = {}}, ["y"] = 13, ["param1"] = 62, ["z"] = 9, ["name"] = "default:junglewood"}, {["x"] = 0, ["meta"] = {["fields"] = {}, ["inventory"] = {}}, ["y"] = 13, ["param1"] = 62, ["z"] = 10, ["name"] = "default:junglewood"}, {["x"] = 0, ["meta"] = {["fields"] = {}, ["inventory"] = {}}, ["y"] = 13, ["param1"] = 62, ["z"] = 11, ["name"] = "default:junglewood"}, {["x"] = 0, ["meta"] = {["fields"] = {}, ["inventory"] = {}}, ["y"] = 13, ["param1"] = 62, ["z"] = 12, ["name"] = "default:junglewood"}, {["x"] = 0, ["meta"] = {["fields"] = {}, ["inventory"] = {}}, ["y"] = 13, ["param1"] = 62, ["z"] = 13, ["name"] = "default:junglewood"}, {["x"] = 0, ["meta"] = {["fields"] = {}, ["inventory"] = {}}, ["y"] = 13, ["param1"] = 62, ["z"] = 14, ["name"] = "default:junglewood"}, {["x"] = 0, ["meta"] = {["fields"] = {}, ["inventory"] = {}}, ["y"] = 13, ["param1"] = 62, ["z"] = 15, ["name"] = "default:junglewood"}, {["x"] = 0, ["meta"] = {["fields"] = {}, ["inventory"] = {}}, ["y"] = 14, ["param1"] = 62, ["z"] = 0, ["name"] = "default:junglewood"}, {["x"] = 0, ["meta"] = {["fields"] = {}, ["inventory"] = {}}, ["y"] = 14, ["param1"] = 62, ["z"] = 1, ["name"] = "default:junglewood"}, {["x"] = 0, ["meta"] = {["fields"] = {}, ["inventory"] = {}}, ["y"] = 14, ["param1"] = 62, ["z"] = 2, ["name"] = "default:junglewood"}, {["x"] = 0, ["meta"] = {["fields"] = {}, ["inventory"] = {}}, ["y"] = 14, ["param1"] = 62, ["z"] = 3, ["name"] = "default:junglewood"}, {["x"] = 0, ["meta"] = {["fields"] = {}, ["inventory"] = {}}, ["y"] = 14, ["param1"] = 62, ["z"] = 4, ["name"] = "default:junglewood"}, {["x"] = 0, ["meta"] = {["fields"] = {}, ["inventory"] = {}}, ["y"] = 14, ["param1"] = 62, ["z"] = 5, ["name"] = "default:junglewood"}, {["x"] = 0, ["meta"] = {["fields"] = {}, ["inventory"] = {}}, ["y"] = 14, ["param1"] = 62, ["z"] = 6, ["name"] = "default:junglewood"}, {["x"] = 0, ["meta"] = {["fields"] = {}, ["inventory"] = {}}, ["y"] = 14, ["param1"] = 62, ["z"] = 7, ["name"] = "default:junglewood"}, {["x"] = 0, ["meta"] = {["fields"] = {}, ["inventory"] = {}}, ["y"] = 14, ["param1"] = 62, ["z"] = 8, ["name"] = "default:junglewood"}, {["x"] = 0, ["meta"] = {["fields"] = {}, ["inventory"] = {}}, ["y"] = 14, ["param1"] = 62, ["z"] = 9, ["name"] = "default:junglewood"}, {["x"] = 0, ["meta"] = {["fields"] = {}, ["inventory"] = {}}, ["y"] = 14, ["param1"] = 62, ["z"] = 10, ["name"] = "default:junglewood"}, {["x"] = 0, ["meta"] = {["fields"] = {}, ["inventory"] = {}}, ["y"] = 14, ["param1"] = 62, ["z"] = 11, ["name"] = "default:junglewood"}, {["x"] = 0, ["meta"] = {["fields"] = {}, ["inventory"] = {}}, ["y"] = 14, ["param1"] = 62, ["z"] = 12, ["name"] = "default:junglewood"}, {["x"] = 0, ["meta"] = {["fields"] = {}, ["inventory"] = {}}, ["y"] = 14, ["param1"] = 62, ["z"] = 13, ["name"] = "default:junglewood"}, {["x"] = 0, ["meta"] = {["fields"] = {}, ["inventory"] = {}}, ["y"] = 14, ["param1"] = 62, ["z"] = 14, ["name"] = "default:junglewood"}, {["x"] = 0, ["meta"] = {["fields"] = {}, ["inventory"] = {}}, ["y"] = 14, ["param1"] = 62, ["z"] = 15, ["name"] = "default:junglewood"}, {["x"] = 1, ["meta"] = {["fields"] = {}, ["inventory"] = {}}, ["y"] = 12, ["param1"] = 62, ["z"] = 0, ["name"] = "default:junglewood"}, {["x"] = 1, ["meta"] = {["fields"] = {}, ["inventory"] = {}}, ["y"] = 12, ["param1"] = 62, ["z"] = 1, ["name"] = "default:junglewood"}, {["x"] = 1, ["meta"] = {["fields"] = {}, ["inventory"] = {}}, ["y"] = 12, ["param1"] = 62, ["z"] = 2, ["name"] = "default:junglewood"}, {["x"] = 1, ["meta"] = {["fields"] = {}, ["inventory"] = {}}, ["y"] = 12, ["param1"] = 62, ["z"] = 3, ["name"] = "default:junglewood"}, {["x"] = 1, ["meta"] = {["fields"] = {}, ["inventory"] = {}}, ["y"] = 12, ["param1"] = 62, ["z"] = 4, ["name"] = "default:junglewood"}, {["x"] = 1, ["meta"] = {["fields"] = {}, ["inventory"] = {}}, ["y"] = 12, ["param1"] = 62, ["z"] = 5, ["name"] = "default:junglewood"}, {["x"] = 1, ["meta"] = {["fields"] = {}, ["inventory"] = {}}, ["y"] = 12, ["param1"] = 62, ["z"] = 6, ["name"] = "default:junglewood"}, {["x"] = 1, ["meta"] = {["fields"] = {}, ["inventory"] = {}}, ["y"] = 12, ["param1"] = 62, ["z"] = 7, ["name"] = "default:junglewood"}, {["x"] = 1, ["meta"] = {["fields"] = {}, ["inventory"] = {}}, ["y"] = 12, ["param1"] = 62, ["z"] = 8, ["name"] = "default:junglewood"}, {["x"] = 1, ["meta"] = {["fields"] = {}, ["inventory"] = {}}, ["y"] = 12, ["param1"] = 62, ["z"] = 9, ["name"] = "default:junglewood"}, {["x"] = 1, ["meta"] = {["fields"] = {}, ["inventory"] = {}}, ["y"] = 12, ["param1"] = 62, ["z"] = 10, ["name"] = "default:junglewood"}, {["x"] = 1, ["meta"] = {["fields"] = {}, ["inventory"] = {}}, ["y"] = 12, ["param1"] = 62, ["z"] = 11, ["name"] = "default:junglewood"}, {["x"] = 1, ["meta"] = {["fields"] = {}, ["inventory"] = {}}, ["y"] = 12, ["param1"] = 62, ["z"] = 12, ["name"] = "default:junglewood"}, {["x"] = 1, ["meta"] = {["fields"] = {}, ["inventory"] = {}}, ["y"] = 12, ["param1"] = 62, ["z"] = 13, ["name"] = "default:junglewood"}, {["x"] = 1, ["meta"] = {["fields"] = {}, ["inventory"] = {}}, ["y"] = 12, ["param1"] = 62, ["z"] = 14, ["name"] = "default:junglewood"}, {["x"] = 1, ["meta"] = {["fields"] = {}, ["inventory"] = {}}, ["y"] = 12, ["param1"] = 62, ["z"] = 15, ["name"] = "default:junglewood"}, {["x"] = 1, ["meta"] = {["fields"] = {}, ["inventory"] = {}}, ["y"] = 13, ["param1"] = 62, ["z"] = 0, ["name"] = "default:junglewood"}, {["x"] = 1, ["meta"] = {["fields"] = {}, ["inventory"] = {}}, ["y"] = 13, ["param1"] = 62, ["z"] = 1, ["name"] = "default:junglewood"}, {["x"] = 1, ["meta"] = {["fields"] = {}, ["inventory"] = {}}, ["y"] = 13, ["param1"] = 62, ["z"] = 2, ["name"] = "default:junglewood"}, {["x"] = 1, ["meta"] = {["fields"] = {}, ["inventory"] = {}}, ["y"] = 13, ["param1"] = 62, ["z"] = 3, ["name"] = "default:junglewood"}, {["x"] = 1, ["meta"] = {["fields"] = {}, ["inventory"] = {}}, ["y"] = 13, ["param1"] = 62, ["z"] = 4, ["name"] = "default:junglewood"}, {["x"] = 1, ["meta"] = {["fields"] = {}, ["inventory"] = {}}, ["y"] = 13, ["param1"] = 62, ["z"] = 5, ["name"] = "default:junglewood"}, {["x"] = 1, ["meta"] = {["fields"] = {}, ["inventory"] = {}}, ["y"] = 13, ["param1"] = 62, ["z"] = 6, ["name"] = "default:junglewood"}, {["x"] = 1, ["meta"] = {["fields"] = {}, ["inventory"] = {}}, ["y"] = 13, ["param1"] = 62, ["z"] = 7, ["name"] = "default:junglewood"}, {["x"] = 1, ["meta"] = {["fields"] = {}, ["inventory"] = {}}, ["y"] = 13, ["param1"] = 62, ["z"] = 8, ["name"] = "default:junglewood"}, {["x"] = 1, ["meta"] = {["fields"] = {}, ["inventory"] = {}}, ["y"] = 13, ["param1"] = 62, ["z"] = 9, ["name"] = "default:junglewood"}, {["x"] = 1, ["meta"] = {["fields"] = {}, ["inventory"] = {}}, ["y"] = 13, ["param1"] = 62, ["z"] = 10, ["name"] = "default:junglewood"}, {["x"] = 1, ["meta"] = {["fields"] = {}, ["inventory"] = {}}, ["y"] = 13, ["param1"] = 62, ["z"] = 11, ["name"] = "default:junglewood"}, {["x"] = 1, ["meta"] = {["fields"] = {}, ["inventory"] = {}}, ["y"] = 13, ["param1"] = 62, ["z"] = 12, ["name"] = "default:junglewood"}, {["x"] = 1, ["meta"] = {["fields"] = {}, ["inventory"] = {}}, ["y"] = 13, ["param1"] = 62, ["z"] = 13, ["name"] = "default:junglewood"}, {["x"] = 1, ["meta"] = {["fields"] = {}, ["inventory"] = {}}, ["y"] = 13, ["param1"] = 62, ["z"] = 14, ["name"] = "default:junglewood"}, {["x"] = 1, ["meta"] = {["fields"] = {}, ["inventory"] = {}}, ["y"] = 13, ["param1"] = 62, ["z"] = 15, ["name"] = "default:junglewood"}, {["x"] = 1, ["meta"] = {["fields"] = {}, ["inventory"] = {}}, ["y"] = 14, ["param1"] = 62, ["z"] = 0, ["name"] = "default:junglewood"}, {["x"] = 1, ["meta"] = {["fields"] = {}, ["inventory"] = {}}, ["y"] = 14, ["param1"] = 62, ["z"] = 1, ["name"] = "default:junglewood"}, {["x"] = 1, ["meta"] = {["fields"] = {}, ["inventory"] = {}}, ["y"] = 14, ["param1"] = 62, ["z"] = 2, ["name"] = "default:junglewood"}, {["x"] = 1, ["meta"] = {["fields"] = {}, ["inventory"] = {}}, ["y"] = 14, ["param1"] = 62, ["z"] = 3, ["name"] = "default:junglewood"}, {["x"] = 1, ["meta"] = {["fields"] = {}, ["inventory"] = {}}, ["y"] = 14, ["param1"] = 62, ["z"] = 4, ["name"] = "default:junglewood"}, {["x"] = 1, ["meta"] = {["fields"] = {}, ["inventory"] = {}}, ["y"] = 14, ["param1"] = 62, ["z"] = 5, ["name"] = "default:junglewood"}, {["x"] = 1, ["meta"] = {["fields"] = {}, ["inventory"] = {}}, ["y"] = 14, ["param1"] = 62, ["z"] = 6, ["name"] = "default:junglewood"}, {["x"] = 1, ["meta"] = {["fields"] = {}, ["inventory"] = {}}, ["y"] = 14, ["param1"] = 62, ["z"] = 7, ["name"] = "default:junglewood"}, {["x"] = 1, ["meta"] = {["fields"] = {}, ["inventory"] = {}}, ["y"] = 14, ["param1"] = 62, ["z"] = 8, ["name"] = "default:junglewood"}, {["x"] = 1, ["meta"] = {["fields"] = {}, ["inventory"] = {}}, ["y"] = 14, ["param1"] = 62, ["z"] = 9, ["name"] = "default:junglewood"}, {["x"] = 1, ["meta"] = {["fields"] = {}, ["inventory"] = {}}, ["y"] = 14, ["param1"] = 62, ["z"] = 10, ["name"] = "default:junglewood"}, {["x"] = 1, ["meta"] = {["fields"] = {}, ["inventory"] = {}}, ["y"] = 14, ["param1"] = 62, ["z"] = 11, ["name"] = "default:junglewood"}, {["x"] = 1, ["meta"] = {["fields"] = {}, ["inventory"] = {}}, ["y"] = 14, ["param1"] = 62, ["z"] = 12, ["name"] = "default:junglewood"}, {["x"] = 1, ["meta"] = {["fields"] = {}, ["inventory"] = {}}, ["y"] = 14, ["param1"] = 62, ["z"] = 13, ["name"] = "default:junglewood"}, {["x"] = 1, ["meta"] = {["fields"] = {}, ["inventory"] = {}}, ["y"] = 14, ["param1"] = 62, ["z"] = 14, ["name"] = "default:junglewood"}, {["x"] = 1, ["meta"] = {["fields"] = {}, ["inventory"] = {}}, ["y"] = 14, ["param1"] = 62, ["z"] = 15, ["name"] = "default:junglewood"}, {["x"] = 2, ["meta"] = {["fields"] = {}, ["inventory"] = {}}, ["y"] = 0, ["param1"] = 56, ["z"] = 2, ["name"] = "default:wood"}, {["x"] = 2, ["meta"] = {["fields"] = {}, ["inventory"] = {}}, ["y"] = 0, ["param1"] = 56, ["z"] = 3, ["name"] = "default:wood"}, {["x"] = 2, ["meta"] = {["fields"] = {}, ["inventory"] = {}}, ["y"] = 0, ["param1"] = 56, ["z"] = 12, ["name"] = "default:wood"}, {["x"] = 2, ["meta"] = {["fields"] = {}, ["inventory"] = {}}, ["y"] = 0, ["param1"] = 56, ["z"] = 13, ["name"] = "default:wood"}, {["x"] = 2, ["meta"] = {["fields"] = {}, ["inventory"] = {}}, ["y"] = 1, ["param1"] = 56, ["z"] = 2, ["name"] = "default:wood"}, {["x"] = 2, ["meta"] = {["fields"] = {}, ["inventory"] = {}}, ["y"] = 1, ["param1"] = 56, ["z"] = 3, ["name"] = "default:wood"}, {["x"] = 2, ["y"] = 1, ["param1"] = 56, ["z"] = 12, ["name"] = "default:wood"}, {["x"] = 2, ["y"] = 1, ["param1"] = 56, ["z"] = 13, ["name"] = "default:wood"}, {["x"] = 2, ["meta"] = {["fields"] = {}, ["inventory"] = {}}, ["y"] = 2, ["param1"] = 56, ["z"] = 2, ["name"] = "default:wood"}, {["x"] = 2, ["meta"] = {["fields"] = {}, ["inventory"] = {}}, ["y"] = 2, ["param1"] = 56, ["z"] = 3, ["name"] = "default:wood"}, {["x"] = 2, ["y"] = 2, ["param1"] = 56, ["z"] = 12, ["name"] = "default:wood"}, {["x"] = 2, ["y"] = 2, ["param1"] = 56, ["z"] = 13, ["name"] = "default:wood"}, {["x"] = 2, ["meta"] = {["fields"] = {}, ["inventory"] = {}}, ["y"] = 3, ["param1"] = 56, ["z"] = 2, ["name"] = "default:wood"}, {["x"] = 2, ["meta"] = {["fields"] = {}, ["inventory"] = {}}, ["y"] = 3, ["param1"] = 56, ["z"] = 3, ["name"] = "default:wood"}, {["x"] = 2, ["y"] = 3, ["param1"] = 56, ["z"] = 12, ["name"] = "default:wood"}, {["x"] = 2, ["y"] = 3, ["param1"] = 56, ["z"] = 13, ["name"] = "default:wood"}, {["x"] = 2, ["meta"] = {["fields"] = {}, ["inventory"] = {}}, ["y"] = 4, ["param1"] = 56, ["z"] = 2, ["name"] = "default:wood"}, {["x"] = 2, ["meta"] = {["fields"] = {}, ["inventory"] = {}}, ["y"] = 4, ["param1"] = 56, ["z"] = 3, ["name"] = "default:wood"}, {["x"] = 2, ["y"] = 4, ["param1"] = 56, ["z"] = 12, ["name"] = "default:wood"}, {["x"] = 2, ["y"] = 4, ["param1"] = 56, ["z"] = 13, ["name"] = "default:wood"}, {["x"] = 2, ["meta"] = {["fields"] = {}, ["inventory"] = {}}, ["y"] = 5, ["param1"] = 56, ["z"] = 2, ["name"] = "default:wood"}, {["x"] = 2, ["meta"] = {["fields"] = {}, ["inventory"] = {}}, ["y"] = 5, ["param1"] = 56, ["z"] = 3, ["name"] = "default:wood"}, {["x"] = 2, ["y"] = 5, ["param1"] = 56, ["z"] = 12, ["name"] = "default:wood"}, {["x"] = 2, ["y"] = 5, ["param1"] = 56, ["z"] = 13, ["name"] = "default:wood"}, {["x"] = 2, ["meta"] = {["fields"] = {}, ["inventory"] = {}}, ["y"] = 6, ["param1"] = 56, ["z"] = 2, ["name"] = "default:wood"}, {["x"] = 2, ["meta"] = {["fields"] = {}, ["inventory"] = {}}, ["y"] = 6, ["param1"] = 56, ["z"] = 3, ["name"] = "default:wood"}, {["x"] = 2, ["y"] = 6, ["param1"] = 56, ["z"] = 12, ["name"] = "default:wood"}, {["x"] = 2, ["y"] = 6, ["param1"] = 56, ["z"] = 13, ["name"] = "default:wood"}, {["x"] = 2, ["meta"] = {["fields"] = {}, ["inventory"] = {}}, ["y"] = 7, ["param1"] = 56, ["z"] = 2, ["name"] = "default:wood"}, {["x"] = 2, ["meta"] = {["fields"] = {}, ["inventory"] = {}}, ["y"] = 7, ["param1"] = 56, ["z"] = 3, ["name"] = "default:wood"}, {["x"] = 2, ["y"] = 7, ["param1"] = 56, ["z"] = 12, ["name"] = "default:wood"}, {["x"] = 2, ["y"] = 7, ["param1"] = 56, ["z"] = 13, ["name"] = "default:wood"}, {["x"] = 2, ["meta"] = {["fields"] = {}, ["inventory"] = {}}, ["y"] = 8, ["param1"] = 56, ["z"] = 2, ["name"] = "default:wood"}, {["x"] = 2, ["meta"] = {["fields"] = {}, ["inventory"] = {}}, ["y"] = 8, ["param1"] = 56, ["z"] = 3, ["name"] = "default:wood"}, {["x"] = 2, ["y"] = 8, ["param1"] = 56, ["z"] = 12, ["name"] = "default:wood"}, {["x"] = 2, ["y"] = 8, ["param1"] = 56, ["z"] = 13, ["name"] = "default:wood"}, {["x"] = 2, ["meta"] = {["fields"] = {}, ["inventory"] = {}}, ["y"] = 9, ["param1"] = 56, ["z"] = 2, ["name"] = "default:wood"}, {["x"] = 2, ["meta"] = {["fields"] = {}, ["inventory"] = {}}, ["y"] = 9, ["param1"] = 56, ["z"] = 3, ["name"] = "default:wood"}, {["x"] = 2, ["y"] = 9, ["param1"] = 56, ["z"] = 12, ["name"] = "default:wood"}, {["x"] = 2, ["y"] = 9, ["param1"] = 56, ["z"] = 13, ["name"] = "default:wood"}, {["x"] = 2, ["meta"] = {["fields"] = {}, ["inventory"] = {}}, ["y"] = 10, ["param1"] = 56, ["z"] = 2, ["name"] = "default:wood"}, {["x"] = 2, ["meta"] = {["fields"] = {}, ["inventory"] = {}}, ["y"] = 10, ["param1"] = 56, ["z"] = 3, ["name"] = "default:wood"}, {["x"] = 2, ["y"] = 10, ["param1"] = 56, ["z"] = 12, ["name"] = "default:wood"}, {["x"] = 2, ["y"] = 10, ["param1"] = 56, ["z"] = 13, ["name"] = "default:wood"}, {["x"] = 2, ["meta"] = {["fields"] = {}, ["inventory"] = {}}, ["y"] = 11, ["param1"] = 56, ["z"] = 2, ["name"] = "default:wood"}, {["x"] = 2, ["meta"] = {["fields"] = {}, ["inventory"] = {}}, ["y"] = 11, ["param1"] = 56, ["z"] = 3, ["name"] = "default:wood"}, {["x"] = 2, ["y"] = 11, ["param1"] = 56, ["z"] = 12, ["name"] = "default:wood"}, {["x"] = 2, ["y"] = 11, ["param1"] = 56, ["z"] = 13, ["name"] = "default:wood"}, {["x"] = 2, ["meta"] = {["fields"] = {}, ["inventory"] = {}}, ["y"] = 12, ["param1"] = 62, ["z"] = 0, ["name"] = "default:junglewood"}, {["x"] = 2, ["meta"] = {["fields"] = {}, ["inventory"] = {}}, ["y"] = 12, ["param1"] = 62, ["z"] = 1, ["name"] = "default:junglewood"}, {["x"] = 2, ["meta"] = {["fields"] = {}, ["inventory"] = {}}, ["y"] = 12, ["param1"] = 62, ["z"] = 2, ["name"] = "default:junglewood"}, {["x"] = 2, ["meta"] = {["fields"] = {}, ["inventory"] = {}}, ["y"] = 12, ["param1"] = 62, ["z"] = 3, ["name"] = "default:junglewood"}, {["x"] = 2, ["meta"] = {["fields"] = {}, ["inventory"] = {}}, ["y"] = 12, ["param1"] = 62, ["z"] = 4, ["name"] = "default:junglewood"}, {["x"] = 2, ["meta"] = {["fields"] = {}, ["inventory"] = {}}, ["y"] = 12, ["param1"] = 62, ["z"] = 5, ["name"] = "default:junglewood"}, {["x"] = 2, ["meta"] = {["fields"] = {}, ["inventory"] = {}}, ["y"] = 12, ["param1"] = 62, ["z"] = 6, ["name"] = "default:junglewood"}, {["x"] = 2, ["meta"] = {["fields"] = {}, ["inventory"] = {}}, ["y"] = 12, ["param1"] = 62, ["z"] = 7, ["name"] = "default:junglewood"}, {["x"] = 2, ["meta"] = {["fields"] = {}, ["inventory"] = {}}, ["y"] = 12, ["param1"] = 62, ["z"] = 8, ["name"] = "default:junglewood"}, {["x"] = 2, ["meta"] = {["fields"] = {}, ["inventory"] = {}}, ["y"] = 12, ["param1"] = 62, ["z"] = 9, ["name"] = "default:junglewood"}, {["x"] = 2, ["meta"] = {["fields"] = {}, ["inventory"] = {}}, ["y"] = 12, ["param1"] = 62, ["z"] = 10, ["name"] = "default:junglewood"}, {["x"] = 2, ["meta"] = {["fields"] = {}, ["inventory"] = {}}, ["y"] = 12, ["param1"] = 62, ["z"] = 11, ["name"] = "default:junglewood"}, {["x"] = 2, ["meta"] = {["fields"] = {}, ["inventory"] = {}}, ["y"] = 12, ["param1"] = 62, ["z"] = 12, ["name"] = "default:junglewood"}, {["x"] = 2, ["meta"] = {["fields"] = {}, ["inventory"] = {}}, ["y"] = 12, ["param1"] = 62, ["z"] = 13, ["name"] = "default:junglewood"}, {["x"] = 2, ["meta"] = {["fields"] = {}, ["inventory"] = {}}, ["y"] = 12, ["param1"] = 62, ["z"] = 14, ["name"] = "default:junglewood"}, {["x"] = 2, ["meta"] = {["fields"] = {}, ["inventory"] = {}}, ["y"] = 12, ["param1"] = 62, ["z"] = 15, ["name"] = "default:junglewood"}, {["x"] = 2, ["meta"] = {["fields"] = {}, ["inventory"] = {}}, ["y"] = 13, ["param1"] = 62, ["z"] = 0, ["name"] = "default:junglewood"}, {["x"] = 2, ["meta"] = {["fields"] = {}, ["inventory"] = {}}, ["y"] = 13, ["param1"] = 62, ["z"] = 1, ["name"] = "default:junglewood"}, {["x"] = 2, ["meta"] = {["fields"] = {}, ["inventory"] = {}}, ["y"] = 13, ["param1"] = 62, ["z"] = 2, ["name"] = "default:junglewood"}, {["x"] = 2, ["meta"] = {["fields"] = {}, ["inventory"] = {}}, ["y"] = 13, ["param1"] = 62, ["z"] = 3, ["name"] = "default:junglewood"}, {["x"] = 2, ["meta"] = {["fields"] = {}, ["inventory"] = {}}, ["y"] = 13, ["param1"] = 62, ["z"] = 4, ["name"] = "default:junglewood"}, {["x"] = 2, ["meta"] = {["fields"] = {}, ["inventory"] = {}}, ["y"] = 13, ["param1"] = 62, ["z"] = 5, ["name"] = "default:junglewood"}, {["x"] = 2, ["meta"] = {["fields"] = {}, ["inventory"] = {}}, ["y"] = 13, ["param1"] = 62, ["z"] = 6, ["name"] = "default:junglewood"}, {["x"] = 2, ["meta"] = {["fields"] = {}, ["inventory"] = {}}, ["y"] = 13, ["param1"] = 62, ["z"] = 7, ["name"] = "default:junglewood"}, {["x"] = 2, ["meta"] = {["fields"] = {}, ["inventory"] = {}}, ["y"] = 13, ["param1"] = 62, ["z"] = 8, ["name"] = "default:junglewood"}, {["x"] = 2, ["meta"] = {["fields"] = {}, ["inventory"] = {}}, ["y"] = 13, ["param1"] = 62, ["z"] = 9, ["name"] = "default:junglewood"}, {["x"] = 2, ["meta"] = {["fields"] = {}, ["inventory"] = {}}, ["y"] = 13, ["param1"] = 62, ["z"] = 10, ["name"] = "default:junglewood"}, {["x"] = 2, ["meta"] = {["fields"] = {}, ["inventory"] = {}}, ["y"] = 13, ["param1"] = 62, ["z"] = 11, ["name"] = "default:junglewood"}, {["x"] = 2, ["meta"] = {["fields"] = {}, ["inventory"] = {}}, ["y"] = 13, ["param1"] = 62, ["z"] = 12, ["name"] = "default:junglewood"}, {["x"] = 2, ["meta"] = {["fields"] = {}, ["inventory"] = {}}, ["y"] = 13, ["param1"] = 62, ["z"] = 13, ["name"] = "default:junglewood"}, {["x"] = 2, ["meta"] = {["fields"] = {}, ["inventory"] = {}}, ["y"] = 13, ["param1"] = 62, ["z"] = 14, ["name"] = "default:junglewood"}, {["x"] = 2, ["meta"] = {["fields"] = {}, ["inventory"] = {}}, ["y"] = 13, ["param1"] = 62, ["z"] = 15, ["name"] = "default:junglewood"}, {["x"] = 2, ["meta"] = {["fields"] = {}, ["inventory"] = {}}, ["y"] = 14, ["param1"] = 62, ["z"] = 0, ["name"] = "default:junglewood"}, {["x"] = 2, ["meta"] = {["fields"] = {}, ["inventory"] = {}}, ["y"] = 14, ["param1"] = 62, ["z"] = 1, ["name"] = "default:junglewood"}, {["x"] = 2, ["meta"] = {["fields"] = {}, ["inventory"] = {}}, ["y"] = 14, ["param1"] = 62, ["z"] = 2, ["name"] = "default:junglewood"}, {["x"] = 2, ["meta"] = {["fields"] = {}, ["inventory"] = {}}, ["y"] = 14, ["param1"] = 62, ["z"] = 3, ["name"] = "default:junglewood"}, {["x"] = 2, ["meta"] = {["fields"] = {}, ["inventory"] = {}}, ["y"] = 14, ["param1"] = 62, ["z"] = 4, ["name"] = "default:junglewood"}, {["x"] = 2, ["meta"] = {["fields"] = {}, ["inventory"] = {}}, ["y"] = 14, ["param1"] = 62, ["z"] = 5, ["name"] = "default:junglewood"}, {["x"] = 2, ["meta"] = {["fields"] = {}, ["inventory"] = {}}, ["y"] = 14, ["param1"] = 62, ["z"] = 6, ["name"] = "default:junglewood"}, {["x"] = 2, ["meta"] = {["fields"] = {}, ["inventory"] = {}}, ["y"] = 14, ["param1"] = 62, ["z"] = 7, ["name"] = "default:junglewood"}, {["x"] = 2, ["meta"] = {["fields"] = {}, ["inventory"] = {}}, ["y"] = 14, ["param1"] = 62, ["z"] = 8, ["name"] = "default:junglewood"}, {["x"] = 2, ["meta"] = {["fields"] = {}, ["inventory"] = {}}, ["y"] = 14, ["param1"] = 62, ["z"] = 9, ["name"] = "default:junglewood"}, {["x"] = 2, ["meta"] = {["fields"] = {}, ["inventory"] = {}}, ["y"] = 14, ["param1"] = 62, ["z"] = 10, ["name"] = "default:junglewood"}, {["x"] = 2, ["meta"] = {["fields"] = {}, ["inventory"] = {}}, ["y"] = 14, ["param1"] = 62, ["z"] = 11, ["name"] = "default:junglewood"}, {["x"] = 2, ["meta"] = {["fields"] = {}, ["inventory"] = {}}, ["y"] = 14, ["param1"] = 62, ["z"] = 12, ["name"] = "default:junglewood"}, {["x"] = 2, ["meta"] = {["fields"] = {}, ["inventory"] = {}}, ["y"] = 14, ["param1"] = 62, ["z"] = 13, ["name"] = "default:junglewood"}, {["x"] = 2, ["meta"] = {["fields"] = {}, ["inventory"] = {}}, ["y"] = 14, ["param1"] = 62, ["z"] = 14, ["name"] = "default:junglewood"}, {["x"] = 2, ["meta"] = {["fields"] = {}, ["inventory"] = {}}, ["y"] = 14, ["param1"] = 62, ["z"] = 15, ["name"] = "default:junglewood"}, {["x"] = 2, ["y"] = 15, ["z"] = 2, ["name"] = "wool:red"}, {["x"] = 2, ["y"] = 15, ["z"] = 3, ["name"] = "wool:red"}, {["x"] = 2, ["y"] = 15, ["z"] = 4, ["name"] = "wool:red"}, {["x"] = 2, ["y"] = 15, ["z"] = 5, ["name"] = "wool:red"}, {["x"] = 2, ["y"] = 15, ["z"] = 6, ["name"] = "wool:red"}, {["x"] = 2, ["y"] = 15, ["z"] = 7, ["name"] = "wool:red"}, {["x"] = 2, ["y"] = 15, ["z"] = 8, ["name"] = "wool:red"}, {["x"] = 2, ["y"] = 15, ["z"] = 9, ["name"] = "wool:red"}, {["x"] = 2, ["y"] = 15, ["z"] = 10, ["name"] = "wool:red"}, {["x"] = 2, ["y"] = 15, ["z"] = 11, ["name"] = "wool:red"}, {["x"] = 2, ["y"] = 15, ["z"] = 12, ["name"] = "wool:red"}, {["x"] = 2, ["y"] = 15, ["z"] = 13, ["name"] = "wool:red"}, {["x"] = 3, ["meta"] = {["fields"] = {}, ["inventory"] = {}}, ["y"] = 0, ["param1"] = 56, ["z"] = 2, ["name"] = "default:wood"}, {["x"] = 3, ["meta"] = {["fields"] = {}, ["inventory"] = {}}, ["y"] = 0, ["param1"] = 56, ["z"] = 3, ["name"] = "default:wood"}, {["x"] = 3, ["meta"] = {["fields"] = {}, ["inventory"] = {}}, ["y"] = 0, ["param1"] = 56, ["z"] = 12, ["name"] = "default:wood"}, {["x"] = 3, ["meta"] = {["fields"] = {}, ["inventory"] = {}}, ["y"] = 0, ["param1"] = 56, ["z"] = 13, ["name"] = "default:wood"}, {["x"] = 3, ["meta"] = {["fields"] = {}, ["inventory"] = {}}, ["y"] = 1, ["param1"] = 56, ["z"] = 2, ["name"] = "default:wood"}, {["x"] = 3, ["meta"] = {["fields"] = {}, ["inventory"] = {}}, ["y"] = 1, ["param1"] = 56, ["z"] = 3, ["name"] = "default:wood"}, {["x"] = 3, ["y"] = 1, ["param1"] = 56, ["z"] = 12, ["name"] = "default:wood"}, {["x"] = 3, ["y"] = 1, ["param1"] = 56, ["z"] = 13, ["name"] = "default:wood"}, {["x"] = 3, ["meta"] = {["fields"] = {}, ["inventory"] = {}}, ["y"] = 2, ["param1"] = 56, ["z"] = 2, ["name"] = "default:wood"}, {["x"] = 3, ["meta"] = {["fields"] = {}, ["inventory"] = {}}, ["y"] = 2, ["param1"] = 56, ["z"] = 3, ["name"] = "default:wood"}, {["x"] = 3, ["y"] = 2, ["param1"] = 56, ["z"] = 12, ["name"] = "default:wood"}, {["x"] = 3, ["y"] = 2, ["param1"] = 56, ["z"] = 13, ["name"] = "default:wood"}, {["x"] = 3, ["meta"] = {["fields"] = {}, ["inventory"] = {}}, ["y"] = 3, ["param1"] = 56, ["z"] = 2, ["name"] = "default:wood"}, {["x"] = 3, ["meta"] = {["fields"] = {}, ["inventory"] = {}}, ["y"] = 3, ["param1"] = 56, ["z"] = 3, ["name"] = "default:wood"}, {["x"] = 3, ["y"] = 3, ["param1"] = 56, ["z"] = 12, ["name"] = "default:wood"}, {["x"] = 3, ["y"] = 3, ["param1"] = 56, ["z"] = 13, ["name"] = "default:wood"}, {["x"] = 3, ["meta"] = {["fields"] = {}, ["inventory"] = {}}, ["y"] = 4, ["param1"] = 56, ["z"] = 2, ["name"] = "default:wood"}, {["x"] = 3, ["meta"] = {["fields"] = {}, ["inventory"] = {}}, ["y"] = 4, ["param1"] = 56, ["z"] = 3, ["name"] = "default:wood"}, {["x"] = 3, ["y"] = 4, ["param1"] = 56, ["z"] = 12, ["name"] = "default:wood"}, {["x"] = 3, ["y"] = 4, ["param1"] = 56, ["z"] = 13, ["name"] = "default:wood"}, {["x"] = 3, ["meta"] = {["fields"] = {}, ["inventory"] = {}}, ["y"] = 5, ["param1"] = 56, ["z"] = 2, ["name"] = "default:wood"}, {["x"] = 3, ["meta"] = {["fields"] = {}, ["inventory"] = {}}, ["y"] = 5, ["param1"] = 56, ["z"] = 3, ["name"] = "default:wood"}, {["x"] = 3, ["y"] = 5, ["param1"] = 56, ["z"] = 12, ["name"] = "default:wood"}, {["x"] = 3, ["y"] = 5, ["param1"] = 56, ["z"] = 13, ["name"] = "default:wood"}, {["x"] = 3, ["meta"] = {["fields"] = {}, ["inventory"] = {}}, ["y"] = 6, ["param1"] = 56, ["z"] = 2, ["name"] = "default:wood"}, {["x"] = 3, ["meta"] = {["fields"] = {}, ["inventory"] = {}}, ["y"] = 6, ["param1"] = 56, ["z"] = 3, ["name"] = "default:wood"}, {["x"] = 3, ["y"] = 6, ["param1"] = 56, ["z"] = 12, ["name"] = "default:wood"}, {["x"] = 3, ["y"] = 6, ["param1"] = 56, ["z"] = 13, ["name"] = "default:wood"}, {["x"] = 3, ["meta"] = {["fields"] = {}, ["inventory"] = {}}, ["y"] = 7, ["param1"] = 56, ["z"] = 2, ["name"] = "default:wood"}, {["x"] = 3, ["meta"] = {["fields"] = {}, ["inventory"] = {}}, ["y"] = 7, ["param1"] = 56, ["z"] = 3, ["name"] = "default:wood"}, {["x"] = 3, ["y"] = 7, ["param1"] = 56, ["z"] = 12, ["name"] = "default:wood"}, {["x"] = 3, ["y"] = 7, ["param1"] = 56, ["z"] = 13, ["name"] = "default:wood"}, {["x"] = 3, ["meta"] = {["fields"] = {}, ["inventory"] = {}}, ["y"] = 8, ["param1"] = 56, ["z"] = 2, ["name"] = "default:wood"}, {["x"] = 3, ["meta"] = {["fields"] = {}, ["inventory"] = {}}, ["y"] = 8, ["param1"] = 56, ["z"] = 3, ["name"] = "default:wood"}, {["x"] = 3, ["y"] = 8, ["param1"] = 56, ["z"] = 12, ["name"] = "default:wood"}, {["x"] = 3, ["y"] = 8, ["param1"] = 56, ["z"] = 13, ["name"] = "default:wood"}, {["x"] = 3, ["meta"] = {["fields"] = {}, ["inventory"] = {}}, ["y"] = 9, ["param1"] = 56, ["z"] = 2, ["name"] = "default:wood"}, {["x"] = 3, ["meta"] = {["fields"] = {}, ["inventory"] = {}}, ["y"] = 9, ["param1"] = 56, ["z"] = 3, ["name"] = "default:wood"}, {["x"] = 3, ["y"] = 9, ["param1"] = 56, ["z"] = 12, ["name"] = "default:wood"}, {["x"] = 3, ["y"] = 9, ["param1"] = 56, ["z"] = 13, ["name"] = "default:wood"}, {["x"] = 3, ["meta"] = {["fields"] = {}, ["inventory"] = {}}, ["y"] = 10, ["param1"] = 56, ["z"] = 2, ["name"] = "default:wood"}, {["x"] = 3, ["meta"] = {["fields"] = {}, ["inventory"] = {}}, ["y"] = 10, ["param1"] = 56, ["z"] = 3, ["name"] = "default:wood"}, {["x"] = 3, ["y"] = 10, ["param1"] = 56, ["z"] = 12, ["name"] = "default:wood"}, {["x"] = 3, ["y"] = 10, ["param1"] = 56, ["z"] = 13, ["name"] = "default:wood"}, {["x"] = 3, ["meta"] = {["fields"] = {}, ["inventory"] = {}}, ["y"] = 11, ["param1"] = 56, ["z"] = 2, ["name"] = "default:wood"}, {["x"] = 3, ["meta"] = {["fields"] = {}, ["inventory"] = {}}, ["y"] = 11, ["param1"] = 56, ["z"] = 3, ["name"] = "default:wood"}, {["x"] = 3, ["y"] = 11, ["param1"] = 56, ["z"] = 12, ["name"] = "default:wood"}, {["x"] = 3, ["y"] = 11, ["param1"] = 56, ["z"] = 13, ["name"] = "default:wood"}, {["x"] = 3, ["meta"] = {["fields"] = {}, ["inventory"] = {}}, ["y"] = 12, ["param1"] = 62, ["z"] = 0, ["name"] = "default:junglewood"}, {["x"] = 3, ["meta"] = {["fields"] = {}, ["inventory"] = {}}, ["y"] = 12, ["param1"] = 62, ["z"] = 1, ["name"] = "default:junglewood"}, {["x"] = 3, ["meta"] = {["fields"] = {}, ["inventory"] = {}}, ["y"] = 12, ["param1"] = 62, ["z"] = 2, ["name"] = "default:junglewood"}, {["x"] = 3, ["meta"] = {["fields"] = {}, ["inventory"] = {}}, ["y"] = 12, ["param1"] = 62, ["z"] = 3, ["name"] = "default:junglewood"}, {["x"] = 3, ["meta"] = {["fields"] = {}, ["inventory"] = {}}, ["y"] = 12, ["param1"] = 62, ["z"] = 4, ["name"] = "default:junglewood"}, {["x"] = 3, ["meta"] = {["fields"] = {}, ["inventory"] = {}}, ["y"] = 12, ["param1"] = 62, ["z"] = 5, ["name"] = "default:junglewood"}, {["x"] = 3, ["meta"] = {["fields"] = {}, ["inventory"] = {}}, ["y"] = 12, ["param1"] = 62, ["z"] = 6, ["name"] = "default:junglewood"}, {["x"] = 3, ["meta"] = {["fields"] = {}, ["inventory"] = {}}, ["y"] = 12, ["param1"] = 62, ["z"] = 7, ["name"] = "default:junglewood"}, {["x"] = 3, ["meta"] = {["fields"] = {}, ["inventory"] = {}}, ["y"] = 12, ["param1"] = 62, ["z"] = 8, ["name"] = "default:junglewood"}, {["x"] = 3, ["meta"] = {["fields"] = {}, ["inventory"] = {}}, ["y"] = 12, ["param1"] = 62, ["z"] = 9, ["name"] = "default:junglewood"}, {["x"] = 3, ["meta"] = {["fields"] = {}, ["inventory"] = {}}, ["y"] = 12, ["param1"] = 62, ["z"] = 10, ["name"] = "default:junglewood"}, {["x"] = 3, ["meta"] = {["fields"] = {}, ["inventory"] = {}}, ["y"] = 12, ["param1"] = 62, ["z"] = 11, ["name"] = "default:junglewood"}, {["x"] = 3, ["meta"] = {["fields"] = {}, ["inventory"] = {}}, ["y"] = 12, ["param1"] = 62, ["z"] = 12, ["name"] = "default:junglewood"}, {["x"] = 3, ["meta"] = {["fields"] = {}, ["inventory"] = {}}, ["y"] = 12, ["param1"] = 62, ["z"] = 13, ["name"] = "default:junglewood"}, {["x"] = 3, ["meta"] = {["fields"] = {}, ["inventory"] = {}}, ["y"] = 12, ["param1"] = 62, ["z"] = 14, ["name"] = "default:junglewood"}, {["x"] = 3, ["meta"] = {["fields"] = {}, ["inventory"] = {}}, ["y"] = 12, ["param1"] = 62, ["z"] = 15, ["name"] = "default:junglewood"}, {["x"] = 3, ["meta"] = {["fields"] = {}, ["inventory"] = {}}, ["y"] = 13, ["param1"] = 62, ["z"] = 0, ["name"] = "default:junglewood"}, {["x"] = 3, ["meta"] = {["fields"] = {}, ["inventory"] = {}}, ["y"] = 13, ["param1"] = 62, ["z"] = 1, ["name"] = "default:junglewood"}, {["x"] = 3, ["meta"] = {["fields"] = {}, ["inventory"] = {}}, ["y"] = 13, ["param1"] = 62, ["z"] = 2, ["name"] = "default:junglewood"}, {["x"] = 3, ["meta"] = {["fields"] = {}, ["inventory"] = {}}, ["y"] = 13, ["param1"] = 62, ["z"] = 3, ["name"] = "default:junglewood"}, {["x"] = 3, ["meta"] = {["fields"] = {}, ["inventory"] = {}}, ["y"] = 13, ["param1"] = 62, ["z"] = 4, ["name"] = "default:junglewood"}, {["x"] = 3, ["meta"] = {["fields"] = {}, ["inventory"] = {}}, ["y"] = 13, ["param1"] = 62, ["z"] = 5, ["name"] = "default:junglewood"}, {["x"] = 3, ["meta"] = {["fields"] = {}, ["inventory"] = {}}, ["y"] = 13, ["param1"] = 62, ["z"] = 6, ["name"] = "default:junglewood"}, {["x"] = 3, ["meta"] = {["fields"] = {}, ["inventory"] = {}}, ["y"] = 13, ["param1"] = 62, ["z"] = 7, ["name"] = "default:junglewood"}, {["x"] = 3, ["meta"] = {["fields"] = {}, ["inventory"] = {}}, ["y"] = 13, ["param1"] = 62, ["z"] = 8, ["name"] = "default:junglewood"}, {["x"] = 3, ["meta"] = {["fields"] = {}, ["inventory"] = {}}, ["y"] = 13, ["param1"] = 62, ["z"] = 9, ["name"] = "default:junglewood"}, {["x"] = 3, ["meta"] = {["fields"] = {}, ["inventory"] = {}}, ["y"] = 13, ["param1"] = 62, ["z"] = 10, ["name"] = "default:junglewood"}, {["x"] = 3, ["meta"] = {["fields"] = {}, ["inventory"] = {}}, ["y"] = 13, ["param1"] = 62, ["z"] = 11, ["name"] = "default:junglewood"}, {["x"] = 3, ["meta"] = {["fields"] = {}, ["inventory"] = {}}, ["y"] = 13, ["param1"] = 62, ["z"] = 12, ["name"] = "default:junglewood"}, {["x"] = 3, ["meta"] = {["fields"] = {}, ["inventory"] = {}}, ["y"] = 13, ["param1"] = 62, ["z"] = 13, ["name"] = "default:junglewood"}, {["x"] = 3, ["meta"] = {["fields"] = {}, ["inventory"] = {}}, ["y"] = 13, ["param1"] = 62, ["z"] = 14, ["name"] = "default:junglewood"}, {["x"] = 3, ["meta"] = {["fields"] = {}, ["inventory"] = {}}, ["y"] = 13, ["param1"] = 62, ["z"] = 15, ["name"] = "default:junglewood"}, {["x"] = 3, ["meta"] = {["fields"] = {}, ["inventory"] = {}}, ["y"] = 14, ["param1"] = 62, ["z"] = 0, ["name"] = "default:junglewood"}, {["x"] = 3, ["meta"] = {["fields"] = {}, ["inventory"] = {}}, ["y"] = 14, ["param1"] = 62, ["z"] = 1, ["name"] = "default:junglewood"}, {["x"] = 3, ["meta"] = {["fields"] = {}, ["inventory"] = {}}, ["y"] = 14, ["param1"] = 62, ["z"] = 2, ["name"] = "default:junglewood"}, {["x"] = 3, ["meta"] = {["fields"] = {}, ["inventory"] = {}}, ["y"] = 14, ["param1"] = 62, ["z"] = 3, ["name"] = "default:junglewood"}, {["x"] = 3, ["meta"] = {["fields"] = {}, ["inventory"] = {}}, ["y"] = 14, ["param1"] = 62, ["z"] = 4, ["name"] = "default:junglewood"}, {["x"] = 3, ["meta"] = {["fields"] = {}, ["inventory"] = {}}, ["y"] = 14, ["param1"] = 62, ["z"] = 5, ["name"] = "default:junglewood"}, {["x"] = 3, ["meta"] = {["fields"] = {}, ["inventory"] = {}}, ["y"] = 14, ["param1"] = 62, ["z"] = 6, ["name"] = "default:junglewood"}, {["x"] = 3, ["meta"] = {["fields"] = {}, ["inventory"] = {}}, ["y"] = 14, ["param1"] = 62, ["z"] = 7, ["name"] = "default:junglewood"}, {["x"] = 3, ["meta"] = {["fields"] = {}, ["inventory"] = {}}, ["y"] = 14, ["param1"] = 62, ["z"] = 8, ["name"] = "default:junglewood"}, {["x"] = 3, ["meta"] = {["fields"] = {}, ["inventory"] = {}}, ["y"] = 14, ["param1"] = 62, ["z"] = 9, ["name"] = "default:junglewood"}, {["x"] = 3, ["meta"] = {["fields"] = {}, ["inventory"] = {}}, ["y"] = 14, ["param1"] = 62, ["z"] = 10, ["name"] = "default:junglewood"}, {["x"] = 3, ["meta"] = {["fields"] = {}, ["inventory"] = {}}, ["y"] = 14, ["param1"] = 62, ["z"] = 11, ["name"] = "default:junglewood"}, {["x"] = 3, ["meta"] = {["fields"] = {}, ["inventory"] = {}}, ["y"] = 14, ["param1"] = 62, ["z"] = 12, ["name"] = "default:junglewood"}, {["x"] = 3, ["meta"] = {["fields"] = {}, ["inventory"] = {}}, ["y"] = 14, ["param1"] = 62, ["z"] = 13, ["name"] = "default:junglewood"}, {["x"] = 3, ["meta"] = {["fields"] = {}, ["inventory"] = {}}, ["y"] = 14, ["param1"] = 62, ["z"] = 14, ["name"] = "default:junglewood"}, {["x"] = 3, ["meta"] = {["fields"] = {}, ["inventory"] = {}}, ["y"] = 14, ["param1"] = 62, ["z"] = 15, ["name"] = "default:junglewood"}, {["x"] = 3, ["y"] = 15, ["z"] = 2, ["name"] = "wool:red"}, {["x"] = 3, ["y"] = 15, ["z"] = 3, ["name"] = "wool:red"}, {["x"] = 3, ["y"] = 15, ["z"] = 4, ["name"] = "wool:red"}, {["x"] = 3, ["y"] = 15, ["z"] = 5, ["name"] = "wool:red"}, {["x"] = 3, ["y"] = 15, ["z"] = 6, ["name"] = "wool:red"}, {["x"] = 3, ["y"] = 15, ["z"] = 7, ["name"] = "wool:red"}, {["x"] = 3, ["y"] = 15, ["z"] = 8, ["name"] = "wool:red"}, {["x"] = 3, ["y"] = 15, ["z"] = 9, ["name"] = "wool:red"}, {["x"] = 3, ["y"] = 15, ["z"] = 10, ["name"] = "wool:red"}, {["x"] = 3, ["y"] = 15, ["z"] = 11, ["name"] = "wool:red"}, {["x"] = 3, ["y"] = 15, ["z"] = 12, ["name"] = "wool:red"}, {["x"] = 3, ["y"] = 15, ["z"] = 13, ["name"] = "wool:red"}, {["x"] = 4, ["meta"] = {["fields"] = {}, ["inventory"] = {}}, ["y"] = 12, ["param1"] = 62, ["z"] = 0, ["name"] = "default:junglewood"}, {["x"] = 4, ["meta"] = {["fields"] = {}, ["inventory"] = {}}, ["y"] = 12, ["param1"] = 62, ["z"] = 1, ["name"] = "default:junglewood"}, {["x"] = 4, ["meta"] = {["fields"] = {}, ["inventory"] = {}}, ["y"] = 12, ["param1"] = 62, ["z"] = 2, ["name"] = "default:junglewood"}, {["x"] = 4, ["meta"] = {["fields"] = {}, ["inventory"] = {}}, ["y"] = 12, ["param1"] = 62, ["z"] = 3, ["name"] = "default:junglewood"}, {["x"] = 4, ["meta"] = {["fields"] = {}, ["inventory"] = {}}, ["y"] = 12, ["param1"] = 62, ["z"] = 4, ["name"] = "default:junglewood"}, {["x"] = 4, ["meta"] = {["fields"] = {}, ["inventory"] = {}}, ["y"] = 12, ["param1"] = 62, ["z"] = 5, ["name"] = "default:junglewood"}, {["x"] = 4, ["meta"] = {["fields"] = {}, ["inventory"] = {}}, ["y"] = 12, ["param1"] = 62, ["z"] = 6, ["name"] = "default:junglewood"}, {["x"] = 4, ["meta"] = {["fields"] = {}, ["inventory"] = {}}, ["y"] = 12, ["param1"] = 62, ["z"] = 7, ["name"] = "default:junglewood"}, {["x"] = 4, ["meta"] = {["fields"] = {}, ["inventory"] = {}}, ["y"] = 12, ["param1"] = 62, ["z"] = 8, ["name"] = "default:junglewood"}, {["x"] = 4, ["meta"] = {["fields"] = {}, ["inventory"] = {}}, ["y"] = 12, ["param1"] = 62, ["z"] = 9, ["name"] = "default:junglewood"}, {["x"] = 4, ["meta"] = {["fields"] = {}, ["inventory"] = {}}, ["y"] = 12, ["param1"] = 62, ["z"] = 10, ["name"] = "default:junglewood"}, {["x"] = 4, ["meta"] = {["fields"] = {}, ["inventory"] = {}}, ["y"] = 12, ["param1"] = 62, ["z"] = 11, ["name"] = "default:junglewood"}, {["x"] = 4, ["meta"] = {["fields"] = {}, ["inventory"] = {}}, ["y"] = 12, ["param1"] = 62, ["z"] = 12, ["name"] = "default:junglewood"}, {["x"] = 4, ["meta"] = {["fields"] = {}, ["inventory"] = {}}, ["y"] = 12, ["param1"] = 62, ["z"] = 13, ["name"] = "default:junglewood"}, {["x"] = 4, ["meta"] = {["fields"] = {}, ["inventory"] = {}}, ["y"] = 12, ["param1"] = 62, ["z"] = 14, ["name"] = "default:junglewood"}, {["x"] = 4, ["meta"] = {["fields"] = {}, ["inventory"] = {}}, ["y"] = 12, ["param1"] = 62, ["z"] = 15, ["name"] = "default:junglewood"}, {["x"] = 4, ["meta"] = {["fields"] = {}, ["inventory"] = {}}, ["y"] = 13, ["param1"] = 62, ["z"] = 0, ["name"] = "default:junglewood"}, {["x"] = 4, ["meta"] = {["fields"] = {}, ["inventory"] = {}}, ["y"] = 13, ["param1"] = 62, ["z"] = 1, ["name"] = "default:junglewood"}, {["x"] = 4, ["meta"] = {["fields"] = {}, ["inventory"] = {}}, ["y"] = 13, ["param1"] = 62, ["z"] = 2, ["name"] = "default:junglewood"}, {["x"] = 4, ["meta"] = {["fields"] = {}, ["inventory"] = {}}, ["y"] = 13, ["param1"] = 62, ["z"] = 3, ["name"] = "default:junglewood"}, {["x"] = 4, ["meta"] = {["fields"] = {}, ["inventory"] = {}}, ["y"] = 13, ["param1"] = 62, ["z"] = 4, ["name"] = "default:junglewood"}, {["x"] = 4, ["meta"] = {["fields"] = {}, ["inventory"] = {}}, ["y"] = 13, ["param1"] = 62, ["z"] = 5, ["name"] = "default:junglewood"}, {["x"] = 4, ["meta"] = {["fields"] = {}, ["inventory"] = {}}, ["y"] = 13, ["param1"] = 62, ["z"] = 6, ["name"] = "default:junglewood"}, {["x"] = 4, ["meta"] = {["fields"] = {}, ["inventory"] = {}}, ["y"] = 13, ["param1"] = 62, ["z"] = 7, ["name"] = "default:junglewood"}, {["x"] = 4, ["meta"] = {["fields"] = {}, ["inventory"] = {}}, ["y"] = 13, ["param1"] = 62, ["z"] = 8, ["name"] = "default:junglewood"}, {["x"] = 4, ["meta"] = {["fields"] = {}, ["inventory"] = {}}, ["y"] = 13, ["param1"] = 62, ["z"] = 9, ["name"] = "default:junglewood"}, {["x"] = 4, ["meta"] = {["fields"] = {}, ["inventory"] = {}}, ["y"] = 13, ["param1"] = 62, ["z"] = 10, ["name"] = "default:junglewood"}, {["x"] = 4, ["meta"] = {["fields"] = {}, ["inventory"] = {}}, ["y"] = 13, ["param1"] = 62, ["z"] = 11, ["name"] = "default:junglewood"}, {["x"] = 4, ["meta"] = {["fields"] = {}, ["inventory"] = {}}, ["y"] = 13, ["param1"] = 62, ["z"] = 12, ["name"] = "default:junglewood"}, {["x"] = 4, ["meta"] = {["fields"] = {}, ["inventory"] = {}}, ["y"] = 13, ["param1"] = 62, ["z"] = 13, ["name"] = "default:junglewood"}, {["x"] = 4, ["meta"] = {["fields"] = {}, ["inventory"] = {}}, ["y"] = 13, ["param1"] = 62, ["z"] = 14, ["name"] = "default:junglewood"}, {["x"] = 4, ["meta"] = {["fields"] = {}, ["inventory"] = {}}, ["y"] = 13, ["param1"] = 62, ["z"] = 15, ["name"] = "default:junglewood"}, {["x"] = 4, ["meta"] = {["fields"] = {}, ["inventory"] = {}}, ["y"] = 14, ["param1"] = 62, ["z"] = 0, ["name"] = "default:junglewood"}, {["x"] = 4, ["meta"] = {["fields"] = {}, ["inventory"] = {}}, ["y"] = 14, ["param1"] = 62, ["z"] = 1, ["name"] = "default:junglewood"}, {["x"] = 4, ["meta"] = {["fields"] = {}, ["inventory"] = {}}, ["y"] = 14, ["param1"] = 62, ["z"] = 2, ["name"] = "default:junglewood"}, {["x"] = 4, ["meta"] = {["fields"] = {}, ["inventory"] = {}}, ["y"] = 14, ["param1"] = 62, ["z"] = 3, ["name"] = "default:junglewood"}, {["x"] = 4, ["meta"] = {["fields"] = {}, ["inventory"] = {}}, ["y"] = 14, ["param1"] = 62, ["z"] = 4, ["name"] = "default:junglewood"}, {["x"] = 4, ["meta"] = {["fields"] = {}, ["inventory"] = {}}, ["y"] = 14, ["param1"] = 62, ["z"] = 5, ["name"] = "default:junglewood"}, {["x"] = 4, ["meta"] = {["fields"] = {}, ["inventory"] = {}}, ["y"] = 14, ["param1"] = 62, ["z"] = 6, ["name"] = "default:junglewood"}, {["x"] = 4, ["meta"] = {["fields"] = {}, ["inventory"] = {}}, ["y"] = 14, ["param1"] = 62, ["z"] = 7, ["name"] = "default:junglewood"}, {["x"] = 4, ["meta"] = {["fields"] = {}, ["inventory"] = {}}, ["y"] = 14, ["param1"] = 62, ["z"] = 8, ["name"] = "default:junglewood"}, {["x"] = 4, ["meta"] = {["fields"] = {}, ["inventory"] = {}}, ["y"] = 14, ["param1"] = 62, ["z"] = 9, ["name"] = "default:junglewood"}, {["x"] = 4, ["meta"] = {["fields"] = {}, ["inventory"] = {}}, ["y"] = 14, ["param1"] = 62, ["z"] = 10, ["name"] = "default:junglewood"}, {["x"] = 4, ["meta"] = {["fields"] = {}, ["inventory"] = {}}, ["y"] = 14, ["param1"] = 62, ["z"] = 11, ["name"] = "default:junglewood"}, {["x"] = 4, ["meta"] = {["fields"] = {}, ["inventory"] = {}}, ["y"] = 14, ["param1"] = 62, ["z"] = 12, ["name"] = "default:junglewood"}, {["x"] = 4, ["meta"] = {["fields"] = {}, ["inventory"] = {}}, ["y"] = 14, ["param1"] = 62, ["z"] = 13, ["name"] = "default:junglewood"}, {["x"] = 4, ["meta"] = {["fields"] = {}, ["inventory"] = {}}, ["y"] = 14, ["param1"] = 62, ["z"] = 14, ["name"] = "default:junglewood"}, {["x"] = 4, ["meta"] = {["fields"] = {}, ["inventory"] = {}}, ["y"] = 14, ["param1"] = 62, ["z"] = 15, ["name"] = "default:junglewood"}, {["x"] = 4, ["y"] = 15, ["z"] = 2, ["name"] = "wool:red"}, {["x"] = 4, ["y"] = 15, ["z"] = 3, ["name"] = "wool:red"}, {["x"] = 4, ["y"] = 15, ["z"] = 4, ["name"] = "wool:red"}, {["x"] = 4, ["y"] = 15, ["z"] = 5, ["name"] = "wool:red"}, {["x"] = 4, ["y"] = 15, ["z"] = 6, ["name"] = "wool:red"}, {["x"] = 4, ["y"] = 15, ["z"] = 7, ["name"] = "wool:red"}, {["x"] = 4, ["y"] = 15, ["z"] = 8, ["name"] = "wool:red"}, {["x"] = 4, ["y"] = 15, ["z"] = 9, ["name"] = "wool:red"}, {["x"] = 4, ["y"] = 15, ["z"] = 10, ["name"] = "wool:red"}, {["x"] = 4, ["y"] = 15, ["z"] = 11, ["name"] = "wool:red"}, {["x"] = 4, ["y"] = 15, ["z"] = 12, ["name"] = "wool:red"}, {["x"] = 4, ["y"] = 15, ["z"] = 13, ["name"] = "wool:red"}, {["x"] = 5, ["meta"] = {["fields"] = {}, ["inventory"] = {}}, ["y"] = 12, ["param1"] = 62, ["z"] = 0, ["name"] = "default:junglewood"}, {["x"] = 5, ["meta"] = {["fields"] = {}, ["inventory"] = {}}, ["y"] = 12, ["param1"] = 62, ["z"] = 1, ["name"] = "default:junglewood"}, {["x"] = 5, ["meta"] = {["fields"] = {}, ["inventory"] = {}}, ["y"] = 12, ["param1"] = 62, ["z"] = 2, ["name"] = "default:junglewood"}, {["x"] = 5, ["meta"] = {["fields"] = {}, ["inventory"] = {}}, ["y"] = 12, ["param1"] = 62, ["z"] = 3, ["name"] = "default:junglewood"}, {["x"] = 5, ["meta"] = {["fields"] = {}, ["inventory"] = {}}, ["y"] = 12, ["param1"] = 62, ["z"] = 4, ["name"] = "default:junglewood"}, {["x"] = 5, ["meta"] = {["fields"] = {}, ["inventory"] = {}}, ["y"] = 12, ["param1"] = 62, ["z"] = 5, ["name"] = "default:junglewood"}, {["x"] = 5, ["meta"] = {["fields"] = {}, ["inventory"] = {}}, ["y"] = 12, ["param1"] = 62, ["z"] = 6, ["name"] = "default:junglewood"}, {["x"] = 5, ["meta"] = {["fields"] = {}, ["inventory"] = {}}, ["y"] = 12, ["param1"] = 62, ["z"] = 7, ["name"] = "default:junglewood"}, {["x"] = 5, ["meta"] = {["fields"] = {}, ["inventory"] = {}}, ["y"] = 12, ["param1"] = 62, ["z"] = 8, ["name"] = "default:junglewood"}, {["x"] = 5, ["meta"] = {["fields"] = {}, ["inventory"] = {}}, ["y"] = 12, ["param1"] = 62, ["z"] = 9, ["name"] = "default:junglewood"}, {["x"] = 5, ["meta"] = {["fields"] = {}, ["inventory"] = {}}, ["y"] = 12, ["param1"] = 62, ["z"] = 10, ["name"] = "default:junglewood"}, {["x"] = 5, ["meta"] = {["fields"] = {}, ["inventory"] = {}}, ["y"] = 12, ["param1"] = 62, ["z"] = 11, ["name"] = "default:junglewood"}, {["x"] = 5, ["meta"] = {["fields"] = {}, ["inventory"] = {}}, ["y"] = 12, ["param1"] = 62, ["z"] = 12, ["name"] = "default:junglewood"}, {["x"] = 5, ["meta"] = {["fields"] = {}, ["inventory"] = {}}, ["y"] = 12, ["param1"] = 62, ["z"] = 13, ["name"] = "default:junglewood"}, {["x"] = 5, ["meta"] = {["fields"] = {}, ["inventory"] = {}}, ["y"] = 12, ["param1"] = 62, ["z"] = 14, ["name"] = "default:junglewood"}, {["x"] = 5, ["meta"] = {["fields"] = {}, ["inventory"] = {}}, ["y"] = 12, ["param1"] = 62, ["z"] = 15, ["name"] = "default:junglewood"}, {["x"] = 5, ["meta"] = {["fields"] = {}, ["inventory"] = {}}, ["y"] = 13, ["param1"] = 62, ["z"] = 0, ["name"] = "default:junglewood"}, {["x"] = 5, ["meta"] = {["fields"] = {}, ["inventory"] = {}}, ["y"] = 13, ["param1"] = 62, ["z"] = 1, ["name"] = "default:junglewood"}, {["x"] = 5, ["meta"] = {["fields"] = {}, ["inventory"] = {}}, ["y"] = 13, ["param1"] = 62, ["z"] = 2, ["name"] = "default:junglewood"}, {["x"] = 5, ["meta"] = {["fields"] = {}, ["inventory"] = {}}, ["y"] = 13, ["param1"] = 62, ["z"] = 3, ["name"] = "default:junglewood"}, {["x"] = 5, ["meta"] = {["fields"] = {}, ["inventory"] = {}}, ["y"] = 13, ["param1"] = 62, ["z"] = 4, ["name"] = "default:junglewood"}, {["x"] = 5, ["meta"] = {["fields"] = {}, ["inventory"] = {}}, ["y"] = 13, ["param1"] = 62, ["z"] = 5, ["name"] = "default:junglewood"}, {["x"] = 5, ["meta"] = {["fields"] = {}, ["inventory"] = {}}, ["y"] = 13, ["param1"] = 62, ["z"] = 6, ["name"] = "default:junglewood"}, {["x"] = 5, ["meta"] = {["fields"] = {}, ["inventory"] = {}}, ["y"] = 13, ["param1"] = 62, ["z"] = 7, ["name"] = "default:junglewood"}, {["x"] = 5, ["meta"] = {["fields"] = {}, ["inventory"] = {}}, ["y"] = 13, ["param1"] = 62, ["z"] = 8, ["name"] = "default:junglewood"}, {["x"] = 5, ["meta"] = {["fields"] = {}, ["inventory"] = {}}, ["y"] = 13, ["param1"] = 62, ["z"] = 9, ["name"] = "default:junglewood"}, {["x"] = 5, ["meta"] = {["fields"] = {}, ["inventory"] = {}}, ["y"] = 13, ["param1"] = 62, ["z"] = 10, ["name"] = "default:junglewood"}, {["x"] = 5, ["meta"] = {["fields"] = {}, ["inventory"] = {}}, ["y"] = 13, ["param1"] = 62, ["z"] = 11, ["name"] = "default:junglewood"}, {["x"] = 5, ["meta"] = {["fields"] = {}, ["inventory"] = {}}, ["y"] = 13, ["param1"] = 62, ["z"] = 12, ["name"] = "default:junglewood"}, {["x"] = 5, ["meta"] = {["fields"] = {}, ["inventory"] = {}}, ["y"] = 13, ["param1"] = 62, ["z"] = 13, ["name"] = "default:junglewood"}, {["x"] = 5, ["meta"] = {["fields"] = {}, ["inventory"] = {}}, ["y"] = 13, ["param1"] = 62, ["z"] = 14, ["name"] = "default:junglewood"}, {["x"] = 5, ["meta"] = {["fields"] = {}, ["inventory"] = {}}, ["y"] = 13, ["param1"] = 62, ["z"] = 15, ["name"] = "default:junglewood"}, {["x"] = 5, ["meta"] = {["fields"] = {}, ["inventory"] = {}}, ["y"] = 14, ["param1"] = 62, ["z"] = 0, ["name"] = "default:junglewood"}, {["x"] = 5, ["meta"] = {["fields"] = {}, ["inventory"] = {}}, ["y"] = 14, ["param1"] = 62, ["z"] = 1, ["name"] = "default:junglewood"}, {["x"] = 5, ["meta"] = {["fields"] = {}, ["inventory"] = {}}, ["y"] = 14, ["param1"] = 62, ["z"] = 2, ["name"] = "default:junglewood"}, {["x"] = 5, ["meta"] = {["fields"] = {}, ["inventory"] = {}}, ["y"] = 14, ["param1"] = 62, ["z"] = 3, ["name"] = "default:junglewood"}, {["x"] = 5, ["meta"] = {["fields"] = {}, ["inventory"] = {}}, ["y"] = 14, ["param1"] = 62, ["z"] = 4, ["name"] = "default:junglewood"}, {["x"] = 5, ["meta"] = {["fields"] = {}, ["inventory"] = {}}, ["y"] = 14, ["param1"] = 62, ["z"] = 5, ["name"] = "default:junglewood"}, {["x"] = 5, ["meta"] = {["fields"] = {}, ["inventory"] = {}}, ["y"] = 14, ["param1"] = 62, ["z"] = 6, ["name"] = "default:junglewood"}, {["x"] = 5, ["meta"] = {["fields"] = {}, ["inventory"] = {}}, ["y"] = 14, ["param1"] = 62, ["z"] = 7, ["name"] = "default:junglewood"}, {["x"] = 5, ["meta"] = {["fields"] = {}, ["inventory"] = {}}, ["y"] = 14, ["param1"] = 62, ["z"] = 8, ["name"] = "default:junglewood"}, {["x"] = 5, ["meta"] = {["fields"] = {}, ["inventory"] = {}}, ["y"] = 14, ["param1"] = 62, ["z"] = 9, ["name"] = "default:junglewood"}, {["x"] = 5, ["meta"] = {["fields"] = {}, ["inventory"] = {}}, ["y"] = 14, ["param1"] = 62, ["z"] = 10, ["name"] = "default:junglewood"}, {["x"] = 5, ["meta"] = {["fields"] = {}, ["inventory"] = {}}, ["y"] = 14, ["param1"] = 62, ["z"] = 11, ["name"] = "default:junglewood"}, {["x"] = 5, ["meta"] = {["fields"] = {}, ["inventory"] = {}}, ["y"] = 14, ["param1"] = 62, ["z"] = 12, ["name"] = "default:junglewood"}, {["x"] = 5, ["meta"] = {["fields"] = {}, ["inventory"] = {}}, ["y"] = 14, ["param1"] = 62, ["z"] = 13, ["name"] = "default:junglewood"}, {["x"] = 5, ["meta"] = {["fields"] = {}, ["inventory"] = {}}, ["y"] = 14, ["param1"] = 62, ["z"] = 14, ["name"] = "default:junglewood"}, {["x"] = 5, ["meta"] = {["fields"] = {}, ["inventory"] = {}}, ["y"] = 14, ["param1"] = 62, ["z"] = 15, ["name"] = "default:junglewood"}, {["x"] = 5, ["y"] = 15, ["z"] = 2, ["name"] = "wool:red"}, {["x"] = 5, ["y"] = 15, ["z"] = 3, ["name"] = "wool:red"}, {["x"] = 5, ["y"] = 15, ["z"] = 4, ["name"] = "wool:red"}, {["x"] = 5, ["y"] = 15, ["z"] = 5, ["name"] = "wool:red"}, {["x"] = 5, ["y"] = 15, ["z"] = 6, ["name"] = "wool:red"}, {["x"] = 5, ["y"] = 15, ["z"] = 7, ["name"] = "wool:red"}, {["x"] = 5, ["y"] = 15, ["z"] = 8, ["name"] = "wool:red"}, {["x"] = 5, ["y"] = 15, ["z"] = 9, ["name"] = "wool:red"}, {["x"] = 5, ["y"] = 15, ["z"] = 10, ["name"] = "wool:red"}, {["x"] = 5, ["y"] = 15, ["z"] = 11, ["name"] = "wool:red"}, {["x"] = 5, ["y"] = 15, ["z"] = 12, ["name"] = "wool:red"}, {["x"] = 5, ["y"] = 15, ["z"] = 13, ["name"] = "wool:red"}, {["x"] = 6, ["meta"] = {["fields"] = {}, ["inventory"] = {}}, ["y"] = 12, ["param1"] = 62, ["z"] = 0, ["name"] = "default:junglewood"}, {["x"] = 6, ["meta"] = {["fields"] = {}, ["inventory"] = {}}, ["y"] = 12, ["param1"] = 62, ["z"] = 1, ["name"] = "default:junglewood"}, {["x"] = 6, ["meta"] = {["fields"] = {}, ["inventory"] = {}}, ["y"] = 12, ["param1"] = 62, ["z"] = 2, ["name"] = "default:junglewood"}, {["x"] = 6, ["meta"] = {["fields"] = {}, ["inventory"] = {}}, ["y"] = 12, ["param1"] = 62, ["z"] = 3, ["name"] = "default:junglewood"}, {["x"] = 6, ["meta"] = {["fields"] = {}, ["inventory"] = {}}, ["y"] = 12, ["param1"] = 62, ["z"] = 4, ["name"] = "default:junglewood"}, {["x"] = 6, ["meta"] = {["fields"] = {}, ["inventory"] = {}}, ["y"] = 12, ["param1"] = 62, ["z"] = 5, ["name"] = "default:junglewood"}, {["x"] = 6, ["meta"] = {["fields"] = {}, ["inventory"] = {}}, ["y"] = 12, ["param1"] = 62, ["z"] = 6, ["name"] = "default:junglewood"}, {["x"] = 6, ["meta"] = {["fields"] = {}, ["inventory"] = {}}, ["y"] = 12, ["param1"] = 62, ["z"] = 7, ["name"] = "default:junglewood"}, {["x"] = 6, ["meta"] = {["fields"] = {}, ["inventory"] = {}}, ["y"] = 12, ["param1"] = 62, ["z"] = 8, ["name"] = "default:junglewood"}, {["x"] = 6, ["meta"] = {["fields"] = {}, ["inventory"] = {}}, ["y"] = 12, ["param1"] = 62, ["z"] = 9, ["name"] = "default:junglewood"}, {["x"] = 6, ["meta"] = {["fields"] = {}, ["inventory"] = {}}, ["y"] = 12, ["param1"] = 62, ["z"] = 10, ["name"] = "default:junglewood"}, {["x"] = 6, ["meta"] = {["fields"] = {}, ["inventory"] = {}}, ["y"] = 12, ["param1"] = 62, ["z"] = 11, ["name"] = "default:junglewood"}, {["x"] = 6, ["meta"] = {["fields"] = {}, ["inventory"] = {}}, ["y"] = 12, ["param1"] = 62, ["z"] = 12, ["name"] = "default:junglewood"}, {["x"] = 6, ["meta"] = {["fields"] = {}, ["inventory"] = {}}, ["y"] = 12, ["param1"] = 62, ["z"] = 13, ["name"] = "default:junglewood"}, {["x"] = 6, ["meta"] = {["fields"] = {}, ["inventory"] = {}}, ["y"] = 12, ["param1"] = 62, ["z"] = 14, ["name"] = "default:junglewood"}, {["x"] = 6, ["meta"] = {["fields"] = {}, ["inventory"] = {}}, ["y"] = 12, ["param1"] = 62, ["z"] = 15, ["name"] = "default:junglewood"}, {["x"] = 6, ["meta"] = {["fields"] = {}, ["inventory"] = {}}, ["y"] = 13, ["param1"] = 62, ["z"] = 0, ["name"] = "default:junglewood"}, {["x"] = 6, ["meta"] = {["fields"] = {}, ["inventory"] = {}}, ["y"] = 13, ["param1"] = 62, ["z"] = 1, ["name"] = "default:junglewood"}, {["x"] = 6, ["meta"] = {["fields"] = {}, ["inventory"] = {}}, ["y"] = 13, ["param1"] = 62, ["z"] = 2, ["name"] = "default:junglewood"}, {["x"] = 6, ["meta"] = {["fields"] = {}, ["inventory"] = {}}, ["y"] = 13, ["param1"] = 62, ["z"] = 3, ["name"] = "default:junglewood"}, {["x"] = 6, ["meta"] = {["fields"] = {}, ["inventory"] = {}}, ["y"] = 13, ["param1"] = 62, ["z"] = 4, ["name"] = "default:junglewood"}, {["x"] = 6, ["meta"] = {["fields"] = {}, ["inventory"] = {}}, ["y"] = 13, ["param1"] = 62, ["z"] = 5, ["name"] = "default:junglewood"}, {["x"] = 6, ["meta"] = {["fields"] = {}, ["inventory"] = {}}, ["y"] = 13, ["param1"] = 62, ["z"] = 6, ["name"] = "default:junglewood"}, {["x"] = 6, ["meta"] = {["fields"] = {}, ["inventory"] = {}}, ["y"] = 13, ["param1"] = 62, ["z"] = 7, ["name"] = "default:junglewood"}, {["x"] = 6, ["meta"] = {["fields"] = {}, ["inventory"] = {}}, ["y"] = 13, ["param1"] = 62, ["z"] = 8, ["name"] = "default:junglewood"}, {["x"] = 6, ["meta"] = {["fields"] = {}, ["inventory"] = {}}, ["y"] = 13, ["param1"] = 62, ["z"] = 9, ["name"] = "default:junglewood"}, {["x"] = 6, ["meta"] = {["fields"] = {}, ["inventory"] = {}}, ["y"] = 13, ["param1"] = 62, ["z"] = 10, ["name"] = "default:junglewood"}, {["x"] = 6, ["meta"] = {["fields"] = {}, ["inventory"] = {}}, ["y"] = 13, ["param1"] = 62, ["z"] = 11, ["name"] = "default:junglewood"}, {["x"] = 6, ["meta"] = {["fields"] = {}, ["inventory"] = {}}, ["y"] = 13, ["param1"] = 62, ["z"] = 12, ["name"] = "default:junglewood"}, {["x"] = 6, ["meta"] = {["fields"] = {}, ["inventory"] = {}}, ["y"] = 13, ["param1"] = 62, ["z"] = 13, ["name"] = "default:junglewood"}, {["x"] = 6, ["meta"] = {["fields"] = {}, ["inventory"] = {}}, ["y"] = 13, ["param1"] = 62, ["z"] = 14, ["name"] = "default:junglewood"}, {["x"] = 6, ["meta"] = {["fields"] = {}, ["inventory"] = {}}, ["y"] = 13, ["param1"] = 62, ["z"] = 15, ["name"] = "default:junglewood"}, {["x"] = 6, ["meta"] = {["fields"] = {}, ["inventory"] = {}}, ["y"] = 14, ["param1"] = 62, ["z"] = 0, ["name"] = "default:junglewood"}, {["x"] = 6, ["meta"] = {["fields"] = {}, ["inventory"] = {}}, ["y"] = 14, ["param1"] = 62, ["z"] = 1, ["name"] = "default:junglewood"}, {["x"] = 6, ["meta"] = {["fields"] = {}, ["inventory"] = {}}, ["y"] = 14, ["param1"] = 62, ["z"] = 2, ["name"] = "default:junglewood"}, {["x"] = 6, ["meta"] = {["fields"] = {}, ["inventory"] = {}}, ["y"] = 14, ["param1"] = 62, ["z"] = 3, ["name"] = "default:junglewood"}, {["x"] = 6, ["meta"] = {["fields"] = {}, ["inventory"] = {}}, ["y"] = 14, ["param1"] = 62, ["z"] = 4, ["name"] = "default:junglewood"}, {["x"] = 6, ["meta"] = {["fields"] = {}, ["inventory"] = {}}, ["y"] = 14, ["param1"] = 62, ["z"] = 5, ["name"] = "default:junglewood"}, {["x"] = 6, ["meta"] = {["fields"] = {}, ["inventory"] = {}}, ["y"] = 14, ["param1"] = 62, ["z"] = 6, ["name"] = "default:junglewood"}, {["x"] = 6, ["meta"] = {["fields"] = {}, ["inventory"] = {}}, ["y"] = 14, ["param1"] = 62, ["z"] = 7, ["name"] = "default:junglewood"}, {["x"] = 6, ["meta"] = {["fields"] = {}, ["inventory"] = {}}, ["y"] = 14, ["param1"] = 62, ["z"] = 8, ["name"] = "default:junglewood"}, {["x"] = 6, ["meta"] = {["fields"] = {}, ["inventory"] = {}}, ["y"] = 14, ["param1"] = 62, ["z"] = 9, ["name"] = "default:junglewood"}, {["x"] = 6, ["meta"] = {["fields"] = {}, ["inventory"] = {}}, ["y"] = 14, ["param1"] = 62, ["z"] = 10, ["name"] = "default:junglewood"}, {["x"] = 6, ["meta"] = {["fields"] = {}, ["inventory"] = {}}, ["y"] = 14, ["param1"] = 62, ["z"] = 11, ["name"] = "default:junglewood"}, {["x"] = 6, ["meta"] = {["fields"] = {}, ["inventory"] = {}}, ["y"] = 14, ["param1"] = 62, ["z"] = 12, ["name"] = "default:junglewood"}, {["x"] = 6, ["meta"] = {["fields"] = {}, ["inventory"] = {}}, ["y"] = 14, ["param1"] = 62, ["z"] = 13, ["name"] = "default:junglewood"}, {["x"] = 6, ["meta"] = {["fields"] = {}, ["inventory"] = {}}, ["y"] = 14, ["param1"] = 62, ["z"] = 14, ["name"] = "default:junglewood"}, {["x"] = 6, ["meta"] = {["fields"] = {}, ["inventory"] = {}}, ["y"] = 14, ["param1"] = 62, ["z"] = 15, ["name"] = "default:junglewood"}, {["x"] = 6, ["y"] = 15, ["z"] = 2, ["name"] = "wool:red"}, {["x"] = 6, ["y"] = 15, ["z"] = 3, ["name"] = "wool:red"}, {["x"] = 6, ["y"] = 15, ["z"] = 4, ["name"] = "wool:red"}, {["x"] = 6, ["y"] = 15, ["z"] = 5, ["name"] = "wool:red"}, {["x"] = 6, ["y"] = 15, ["z"] = 6, ["name"] = "wool:red"}, {["x"] = 6, ["y"] = 15, ["z"] = 7, ["name"] = "wool:red"}, {["x"] = 6, ["y"] = 15, ["z"] = 8, ["name"] = "wool:red"}, {["x"] = 6, ["y"] = 15, ["z"] = 9, ["name"] = "wool:red"}, {["x"] = 6, ["y"] = 15, ["z"] = 10, ["name"] = "wool:red"}, {["x"] = 6, ["y"] = 15, ["z"] = 11, ["name"] = "wool:red"}, {["x"] = 6, ["y"] = 15, ["z"] = 12, ["name"] = "wool:red"}, {["x"] = 6, ["y"] = 15, ["z"] = 13, ["name"] = "wool:red"}, {["x"] = 7, ["meta"] = {["fields"] = {}, ["inventory"] = {}}, ["y"] = 12, ["param1"] = 62, ["z"] = 0, ["name"] = "default:junglewood"}, {["x"] = 7, ["meta"] = {["fields"] = {}, ["inventory"] = {}}, ["y"] = 12, ["param1"] = 62, ["z"] = 1, ["name"] = "default:junglewood"}, {["x"] = 7, ["meta"] = {["fields"] = {}, ["inventory"] = {}}, ["y"] = 12, ["param1"] = 62, ["z"] = 2, ["name"] = "default:junglewood"}, {["x"] = 7, ["meta"] = {["fields"] = {}, ["inventory"] = {}}, ["y"] = 12, ["param1"] = 62, ["z"] = 3, ["name"] = "default:junglewood"}, {["x"] = 7, ["meta"] = {["fields"] = {}, ["inventory"] = {}}, ["y"] = 12, ["param1"] = 62, ["z"] = 4, ["name"] = "default:junglewood"}, {["x"] = 7, ["meta"] = {["fields"] = {}, ["inventory"] = {}}, ["y"] = 12, ["param1"] = 62, ["z"] = 5, ["name"] = "default:junglewood"}, {["x"] = 7, ["meta"] = {["fields"] = {}, ["inventory"] = {}}, ["y"] = 12, ["param1"] = 62, ["z"] = 6, ["name"] = "default:junglewood"}, {["x"] = 7, ["meta"] = {["fields"] = {}, ["inventory"] = {}}, ["y"] = 12, ["param1"] = 62, ["z"] = 7, ["name"] = "default:junglewood"}, {["x"] = 7, ["meta"] = {["fields"] = {}, ["inventory"] = {}}, ["y"] = 12, ["param1"] = 62, ["z"] = 8, ["name"] = "default:junglewood"}, {["x"] = 7, ["meta"] = {["fields"] = {}, ["inventory"] = {}}, ["y"] = 12, ["param1"] = 62, ["z"] = 9, ["name"] = "default:junglewood"}, {["x"] = 7, ["meta"] = {["fields"] = {}, ["inventory"] = {}}, ["y"] = 12, ["param1"] = 62, ["z"] = 10, ["name"] = "default:junglewood"}, {["x"] = 7, ["meta"] = {["fields"] = {}, ["inventory"] = {}}, ["y"] = 12, ["param1"] = 62, ["z"] = 11, ["name"] = "default:junglewood"}, {["x"] = 7, ["meta"] = {["fields"] = {}, ["inventory"] = {}}, ["y"] = 12, ["param1"] = 62, ["z"] = 12, ["name"] = "default:junglewood"}, {["x"] = 7, ["meta"] = {["fields"] = {}, ["inventory"] = {}}, ["y"] = 12, ["param1"] = 62, ["z"] = 13, ["name"] = "default:junglewood"}, {["x"] = 7, ["meta"] = {["fields"] = {}, ["inventory"] = {}}, ["y"] = 12, ["param1"] = 62, ["z"] = 14, ["name"] = "default:junglewood"}, {["x"] = 7, ["meta"] = {["fields"] = {}, ["inventory"] = {}}, ["y"] = 12, ["param1"] = 62, ["z"] = 15, ["name"] = "default:junglewood"}, {["x"] = 7, ["meta"] = {["fields"] = {}, ["inventory"] = {}}, ["y"] = 13, ["param1"] = 62, ["z"] = 0, ["name"] = "default:junglewood"}, {["x"] = 7, ["meta"] = {["fields"] = {}, ["inventory"] = {}}, ["y"] = 13, ["param1"] = 62, ["z"] = 1, ["name"] = "default:junglewood"}, {["x"] = 7, ["meta"] = {["fields"] = {}, ["inventory"] = {}}, ["y"] = 13, ["param1"] = 62, ["z"] = 2, ["name"] = "default:junglewood"}, {["x"] = 7, ["meta"] = {["fields"] = {}, ["inventory"] = {}}, ["y"] = 13, ["param1"] = 62, ["z"] = 3, ["name"] = "default:junglewood"}, {["x"] = 7, ["meta"] = {["fields"] = {}, ["inventory"] = {}}, ["y"] = 13, ["param1"] = 62, ["z"] = 4, ["name"] = "default:junglewood"}, {["x"] = 7, ["meta"] = {["fields"] = {}, ["inventory"] = {}}, ["y"] = 13, ["param1"] = 62, ["z"] = 5, ["name"] = "default:junglewood"}, {["x"] = 7, ["meta"] = {["fields"] = {}, ["inventory"] = {}}, ["y"] = 13, ["param1"] = 62, ["z"] = 6, ["name"] = "default:junglewood"}, {["x"] = 7, ["meta"] = {["fields"] = {}, ["inventory"] = {}}, ["y"] = 13, ["param1"] = 62, ["z"] = 7, ["name"] = "default:junglewood"}, {["x"] = 7, ["meta"] = {["fields"] = {}, ["inventory"] = {}}, ["y"] = 13, ["param1"] = 62, ["z"] = 8, ["name"] = "default:junglewood"}, {["x"] = 7, ["meta"] = {["fields"] = {}, ["inventory"] = {}}, ["y"] = 13, ["param1"] = 62, ["z"] = 9, ["name"] = "default:junglewood"}, {["x"] = 7, ["meta"] = {["fields"] = {}, ["inventory"] = {}}, ["y"] = 13, ["param1"] = 62, ["z"] = 10, ["name"] = "default:junglewood"}, {["x"] = 7, ["meta"] = {["fields"] = {}, ["inventory"] = {}}, ["y"] = 13, ["param1"] = 62, ["z"] = 11, ["name"] = "default:junglewood"}, {["x"] = 7, ["meta"] = {["fields"] = {}, ["inventory"] = {}}, ["y"] = 13, ["param1"] = 62, ["z"] = 12, ["name"] = "default:junglewood"}, {["x"] = 7, ["meta"] = {["fields"] = {}, ["inventory"] = {}}, ["y"] = 13, ["param1"] = 62, ["z"] = 13, ["name"] = "default:junglewood"}, {["x"] = 7, ["meta"] = {["fields"] = {}, ["inventory"] = {}}, ["y"] = 13, ["param1"] = 62, ["z"] = 14, ["name"] = "default:junglewood"}, {["x"] = 7, ["meta"] = {["fields"] = {}, ["inventory"] = {}}, ["y"] = 13, ["param1"] = 62, ["z"] = 15, ["name"] = "default:junglewood"}, {["x"] = 7, ["meta"] = {["fields"] = {}, ["inventory"] = {}}, ["y"] = 14, ["param1"] = 62, ["z"] = 0, ["name"] = "default:junglewood"}, {["x"] = 7, ["meta"] = {["fields"] = {}, ["inventory"] = {}}, ["y"] = 14, ["param1"] = 62, ["z"] = 1, ["name"] = "default:junglewood"}, {["x"] = 7, ["meta"] = {["fields"] = {}, ["inventory"] = {}}, ["y"] = 14, ["param1"] = 62, ["z"] = 2, ["name"] = "default:junglewood"}, {["x"] = 7, ["meta"] = {["fields"] = {}, ["inventory"] = {}}, ["y"] = 14, ["param1"] = 62, ["z"] = 3, ["name"] = "default:junglewood"}, {["x"] = 7, ["meta"] = {["fields"] = {}, ["inventory"] = {}}, ["y"] = 14, ["param1"] = 62, ["z"] = 4, ["name"] = "default:junglewood"}, {["x"] = 7, ["meta"] = {["fields"] = {}, ["inventory"] = {}}, ["y"] = 14, ["param1"] = 62, ["z"] = 5, ["name"] = "default:junglewood"}, {["x"] = 7, ["meta"] = {["fields"] = {}, ["inventory"] = {}}, ["y"] = 14, ["param1"] = 62, ["z"] = 6, ["name"] = "default:junglewood"}, {["x"] = 7, ["meta"] = {["fields"] = {}, ["inventory"] = {}}, ["y"] = 14, ["param1"] = 62, ["z"] = 7, ["name"] = "default:junglewood"}, {["x"] = 7, ["meta"] = {["fields"] = {}, ["inventory"] = {}}, ["y"] = 14, ["param1"] = 62, ["z"] = 8, ["name"] = "default:junglewood"}, {["x"] = 7, ["meta"] = {["fields"] = {}, ["inventory"] = {}}, ["y"] = 14, ["param1"] = 62, ["z"] = 9, ["name"] = "default:junglewood"}, {["x"] = 7, ["meta"] = {["fields"] = {}, ["inventory"] = {}}, ["y"] = 14, ["param1"] = 62, ["z"] = 10, ["name"] = "default:junglewood"}, {["x"] = 7, ["meta"] = {["fields"] = {}, ["inventory"] = {}}, ["y"] = 14, ["param1"] = 62, ["z"] = 11, ["name"] = "default:junglewood"}, {["x"] = 7, ["meta"] = {["fields"] = {}, ["inventory"] = {}}, ["y"] = 14, ["param1"] = 62, ["z"] = 12, ["name"] = "default:junglewood"}, {["x"] = 7, ["meta"] = {["fields"] = {}, ["inventory"] = {}}, ["y"] = 14, ["param1"] = 62, ["z"] = 13, ["name"] = "default:junglewood"}, {["x"] = 7, ["meta"] = {["fields"] = {}, ["inventory"] = {}}, ["y"] = 14, ["param1"] = 62, ["z"] = 14, ["name"] = "default:junglewood"}, {["x"] = 7, ["meta"] = {["fields"] = {}, ["inventory"] = {}}, ["y"] = 14, ["param1"] = 62, ["z"] = 15, ["name"] = "default:junglewood"}, {["x"] = 7, ["y"] = 15, ["z"] = 2, ["name"] = "wool:red"}, {["x"] = 7, ["y"] = 15, ["z"] = 3, ["name"] = "wool:red"}, {["x"] = 7, ["y"] = 15, ["z"] = 4, ["name"] = "wool:red"}, {["x"] = 7, ["y"] = 15, ["z"] = 5, ["name"] = "wool:red"}, {["x"] = 7, ["y"] = 15, ["z"] = 6, ["name"] = "wool:red"}, {["x"] = 7, ["y"] = 15, ["z"] = 7, ["name"] = "wool:red"}, {["x"] = 7, ["y"] = 15, ["z"] = 8, ["name"] = "wool:red"}, {["x"] = 7, ["y"] = 15, ["z"] = 9, ["name"] = "wool:red"}, {["x"] = 7, ["y"] = 15, ["z"] = 10, ["name"] = "wool:red"}, {["x"] = 7, ["y"] = 15, ["z"] = 11, ["name"] = "wool:red"}, {["x"] = 7, ["y"] = 15, ["z"] = 12, ["name"] = "wool:red"}, {["x"] = 7, ["y"] = 15, ["z"] = 13, ["name"] = "wool:red"}, {["x"] = 8, ["meta"] = {["fields"] = {}, ["inventory"] = {}}, ["y"] = 12, ["param1"] = 62, ["z"] = 0, ["name"] = "default:junglewood"}, {["x"] = 8, ["meta"] = {["fields"] = {}, ["inventory"] = {}}, ["y"] = 12, ["param1"] = 62, ["z"] = 1, ["name"] = "default:junglewood"}, {["x"] = 8, ["meta"] = {["fields"] = {}, ["inventory"] = {}}, ["y"] = 12, ["param1"] = 62, ["z"] = 2, ["name"] = "default:junglewood"}, {["x"] = 8, ["meta"] = {["fields"] = {}, ["inventory"] = {}}, ["y"] = 12, ["param1"] = 62, ["z"] = 3, ["name"] = "default:junglewood"}, {["x"] = 8, ["meta"] = {["fields"] = {}, ["inventory"] = {}}, ["y"] = 12, ["param1"] = 62, ["z"] = 4, ["name"] = "default:junglewood"}, {["x"] = 8, ["meta"] = {["fields"] = {}, ["inventory"] = {}}, ["y"] = 12, ["param1"] = 62, ["z"] = 5, ["name"] = "default:junglewood"}, {["x"] = 8, ["meta"] = {["fields"] = {}, ["inventory"] = {}}, ["y"] = 12, ["param1"] = 62, ["z"] = 6, ["name"] = "default:junglewood"}, {["x"] = 8, ["meta"] = {["fields"] = {}, ["inventory"] = {}}, ["y"] = 12, ["param1"] = 62, ["z"] = 7, ["name"] = "default:junglewood"}, {["x"] = 8, ["meta"] = {["fields"] = {}, ["inventory"] = {}}, ["y"] = 12, ["param1"] = 62, ["z"] = 8, ["name"] = "default:junglewood"}, {["x"] = 8, ["meta"] = {["fields"] = {}, ["inventory"] = {}}, ["y"] = 12, ["param1"] = 62, ["z"] = 9, ["name"] = "default:junglewood"}, {["x"] = 8, ["meta"] = {["fields"] = {}, ["inventory"] = {}}, ["y"] = 12, ["param1"] = 62, ["z"] = 10, ["name"] = "default:junglewood"}, {["x"] = 8, ["meta"] = {["fields"] = {}, ["inventory"] = {}}, ["y"] = 12, ["param1"] = 62, ["z"] = 11, ["name"] = "default:junglewood"}, {["x"] = 8, ["meta"] = {["fields"] = {}, ["inventory"] = {}}, ["y"] = 12, ["param1"] = 62, ["z"] = 12, ["name"] = "default:junglewood"}, {["x"] = 8, ["meta"] = {["fields"] = {}, ["inventory"] = {}}, ["y"] = 12, ["param1"] = 62, ["z"] = 13, ["name"] = "default:junglewood"}, {["x"] = 8, ["meta"] = {["fields"] = {}, ["inventory"] = {}}, ["y"] = 12, ["param1"] = 62, ["z"] = 14, ["name"] = "default:junglewood"}, {["x"] = 8, ["meta"] = {["fields"] = {}, ["inventory"] = {}}, ["y"] = 12, ["param1"] = 62, ["z"] = 15, ["name"] = "default:junglewood"}, {["x"] = 8, ["meta"] = {["fields"] = {}, ["inventory"] = {}}, ["y"] = 13, ["param1"] = 62, ["z"] = 0, ["name"] = "default:junglewood"}, {["x"] = 8, ["meta"] = {["fields"] = {}, ["inventory"] = {}}, ["y"] = 13, ["param1"] = 62, ["z"] = 1, ["name"] = "default:junglewood"}, {["x"] = 8, ["meta"] = {["fields"] = {}, ["inventory"] = {}}, ["y"] = 13, ["param1"] = 62, ["z"] = 2, ["name"] = "default:junglewood"}, {["x"] = 8, ["meta"] = {["fields"] = {}, ["inventory"] = {}}, ["y"] = 13, ["param1"] = 62, ["z"] = 3, ["name"] = "default:junglewood"}, {["x"] = 8, ["meta"] = {["fields"] = {}, ["inventory"] = {}}, ["y"] = 13, ["param1"] = 62, ["z"] = 4, ["name"] = "default:junglewood"}, {["x"] = 8, ["meta"] = {["fields"] = {}, ["inventory"] = {}}, ["y"] = 13, ["param1"] = 62, ["z"] = 5, ["name"] = "default:junglewood"}, {["x"] = 8, ["meta"] = {["fields"] = {}, ["inventory"] = {}}, ["y"] = 13, ["param1"] = 62, ["z"] = 6, ["name"] = "default:junglewood"}, {["x"] = 8, ["meta"] = {["fields"] = {}, ["inventory"] = {}}, ["y"] = 13, ["param1"] = 62, ["z"] = 7, ["name"] = "default:junglewood"}, {["x"] = 8, ["meta"] = {["fields"] = {}, ["inventory"] = {}}, ["y"] = 13, ["param1"] = 62, ["z"] = 8, ["name"] = "default:junglewood"}, {["x"] = 8, ["meta"] = {["fields"] = {}, ["inventory"] = {}}, ["y"] = 13, ["param1"] = 62, ["z"] = 9, ["name"] = "default:junglewood"}, {["x"] = 8, ["meta"] = {["fields"] = {}, ["inventory"] = {}}, ["y"] = 13, ["param1"] = 62, ["z"] = 10, ["name"] = "default:junglewood"}, {["x"] = 8, ["meta"] = {["fields"] = {}, ["inventory"] = {}}, ["y"] = 13, ["param1"] = 62, ["z"] = 11, ["name"] = "default:junglewood"}, {["x"] = 8, ["meta"] = {["fields"] = {}, ["inventory"] = {}}, ["y"] = 13, ["param1"] = 62, ["z"] = 12, ["name"] = "default:junglewood"}, {["x"] = 8, ["meta"] = {["fields"] = {}, ["inventory"] = {}}, ["y"] = 13, ["param1"] = 62, ["z"] = 13, ["name"] = "default:junglewood"}, {["x"] = 8, ["meta"] = {["fields"] = {}, ["inventory"] = {}}, ["y"] = 13, ["param1"] = 62, ["z"] = 14, ["name"] = "default:junglewood"}, {["x"] = 8, ["meta"] = {["fields"] = {}, ["inventory"] = {}}, ["y"] = 13, ["param1"] = 62, ["z"] = 15, ["name"] = "default:junglewood"}, {["x"] = 8, ["meta"] = {["fields"] = {}, ["inventory"] = {}}, ["y"] = 14, ["param1"] = 62, ["z"] = 0, ["name"] = "default:junglewood"}, {["x"] = 8, ["meta"] = {["fields"] = {}, ["inventory"] = {}}, ["y"] = 14, ["param1"] = 62, ["z"] = 1, ["name"] = "default:junglewood"}, {["x"] = 8, ["meta"] = {["fields"] = {}, ["inventory"] = {}}, ["y"] = 14, ["param1"] = 62, ["z"] = 2, ["name"] = "default:junglewood"}, {["x"] = 8, ["meta"] = {["fields"] = {}, ["inventory"] = {}}, ["y"] = 14, ["param1"] = 62, ["z"] = 3, ["name"] = "default:junglewood"}, {["x"] = 8, ["meta"] = {["fields"] = {}, ["inventory"] = {}}, ["y"] = 14, ["param1"] = 62, ["z"] = 4, ["name"] = "default:junglewood"}, {["x"] = 8, ["meta"] = {["fields"] = {}, ["inventory"] = {}}, ["y"] = 14, ["param1"] = 62, ["z"] = 5, ["name"] = "default:junglewood"}, {["x"] = 8, ["meta"] = {["fields"] = {}, ["inventory"] = {}}, ["y"] = 14, ["param1"] = 62, ["z"] = 6, ["name"] = "default:junglewood"}, {["x"] = 8, ["meta"] = {["fields"] = {}, ["inventory"] = {}}, ["y"] = 14, ["param1"] = 62, ["z"] = 7, ["name"] = "default:junglewood"}, {["x"] = 8, ["meta"] = {["fields"] = {}, ["inventory"] = {}}, ["y"] = 14, ["param1"] = 62, ["z"] = 8, ["name"] = "default:junglewood"}, {["x"] = 8, ["meta"] = {["fields"] = {}, ["inventory"] = {}}, ["y"] = 14, ["param1"] = 62, ["z"] = 9, ["name"] = "default:junglewood"}, {["x"] = 8, ["meta"] = {["fields"] = {}, ["inventory"] = {}}, ["y"] = 14, ["param1"] = 62, ["z"] = 10, ["name"] = "default:junglewood"}, {["x"] = 8, ["meta"] = {["fields"] = {}, ["inventory"] = {}}, ["y"] = 14, ["param1"] = 62, ["z"] = 11, ["name"] = "default:junglewood"}, {["x"] = 8, ["meta"] = {["fields"] = {}, ["inventory"] = {}}, ["y"] = 14, ["param1"] = 62, ["z"] = 12, ["name"] = "default:junglewood"}, {["x"] = 8, ["meta"] = {["fields"] = {}, ["inventory"] = {}}, ["y"] = 14, ["param1"] = 62, ["z"] = 13, ["name"] = "default:junglewood"}, {["x"] = 8, ["meta"] = {["fields"] = {}, ["inventory"] = {}}, ["y"] = 14, ["param1"] = 62, ["z"] = 14, ["name"] = "default:junglewood"}, {["x"] = 8, ["meta"] = {["fields"] = {}, ["inventory"] = {}}, ["y"] = 14, ["param1"] = 62, ["z"] = 15, ["name"] = "default:junglewood"}, {["x"] = 8, ["y"] = 15, ["z"] = 2, ["name"] = "wool:red"}, {["x"] = 8, ["y"] = 15, ["z"] = 3, ["name"] = "wool:red"}, {["x"] = 8, ["y"] = 15, ["z"] = 4, ["name"] = "wool:red"}, {["x"] = 8, ["y"] = 15, ["z"] = 5, ["name"] = "wool:red"}, {["x"] = 8, ["y"] = 15, ["z"] = 6, ["name"] = "wool:red"}, {["x"] = 8, ["y"] = 15, ["z"] = 7, ["name"] = "wool:red"}, {["x"] = 8, ["y"] = 15, ["z"] = 8, ["name"] = "wool:red"}, {["x"] = 8, ["y"] = 15, ["z"] = 9, ["name"] = "wool:red"}, {["x"] = 8, ["y"] = 15, ["z"] = 10, ["name"] = "wool:red"}, {["x"] = 8, ["y"] = 15, ["z"] = 11, ["name"] = "wool:red"}, {["x"] = 8, ["y"] = 15, ["z"] = 12, ["name"] = "wool:red"}, {["x"] = 8, ["y"] = 15, ["z"] = 13, ["name"] = "wool:red"}, {["x"] = 9, ["meta"] = {["fields"] = {}, ["inventory"] = {}}, ["y"] = 12, ["param1"] = 62, ["z"] = 0, ["name"] = "default:junglewood"}, {["x"] = 9, ["meta"] = {["fields"] = {}, ["inventory"] = {}}, ["y"] = 12, ["param1"] = 62, ["z"] = 1, ["name"] = "default:junglewood"}, {["x"] = 9, ["meta"] = {["fields"] = {}, ["inventory"] = {}}, ["y"] = 12, ["param1"] = 62, ["z"] = 2, ["name"] = "default:junglewood"}, {["x"] = 9, ["meta"] = {["fields"] = {}, ["inventory"] = {}}, ["y"] = 12, ["param1"] = 62, ["z"] = 3, ["name"] = "default:junglewood"}, {["x"] = 9, ["meta"] = {["fields"] = {}, ["inventory"] = {}}, ["y"] = 12, ["param1"] = 62, ["z"] = 4, ["name"] = "default:junglewood"}, {["x"] = 9, ["meta"] = {["fields"] = {}, ["inventory"] = {}}, ["y"] = 12, ["param1"] = 62, ["z"] = 5, ["name"] = "default:junglewood"}, {["x"] = 9, ["meta"] = {["fields"] = {}, ["inventory"] = {}}, ["y"] = 12, ["param1"] = 62, ["z"] = 6, ["name"] = "default:junglewood"}, {["x"] = 9, ["meta"] = {["fields"] = {}, ["inventory"] = {}}, ["y"] = 12, ["param1"] = 62, ["z"] = 7, ["name"] = "default:junglewood"}, {["x"] = 9, ["meta"] = {["fields"] = {}, ["inventory"] = {}}, ["y"] = 12, ["param1"] = 62, ["z"] = 8, ["name"] = "default:junglewood"}, {["x"] = 9, ["meta"] = {["fields"] = {}, ["inventory"] = {}}, ["y"] = 12, ["param1"] = 62, ["z"] = 9, ["name"] = "default:junglewood"}, {["x"] = 9, ["meta"] = {["fields"] = {}, ["inventory"] = {}}, ["y"] = 12, ["param1"] = 62, ["z"] = 10, ["name"] = "default:junglewood"}, {["x"] = 9, ["meta"] = {["fields"] = {}, ["inventory"] = {}}, ["y"] = 12, ["param1"] = 62, ["z"] = 11, ["name"] = "default:junglewood"}, {["x"] = 9, ["meta"] = {["fields"] = {}, ["inventory"] = {}}, ["y"] = 12, ["param1"] = 62, ["z"] = 12, ["name"] = "default:junglewood"}, {["x"] = 9, ["meta"] = {["fields"] = {}, ["inventory"] = {}}, ["y"] = 12, ["param1"] = 62, ["z"] = 13, ["name"] = "default:junglewood"}, {["x"] = 9, ["meta"] = {["fields"] = {}, ["inventory"] = {}}, ["y"] = 12, ["param1"] = 62, ["z"] = 14, ["name"] = "default:junglewood"}, {["x"] = 9, ["meta"] = {["fields"] = {}, ["inventory"] = {}}, ["y"] = 12, ["param1"] = 62, ["z"] = 15, ["name"] = "default:junglewood"}, {["x"] = 9, ["meta"] = {["fields"] = {}, ["inventory"] = {}}, ["y"] = 13, ["param1"] = 62, ["z"] = 0, ["name"] = "default:junglewood"}, {["x"] = 9, ["meta"] = {["fields"] = {}, ["inventory"] = {}}, ["y"] = 13, ["param1"] = 62, ["z"] = 1, ["name"] = "default:junglewood"}, {["x"] = 9, ["meta"] = {["fields"] = {}, ["inventory"] = {}}, ["y"] = 13, ["param1"] = 62, ["z"] = 2, ["name"] = "default:junglewood"}, {["x"] = 9, ["meta"] = {["fields"] = {}, ["inventory"] = {}}, ["y"] = 13, ["param1"] = 62, ["z"] = 3, ["name"] = "default:junglewood"}, {["x"] = 9, ["meta"] = {["fields"] = {}, ["inventory"] = {}}, ["y"] = 13, ["param1"] = 62, ["z"] = 4, ["name"] = "default:junglewood"}, {["x"] = 9, ["meta"] = {["fields"] = {}, ["inventory"] = {}}, ["y"] = 13, ["param1"] = 62, ["z"] = 5, ["name"] = "default:junglewood"}, {["x"] = 9, ["meta"] = {["fields"] = {}, ["inventory"] = {}}, ["y"] = 13, ["param1"] = 62, ["z"] = 6, ["name"] = "default:junglewood"}, {["x"] = 9, ["meta"] = {["fields"] = {}, ["inventory"] = {}}, ["y"] = 13, ["param1"] = 62, ["z"] = 7, ["name"] = "default:junglewood"}, {["x"] = 9, ["meta"] = {["fields"] = {}, ["inventory"] = {}}, ["y"] = 13, ["param1"] = 62, ["z"] = 8, ["name"] = "default:junglewood"}, {["x"] = 9, ["meta"] = {["fields"] = {}, ["inventory"] = {}}, ["y"] = 13, ["param1"] = 62, ["z"] = 9, ["name"] = "default:junglewood"}, {["x"] = 9, ["meta"] = {["fields"] = {}, ["inventory"] = {}}, ["y"] = 13, ["param1"] = 62, ["z"] = 10, ["name"] = "default:junglewood"}, {["x"] = 9, ["meta"] = {["fields"] = {}, ["inventory"] = {}}, ["y"] = 13, ["param1"] = 62, ["z"] = 11, ["name"] = "default:junglewood"}, {["x"] = 9, ["meta"] = {["fields"] = {}, ["inventory"] = {}}, ["y"] = 13, ["param1"] = 62, ["z"] = 12, ["name"] = "default:junglewood"}, {["x"] = 9, ["meta"] = {["fields"] = {}, ["inventory"] = {}}, ["y"] = 13, ["param1"] = 62, ["z"] = 13, ["name"] = "default:junglewood"}, {["x"] = 9, ["meta"] = {["fields"] = {}, ["inventory"] = {}}, ["y"] = 13, ["param1"] = 62, ["z"] = 14, ["name"] = "default:junglewood"}, {["x"] = 9, ["meta"] = {["fields"] = {}, ["inventory"] = {}}, ["y"] = 13, ["param1"] = 62, ["z"] = 15, ["name"] = "default:junglewood"}, {["x"] = 9, ["meta"] = {["fields"] = {}, ["inventory"] = {}}, ["y"] = 14, ["param1"] = 62, ["z"] = 0, ["name"] = "default:junglewood"}, {["x"] = 9, ["meta"] = {["fields"] = {}, ["inventory"] = {}}, ["y"] = 14, ["param1"] = 62, ["z"] = 1, ["name"] = "default:junglewood"}, {["x"] = 9, ["meta"] = {["fields"] = {}, ["inventory"] = {}}, ["y"] = 14, ["param1"] = 62, ["z"] = 2, ["name"] = "default:junglewood"}, {["x"] = 9, ["meta"] = {["fields"] = {}, ["inventory"] = {}}, ["y"] = 14, ["param1"] = 62, ["z"] = 3, ["name"] = "default:junglewood"}, {["x"] = 9, ["meta"] = {["fields"] = {}, ["inventory"] = {}}, ["y"] = 14, ["param1"] = 62, ["z"] = 4, ["name"] = "default:junglewood"}, {["x"] = 9, ["meta"] = {["fields"] = {}, ["inventory"] = {}}, ["y"] = 14, ["param1"] = 62, ["z"] = 5, ["name"] = "default:junglewood"}, {["x"] = 9, ["meta"] = {["fields"] = {}, ["inventory"] = {}}, ["y"] = 14, ["param1"] = 62, ["z"] = 6, ["name"] = "default:junglewood"}, {["x"] = 9, ["meta"] = {["fields"] = {}, ["inventory"] = {}}, ["y"] = 14, ["param1"] = 62, ["z"] = 7, ["name"] = "default:junglewood"}, {["x"] = 9, ["meta"] = {["fields"] = {}, ["inventory"] = {}}, ["y"] = 14, ["param1"] = 62, ["z"] = 8, ["name"] = "default:junglewood"}, {["x"] = 9, ["meta"] = {["fields"] = {}, ["inventory"] = {}}, ["y"] = 14, ["param1"] = 62, ["z"] = 9, ["name"] = "default:junglewood"}, {["x"] = 9, ["meta"] = {["fields"] = {}, ["inventory"] = {}}, ["y"] = 14, ["param1"] = 62, ["z"] = 10, ["name"] = "default:junglewood"}, {["x"] = 9, ["meta"] = {["fields"] = {}, ["inventory"] = {}}, ["y"] = 14, ["param1"] = 62, ["z"] = 11, ["name"] = "default:junglewood"}, {["x"] = 9, ["meta"] = {["fields"] = {}, ["inventory"] = {}}, ["y"] = 14, ["param1"] = 62, ["z"] = 12, ["name"] = "default:junglewood"}, {["x"] = 9, ["meta"] = {["fields"] = {}, ["inventory"] = {}}, ["y"] = 14, ["param1"] = 62, ["z"] = 13, ["name"] = "default:junglewood"}, {["x"] = 9, ["meta"] = {["fields"] = {}, ["inventory"] = {}}, ["y"] = 14, ["param1"] = 62, ["z"] = 14, ["name"] = "default:junglewood"}, {["x"] = 9, ["meta"] = {["fields"] = {}, ["inventory"] = {}}, ["y"] = 14, ["param1"] = 62, ["z"] = 15, ["name"] = "default:junglewood"}, {["x"] = 10, ["meta"] = {["fields"] = {}, ["inventory"] = {}}, ["y"] = 12, ["param1"] = 62, ["z"] = 0, ["name"] = "default:junglewood"}, {["x"] = 10, ["meta"] = {["fields"] = {}, ["inventory"] = {}}, ["y"] = 12, ["param1"] = 62, ["z"] = 1, ["name"] = "default:junglewood"}, {["x"] = 10, ["meta"] = {["fields"] = {}, ["inventory"] = {}}, ["y"] = 12, ["param1"] = 62, ["z"] = 2, ["name"] = "default:junglewood"}, {["x"] = 10, ["meta"] = {["fields"] = {}, ["inventory"] = {}}, ["y"] = 12, ["param1"] = 62, ["z"] = 3, ["name"] = "default:junglewood"}, {["x"] = 10, ["meta"] = {["fields"] = {}, ["inventory"] = {}}, ["y"] = 12, ["param1"] = 62, ["z"] = 4, ["name"] = "default:junglewood"}, {["x"] = 10, ["meta"] = {["fields"] = {}, ["inventory"] = {}}, ["y"] = 12, ["param1"] = 62, ["z"] = 5, ["name"] = "default:junglewood"}, {["x"] = 10, ["meta"] = {["fields"] = {}, ["inventory"] = {}}, ["y"] = 12, ["param1"] = 62, ["z"] = 6, ["name"] = "default:junglewood"}, {["x"] = 10, ["meta"] = {["fields"] = {}, ["inventory"] = {}}, ["y"] = 12, ["param1"] = 62, ["z"] = 7, ["name"] = "default:junglewood"}, {["x"] = 10, ["meta"] = {["fields"] = {}, ["inventory"] = {}}, ["y"] = 12, ["param1"] = 62, ["z"] = 8, ["name"] = "default:junglewood"}, {["x"] = 10, ["meta"] = {["fields"] = {}, ["inventory"] = {}}, ["y"] = 12, ["param1"] = 62, ["z"] = 9, ["name"] = "default:junglewood"}, {["x"] = 10, ["meta"] = {["fields"] = {}, ["inventory"] = {}}, ["y"] = 12, ["param1"] = 62, ["z"] = 10, ["name"] = "default:junglewood"}, {["x"] = 10, ["meta"] = {["fields"] = {}, ["inventory"] = {}}, ["y"] = 12, ["param1"] = 62, ["z"] = 11, ["name"] = "default:junglewood"}, {["x"] = 10, ["meta"] = {["fields"] = {}, ["inventory"] = {}}, ["y"] = 12, ["param1"] = 62, ["z"] = 12, ["name"] = "default:junglewood"}, {["x"] = 10, ["meta"] = {["fields"] = {}, ["inventory"] = {}}, ["y"] = 12, ["param1"] = 62, ["z"] = 13, ["name"] = "default:junglewood"}, {["x"] = 10, ["meta"] = {["fields"] = {}, ["inventory"] = {}}, ["y"] = 12, ["param1"] = 62, ["z"] = 14, ["name"] = "default:junglewood"}, {["x"] = 10, ["meta"] = {["fields"] = {}, ["inventory"] = {}}, ["y"] = 12, ["param1"] = 62, ["z"] = 15, ["name"] = "default:junglewood"}, {["x"] = 10, ["meta"] = {["fields"] = {}, ["inventory"] = {}}, ["y"] = 13, ["param1"] = 62, ["z"] = 0, ["name"] = "default:junglewood"}, {["x"] = 10, ["meta"] = {["fields"] = {}, ["inventory"] = {}}, ["y"] = 13, ["param1"] = 62, ["z"] = 1, ["name"] = "default:junglewood"}, {["x"] = 10, ["meta"] = {["fields"] = {}, ["inventory"] = {}}, ["y"] = 13, ["param1"] = 62, ["z"] = 2, ["name"] = "default:junglewood"}, {["x"] = 10, ["meta"] = {["fields"] = {}, ["inventory"] = {}}, ["y"] = 13, ["param1"] = 62, ["z"] = 3, ["name"] = "default:junglewood"}, {["x"] = 10, ["meta"] = {["fields"] = {}, ["inventory"] = {}}, ["y"] = 13, ["param1"] = 62, ["z"] = 4, ["name"] = "default:junglewood"}, {["x"] = 10, ["meta"] = {["fields"] = {}, ["inventory"] = {}}, ["y"] = 13, ["param1"] = 62, ["z"] = 5, ["name"] = "default:junglewood"}, {["x"] = 10, ["meta"] = {["fields"] = {}, ["inventory"] = {}}, ["y"] = 13, ["param1"] = 62, ["z"] = 6, ["name"] = "default:junglewood"}, {["x"] = 10, ["meta"] = {["fields"] = {}, ["inventory"] = {}}, ["y"] = 13, ["param1"] = 62, ["z"] = 7, ["name"] = "default:junglewood"}, {["x"] = 10, ["meta"] = {["fields"] = {}, ["inventory"] = {}}, ["y"] = 13, ["param1"] = 62, ["z"] = 8, ["name"] = "default:junglewood"}, {["x"] = 10, ["meta"] = {["fields"] = {}, ["inventory"] = {}}, ["y"] = 13, ["param1"] = 62, ["z"] = 9, ["name"] = "default:junglewood"}, {["x"] = 10, ["meta"] = {["fields"] = {}, ["inventory"] = {}}, ["y"] = 13, ["param1"] = 62, ["z"] = 10, ["name"] = "default:junglewood"}, {["x"] = 10, ["meta"] = {["fields"] = {}, ["inventory"] = {}}, ["y"] = 13, ["param1"] = 62, ["z"] = 11, ["name"] = "default:junglewood"}, {["x"] = 10, ["meta"] = {["fields"] = {}, ["inventory"] = {}}, ["y"] = 13, ["param1"] = 62, ["z"] = 12, ["name"] = "default:junglewood"}, {["x"] = 10, ["meta"] = {["fields"] = {}, ["inventory"] = {}}, ["y"] = 13, ["param1"] = 62, ["z"] = 13, ["name"] = "default:junglewood"}, {["x"] = 10, ["meta"] = {["fields"] = {}, ["inventory"] = {}}, ["y"] = 13, ["param1"] = 62, ["z"] = 14, ["name"] = "default:junglewood"}, {["x"] = 10, ["meta"] = {["fields"] = {}, ["inventory"] = {}}, ["y"] = 13, ["param1"] = 62, ["z"] = 15, ["name"] = "default:junglewood"}, {["x"] = 10, ["meta"] = {["fields"] = {}, ["inventory"] = {}}, ["y"] = 14, ["param1"] = 62, ["z"] = 0, ["name"] = "default:junglewood"}, {["x"] = 10, ["meta"] = {["fields"] = {}, ["inventory"] = {}}, ["y"] = 14, ["param1"] = 62, ["z"] = 1, ["name"] = "default:junglewood"}, {["x"] = 10, ["meta"] = {["fields"] = {}, ["inventory"] = {}}, ["y"] = 14, ["param1"] = 62, ["z"] = 2, ["name"] = "default:junglewood"}, {["x"] = 10, ["meta"] = {["fields"] = {}, ["inventory"] = {}}, ["y"] = 14, ["param1"] = 62, ["z"] = 3, ["name"] = "default:junglewood"}, {["x"] = 10, ["meta"] = {["fields"] = {}, ["inventory"] = {}}, ["y"] = 14, ["param1"] = 62, ["z"] = 4, ["name"] = "default:junglewood"}, {["x"] = 10, ["meta"] = {["fields"] = {}, ["inventory"] = {}}, ["y"] = 14, ["param1"] = 62, ["z"] = 5, ["name"] = "default:junglewood"}, {["x"] = 10, ["meta"] = {["fields"] = {}, ["inventory"] = {}}, ["y"] = 14, ["param1"] = 62, ["z"] = 6, ["name"] = "default:junglewood"}, {["x"] = 10, ["meta"] = {["fields"] = {}, ["inventory"] = {}}, ["y"] = 14, ["param1"] = 62, ["z"] = 7, ["name"] = "default:junglewood"}, {["x"] = 10, ["meta"] = {["fields"] = {}, ["inventory"] = {}}, ["y"] = 14, ["param1"] = 62, ["z"] = 8, ["name"] = "default:junglewood"}, {["x"] = 10, ["meta"] = {["fields"] = {}, ["inventory"] = {}}, ["y"] = 14, ["param1"] = 62, ["z"] = 9, ["name"] = "default:junglewood"}, {["x"] = 10, ["meta"] = {["fields"] = {}, ["inventory"] = {}}, ["y"] = 14, ["param1"] = 62, ["z"] = 10, ["name"] = "default:junglewood"}, {["x"] = 10, ["meta"] = {["fields"] = {}, ["inventory"] = {}}, ["y"] = 14, ["param1"] = 62, ["z"] = 11, ["name"] = "default:junglewood"}, {["x"] = 10, ["meta"] = {["fields"] = {}, ["inventory"] = {}}, ["y"] = 14, ["param1"] = 62, ["z"] = 12, ["name"] = "default:junglewood"}, {["x"] = 10, ["meta"] = {["fields"] = {}, ["inventory"] = {}}, ["y"] = 14, ["param1"] = 62, ["z"] = 13, ["name"] = "default:junglewood"}, {["x"] = 10, ["meta"] = {["fields"] = {}, ["inventory"] = {}}, ["y"] = 14, ["param1"] = 62, ["z"] = 14, ["name"] = "default:junglewood"}, {["x"] = 10, ["meta"] = {["fields"] = {}, ["inventory"] = {}}, ["y"] = 14, ["param1"] = 62, ["z"] = 15, ["name"] = "default:junglewood"}, {["x"] = 11, ["meta"] = {["fields"] = {}, ["inventory"] = {}}, ["y"] = 12, ["param1"] = 62, ["z"] = 0, ["name"] = "default:junglewood"}, {["x"] = 11, ["meta"] = {["fields"] = {}, ["inventory"] = {}}, ["y"] = 12, ["param1"] = 62, ["z"] = 1, ["name"] = "default:junglewood"}, {["x"] = 11, ["meta"] = {["fields"] = {}, ["inventory"] = {}}, ["y"] = 12, ["param1"] = 62, ["z"] = 2, ["name"] = "default:junglewood"}, {["x"] = 11, ["meta"] = {["fields"] = {}, ["inventory"] = {}}, ["y"] = 12, ["param1"] = 62, ["z"] = 3, ["name"] = "default:junglewood"}, {["x"] = 11, ["meta"] = {["fields"] = {}, ["inventory"] = {}}, ["y"] = 12, ["param1"] = 62, ["z"] = 4, ["name"] = "default:junglewood"}, {["x"] = 11, ["meta"] = {["fields"] = {}, ["inventory"] = {}}, ["y"] = 12, ["param1"] = 62, ["z"] = 5, ["name"] = "default:junglewood"}, {["x"] = 11, ["meta"] = {["fields"] = {}, ["inventory"] = {}}, ["y"] = 12, ["param1"] = 62, ["z"] = 6, ["name"] = "default:junglewood"}, {["x"] = 11, ["meta"] = {["fields"] = {}, ["inventory"] = {}}, ["y"] = 12, ["param1"] = 62, ["z"] = 7, ["name"] = "default:junglewood"}, {["x"] = 11, ["meta"] = {["fields"] = {}, ["inventory"] = {}}, ["y"] = 12, ["param1"] = 62, ["z"] = 8, ["name"] = "default:junglewood"}, {["x"] = 11, ["meta"] = {["fields"] = {}, ["inventory"] = {}}, ["y"] = 12, ["param1"] = 62, ["z"] = 9, ["name"] = "default:junglewood"}, {["x"] = 11, ["meta"] = {["fields"] = {}, ["inventory"] = {}}, ["y"] = 12, ["param1"] = 62, ["z"] = 10, ["name"] = "default:junglewood"}, {["x"] = 11, ["meta"] = {["fields"] = {}, ["inventory"] = {}}, ["y"] = 12, ["param1"] = 62, ["z"] = 11, ["name"] = "default:junglewood"}, {["x"] = 11, ["meta"] = {["fields"] = {}, ["inventory"] = {}}, ["y"] = 12, ["param1"] = 62, ["z"] = 12, ["name"] = "default:junglewood"}, {["x"] = 11, ["meta"] = {["fields"] = {}, ["inventory"] = {}}, ["y"] = 12, ["param1"] = 62, ["z"] = 13, ["name"] = "default:junglewood"}, {["x"] = 11, ["meta"] = {["fields"] = {}, ["inventory"] = {}}, ["y"] = 12, ["param1"] = 62, ["z"] = 14, ["name"] = "default:junglewood"}, {["x"] = 11, ["meta"] = {["fields"] = {}, ["inventory"] = {}}, ["y"] = 12, ["param1"] = 62, ["z"] = 15, ["name"] = "default:junglewood"}, {["x"] = 11, ["meta"] = {["fields"] = {}, ["inventory"] = {}}, ["y"] = 13, ["param1"] = 62, ["z"] = 0, ["name"] = "default:junglewood"}, {["x"] = 11, ["meta"] = {["fields"] = {}, ["inventory"] = {}}, ["y"] = 13, ["param1"] = 62, ["z"] = 1, ["name"] = "default:junglewood"}, {["x"] = 11, ["meta"] = {["fields"] = {}, ["inventory"] = {}}, ["y"] = 13, ["param1"] = 62, ["z"] = 2, ["name"] = "default:junglewood"}, {["x"] = 11, ["meta"] = {["fields"] = {}, ["inventory"] = {}}, ["y"] = 13, ["param1"] = 62, ["z"] = 3, ["name"] = "default:junglewood"}, {["x"] = 11, ["meta"] = {["fields"] = {}, ["inventory"] = {}}, ["y"] = 13, ["param1"] = 62, ["z"] = 4, ["name"] = "default:junglewood"}, {["x"] = 11, ["meta"] = {["fields"] = {}, ["inventory"] = {}}, ["y"] = 13, ["param1"] = 62, ["z"] = 5, ["name"] = "default:junglewood"}, {["x"] = 11, ["meta"] = {["fields"] = {}, ["inventory"] = {}}, ["y"] = 13, ["param1"] = 62, ["z"] = 6, ["name"] = "default:junglewood"}, {["x"] = 11, ["meta"] = {["fields"] = {}, ["inventory"] = {}}, ["y"] = 13, ["param1"] = 62, ["z"] = 7, ["name"] = "default:junglewood"}, {["x"] = 11, ["meta"] = {["fields"] = {}, ["inventory"] = {}}, ["y"] = 13, ["param1"] = 62, ["z"] = 8, ["name"] = "default:junglewood"}, {["x"] = 11, ["meta"] = {["fields"] = {}, ["inventory"] = {}}, ["y"] = 13, ["param1"] = 62, ["z"] = 9, ["name"] = "default:junglewood"}, {["x"] = 11, ["meta"] = {["fields"] = {}, ["inventory"] = {}}, ["y"] = 13, ["param1"] = 62, ["z"] = 10, ["name"] = "default:junglewood"}, {["x"] = 11, ["meta"] = {["fields"] = {}, ["inventory"] = {}}, ["y"] = 13, ["param1"] = 62, ["z"] = 11, ["name"] = "default:junglewood"}, {["x"] = 11, ["meta"] = {["fields"] = {}, ["inventory"] = {}}, ["y"] = 13, ["param1"] = 62, ["z"] = 12, ["name"] = "default:junglewood"}, {["x"] = 11, ["meta"] = {["fields"] = {}, ["inventory"] = {}}, ["y"] = 13, ["param1"] = 62, ["z"] = 13, ["name"] = "default:junglewood"}, {["x"] = 11, ["meta"] = {["fields"] = {}, ["inventory"] = {}}, ["y"] = 13, ["param1"] = 62, ["z"] = 14, ["name"] = "default:junglewood"}, {["x"] = 11, ["meta"] = {["fields"] = {}, ["inventory"] = {}}, ["y"] = 13, ["param1"] = 62, ["z"] = 15, ["name"] = "default:junglewood"}, {["x"] = 11, ["meta"] = {["fields"] = {}, ["inventory"] = {}}, ["y"] = 14, ["param1"] = 62, ["z"] = 0, ["name"] = "default:junglewood"}, {["x"] = 11, ["meta"] = {["fields"] = {}, ["inventory"] = {}}, ["y"] = 14, ["param1"] = 62, ["z"] = 1, ["name"] = "default:junglewood"}, {["x"] = 11, ["meta"] = {["fields"] = {}, ["inventory"] = {}}, ["y"] = 14, ["param1"] = 62, ["z"] = 2, ["name"] = "default:junglewood"}, {["x"] = 11, ["meta"] = {["fields"] = {}, ["inventory"] = {}}, ["y"] = 14, ["param1"] = 62, ["z"] = 3, ["name"] = "default:junglewood"}, {["x"] = 11, ["meta"] = {["fields"] = {}, ["inventory"] = {}}, ["y"] = 14, ["param1"] = 62, ["z"] = 4, ["name"] = "default:junglewood"}, {["x"] = 11, ["meta"] = {["fields"] = {}, ["inventory"] = {}}, ["y"] = 14, ["param1"] = 62, ["z"] = 5, ["name"] = "default:junglewood"}, {["x"] = 11, ["meta"] = {["fields"] = {}, ["inventory"] = {}}, ["y"] = 14, ["param1"] = 62, ["z"] = 6, ["name"] = "default:junglewood"}, {["x"] = 11, ["meta"] = {["fields"] = {}, ["inventory"] = {}}, ["y"] = 14, ["param1"] = 62, ["z"] = 7, ["name"] = "default:junglewood"}, {["x"] = 11, ["meta"] = {["fields"] = {}, ["inventory"] = {}}, ["y"] = 14, ["param1"] = 62, ["z"] = 8, ["name"] = "default:junglewood"}, {["x"] = 11, ["meta"] = {["fields"] = {}, ["inventory"] = {}}, ["y"] = 14, ["param1"] = 62, ["z"] = 9, ["name"] = "default:junglewood"}, {["x"] = 11, ["meta"] = {["fields"] = {}, ["inventory"] = {}}, ["y"] = 14, ["param1"] = 62, ["z"] = 10, ["name"] = "default:junglewood"}, {["x"] = 11, ["meta"] = {["fields"] = {}, ["inventory"] = {}}, ["y"] = 14, ["param1"] = 62, ["z"] = 11, ["name"] = "default:junglewood"}, {["x"] = 11, ["meta"] = {["fields"] = {}, ["inventory"] = {}}, ["y"] = 14, ["param1"] = 62, ["z"] = 12, ["name"] = "default:junglewood"}, {["x"] = 11, ["meta"] = {["fields"] = {}, ["inventory"] = {}}, ["y"] = 14, ["param1"] = 62, ["z"] = 13, ["name"] = "default:junglewood"}, {["x"] = 11, ["meta"] = {["fields"] = {}, ["inventory"] = {}}, ["y"] = 14, ["param1"] = 62, ["z"] = 14, ["name"] = "default:junglewood"}, {["x"] = 11, ["meta"] = {["fields"] = {}, ["inventory"] = {}}, ["y"] = 14, ["param1"] = 62, ["z"] = 15, ["name"] = "default:junglewood"}, {["x"] = 11, ["y"] = 15, ["z"] = 7, ["name"] = "wool:white"}, {["x"] = 11, ["y"] = 15, ["z"] = 8, ["name"] = "wool:white"}, {["x"] = 11, ["y"] = 15, ["z"] = 9, ["name"] = "wool:white"}, {["x"] = 12, ["meta"] = {["fields"] = {}, ["inventory"] = {}}, ["y"] = 0, ["param1"] = 56, ["z"] = 2, ["name"] = "default:wood"}, {["x"] = 12, ["meta"] = {["fields"] = {}, ["inventory"] = {}}, ["y"] = 0, ["param1"] = 56, ["z"] = 3, ["name"] = "default:wood"}, {["x"] = 12, ["meta"] = {["fields"] = {}, ["inventory"] = {}}, ["y"] = 0, ["param1"] = 56, ["z"] = 12, ["name"] = "default:wood"}, {["x"] = 12, ["meta"] = {["fields"] = {}, ["inventory"] = {}}, ["y"] = 0, ["param1"] = 56, ["z"] = 13, ["name"] = "default:wood"}, {["x"] = 12, ["meta"] = {["fields"] = {}, ["inventory"] = {}}, ["y"] = 1, ["param1"] = 56, ["z"] = 2, ["name"] = "default:wood"}, {["x"] = 12, ["meta"] = {["fields"] = {}, ["inventory"] = {}}, ["y"] = 1, ["param1"] = 56, ["z"] = 3, ["name"] = "default:wood"}, {["x"] = 12, ["meta"] = {["fields"] = {}, ["inventory"] = {}}, ["y"] = 1, ["param1"] = 56, ["z"] = 12, ["name"] = "default:wood"}, {["x"] = 12, ["meta"] = {["fields"] = {}, ["inventory"] = {}}, ["y"] = 1, ["param1"] = 56, ["z"] = 13, ["name"] = "default:wood"}, {["x"] = 12, ["y"] = 2, ["param1"] = 56, ["z"] = 2, ["name"] = "default:wood"}, {["x"] = 12, ["y"] = 2, ["param1"] = 56, ["z"] = 3, ["name"] = "default:wood"}, {["x"] = 12, ["y"] = 2, ["param1"] = 56, ["z"] = 12, ["name"] = "default:wood"}, {["x"] = 12, ["y"] = 2, ["param1"] = 56, ["z"] = 13, ["name"] = "default:wood"}, {["x"] = 12, ["y"] = 3, ["param1"] = 56, ["z"] = 2, ["name"] = "default:wood"}, {["x"] = 12, ["y"] = 3, ["param1"] = 56, ["z"] = 3, ["name"] = "default:wood"}, {["x"] = 12, ["y"] = 3, ["param1"] = 56, ["z"] = 12, ["name"] = "default:wood"}, {["x"] = 12, ["y"] = 3, ["param1"] = 56, ["z"] = 13, ["name"] = "default:wood"}, {["x"] = 12, ["y"] = 4, ["param1"] = 56, ["z"] = 2, ["name"] = "default:wood"}, {["x"] = 12, ["y"] = 4, ["param1"] = 56, ["z"] = 3, ["name"] = "default:wood"}, {["x"] = 12, ["y"] = 4, ["param1"] = 56, ["z"] = 12, ["name"] = "default:wood"}, {["x"] = 12, ["y"] = 4, ["param1"] = 56, ["z"] = 13, ["name"] = "default:wood"}, {["x"] = 12, ["y"] = 5, ["param1"] = 56, ["z"] = 2, ["name"] = "default:wood"}, {["x"] = 12, ["y"] = 5, ["param1"] = 56, ["z"] = 3, ["name"] = "default:wood"}, {["x"] = 12, ["y"] = 5, ["param1"] = 56, ["z"] = 12, ["name"] = "default:wood"}, {["x"] = 12, ["y"] = 5, ["param1"] = 56, ["z"] = 13, ["name"] = "default:wood"}, {["x"] = 12, ["y"] = 6, ["param1"] = 56, ["z"] = 2, ["name"] = "default:wood"}, {["x"] = 12, ["y"] = 6, ["param1"] = 56, ["z"] = 3, ["name"] = "default:wood"}, {["x"] = 12, ["y"] = 6, ["param1"] = 56, ["z"] = 12, ["name"] = "default:wood"}, {["x"] = 12, ["y"] = 6, ["param1"] = 56, ["z"] = 13, ["name"] = "default:wood"}, {["x"] = 12, ["y"] = 7, ["param1"] = 56, ["z"] = 2, ["name"] = "default:wood"}, {["x"] = 12, ["y"] = 7, ["param1"] = 56, ["z"] = 3, ["name"] = "default:wood"}, {["x"] = 12, ["y"] = 7, ["param1"] = 56, ["z"] = 12, ["name"] = "default:wood"}, {["x"] = 12, ["y"] = 7, ["param1"] = 56, ["z"] = 13, ["name"] = "default:wood"}, {["x"] = 12, ["y"] = 8, ["param1"] = 56, ["z"] = 2, ["name"] = "default:wood"}, {["x"] = 12, ["y"] = 8, ["param1"] = 56, ["z"] = 3, ["name"] = "default:wood"}, {["x"] = 12, ["y"] = 8, ["param1"] = 56, ["z"] = 12, ["name"] = "default:wood"}, {["x"] = 12, ["y"] = 8, ["param1"] = 56, ["z"] = 13, ["name"] = "default:wood"}, {["x"] = 12, ["y"] = 9, ["param1"] = 56, ["z"] = 2, ["name"] = "default:wood"}, {["x"] = 12, ["y"] = 9, ["param1"] = 56, ["z"] = 3, ["name"] = "default:wood"}, {["x"] = 12, ["y"] = 9, ["param1"] = 56, ["z"] = 12, ["name"] = "default:wood"}, {["x"] = 12, ["y"] = 9, ["param1"] = 56, ["z"] = 13, ["name"] = "default:wood"}, {["x"] = 12, ["y"] = 10, ["param1"] = 56, ["z"] = 2, ["name"] = "default:wood"}, {["x"] = 12, ["y"] = 10, ["param1"] = 56, ["z"] = 3, ["name"] = "default:wood"}, {["x"] = 12, ["y"] = 10, ["param1"] = 56, ["z"] = 12, ["name"] = "default:wood"}, {["x"] = 12, ["y"] = 10, ["param1"] = 56, ["z"] = 13, ["name"] = "default:wood"}, {["x"] = 12, ["y"] = 11, ["param1"] = 56, ["z"] = 2, ["name"] = "default:wood"}, {["x"] = 12, ["y"] = 11, ["param1"] = 56, ["z"] = 3, ["name"] = "default:wood"}, {["x"] = 12, ["y"] = 11, ["param1"] = 56, ["z"] = 12, ["name"] = "default:wood"}, {["x"] = 12, ["y"] = 11, ["param1"] = 56, ["z"] = 13, ["name"] = "default:wood"}, {["x"] = 12, ["meta"] = {["fields"] = {}, ["inventory"] = {}}, ["y"] = 12, ["param1"] = 62, ["z"] = 0, ["name"] = "default:junglewood"}, {["x"] = 12, ["meta"] = {["fields"] = {}, ["inventory"] = {}}, ["y"] = 12, ["param1"] = 62, ["z"] = 1, ["name"] = "default:junglewood"}, {["x"] = 12, ["meta"] = {["fields"] = {}, ["inventory"] = {}}, ["y"] = 12, ["param1"] = 62, ["z"] = 2, ["name"] = "default:junglewood"}, {["x"] = 12, ["meta"] = {["fields"] = {}, ["inventory"] = {}}, ["y"] = 12, ["param1"] = 62, ["z"] = 3, ["name"] = "default:junglewood"}, {["x"] = 12, ["meta"] = {["fields"] = {}, ["inventory"] = {}}, ["y"] = 12, ["param1"] = 62, ["z"] = 4, ["name"] = "default:junglewood"}, {["x"] = 12, ["meta"] = {["fields"] = {}, ["inventory"] = {}}, ["y"] = 12, ["param1"] = 62, ["z"] = 5, ["name"] = "default:junglewood"}, {["x"] = 12, ["meta"] = {["fields"] = {}, ["inventory"] = {}}, ["y"] = 12, ["param1"] = 62, ["z"] = 6, ["name"] = "default:junglewood"}, {["x"] = 12, ["meta"] = {["fields"] = {}, ["inventory"] = {}}, ["y"] = 12, ["param1"] = 62, ["z"] = 7, ["name"] = "default:junglewood"}, {["x"] = 12, ["meta"] = {["fields"] = {}, ["inventory"] = {}}, ["y"] = 12, ["param1"] = 62, ["z"] = 8, ["name"] = "default:junglewood"}, {["x"] = 12, ["meta"] = {["fields"] = {}, ["inventory"] = {}}, ["y"] = 12, ["param1"] = 62, ["z"] = 9, ["name"] = "default:junglewood"}, {["x"] = 12, ["meta"] = {["fields"] = {}, ["inventory"] = {}}, ["y"] = 12, ["param1"] = 62, ["z"] = 10, ["name"] = "default:junglewood"}, {["x"] = 12, ["meta"] = {["fields"] = {}, ["inventory"] = {}}, ["y"] = 12, ["param1"] = 62, ["z"] = 11, ["name"] = "default:junglewood"},